<mujoco><asset><texture name="checkered" type="2d" builtin="checker" rgb1="0.2 0.3 0.4" rgb2="0.9 0.9 0.9" width="512" height="512" /><material name="MatCheckered" texture="checkered" reflectance="0.5" /><material name="MatPlane" reflectance="0.5" shininess="1" specular="1" /><material name="red" rgba="1 0 0 1" /><material name="green" rgba="0 1 0 1" /><material name="blue" rgba="0 0 1 1" /><material name="yellow" rgba="1 1 0 1" /><material name="purple" rgba="0.5 0 0.5 1" /><material name="orange" rgba="1 0.5 0 1" /><material name="pink" rgba="1 0.7 0.7 1" /><material name="grey" rgba="0.5 0.5 0.5 1" /><material name="brown" rgba="0.6 0.3 0 1" /></asset><worldbody><geom name="floor" type="plane" size="10 10 0.1" pos="0 0 0" material="MatCheckered" /><body name="torso_0" pos="-6.5 -6.5 0.75"><geom name="torso_geom_torso_0" type="box" size="0.3315451392151798 0.112427595008552 0.09891005885640927" pos="0 0 0" contype="1" conaffinity="1" material="red" /><joint name="torso_0_root" type="free" armature="0" damping="0" limited="false" /><site name="torso_0_site" pos="0 0 0" type="sphere" size="0.01" /><body name="leg_0_1" pos="-0.1657725696075899 0 0"><geom name="leg_0_1_upper_geom" type="capsule" fromto="0.0 0.0 0.0 0.10289183755689522 0.0 0.0" size="0.04" /><joint name="leg_0_1_hip_joint" type="ball" damping="2.0" /><body name="leg_0_1_lower" pos="0.10289183755689522 0.0 0.0"><geom name="leg_0_1_lower_geom" type="capsule" fromto="0.10289183755689522 0.0 0.0 0.2321589840437136 0.0 0.0" size="0.04" /><joint name="leg_0_1_knee_joint" type="hinge" axis="0 1 0" range="-90 90" damping="4.0" limited="true" /><body name="leg_0_1_foot" pos="0.2321589840437136 0.0 0.0"><geom name="leg_0_1_foot_geom" type="cylinder" fromto="0.2321589840437136 0.0 0.0 0.36663294152158676 0.0 0.0" size="0.04" /><joint name="leg_0_1_ankle_joint" type="ball" damping="6.0" /></body></body></body><body name="leg_0_2" pos="0.1657725696075899 0 0"><geom name="leg_0_2_upper_geom" type="capsule" fromto="0.0 0.0 0.0 0.19812795833847074 0.0 0.0" size="0.04" /><joint name="leg_0_2_hip_joint" type="ball" damping="2.0" /><body name="leg_0_2_lower" pos="0.19812795833847074 0.0 0.0"><geom name="leg_0_2_lower_geom" type="capsule" fromto="0.19812795833847074 0.0 0.0 0.39572479835832886 0.0 0.0" size="0.04" /><joint name="leg_0_2_knee_joint" type="hinge" axis="0 1 0" range="-90 90" damping="4.0" limited="true" /><body name="leg_0_2_foot" pos="0.39572479835832886 0.0 0.0"><geom name="leg_0_2_foot_geom" type="cylinder" fromto="0.39572479835832886 0.0 0.0 0.5160291751589269 0.0 0.0" size="0.04" /><joint name="leg_0_2_ankle_joint" type="ball" damping="6.0" /></body></body></body></body><geom name="flag_0" type="box" size="0.05 0.05 0.5" pos="-9.829122864755202 -7.580250411415851 0" material="red" contype="1" conaffinity="1" /><body name="torso_1" pos="0 -6.5 0.75"><geom name="torso_geom_torso_1" type="box" size="0.2080253860116498 0.17978726400955397 0.09787747071935608" pos="0 0 0" contype="1" conaffinity="2" material="green" /><joint name="torso_1_root" type="free" armature="0" damping="0" limited="false" /><site name="torso_1_site" pos="0 0 0" type="sphere" size="0.01" /><body name="leg_1_1" pos="0 0.08989363200477699 0"><geom name="leg_1_1_upper_geom" type="capsule" fromto="0.0 0.0 0.0 0.19680894499850812 0.0 0.0" size="0.04" /><joint name="leg_1_1_hip_joint" type="ball" damping="2.0" /><body name="leg_1_1_lower" pos="0.19680894499850812 0.0 0.0"><geom name="leg_1_1_lower_geom" type="capsule" fromto="0.19680894499850812 0.0 0.0 0.34846760081445355 0.0 0.0" size="0.04" /><joint name="leg_1_1_knee_joint" type="hinge" axis="0 1 0" range="-90 90" damping="4.0" limited="true" /><body name="leg_1_1_foot" pos="0.34846760081445355 0.0 0.0"><geom name="leg_1_1_foot_geom" type="cylinder" fromto="0.34846760081445355 0.0 0.0 0.5296614239935011 0.0 0.0" size="0.04" /><joint name="leg_1_1_ankle_joint" type="ball" damping="6.0" /></body></body></body><body name="leg_1_2" pos="0 -0.08989363200477699 0"><geom name="leg_1_2_upper_geom" type="capsule" fromto="0.0 0.0 0.0 0.15402143687297706 0.0 0.0" size="0.04" /><joint name="leg_1_2_hip_joint" type="ball" damping="2.0" /><body name="leg_1_2_lower" pos="0.15402143687297706 0.0 0.0"><geom name="leg_1_2_lower_geom" type="capsule" fromto="0.15402143687297706 0.0 0.0 0.26104984357598243 0.0 0.0" size="0.04" /><joint name="leg_1_2_knee_joint" type="hinge" axis="0 1 0" range="-90 90" damping="4.0" limited="true" /><body name="leg_1_2_foot" pos="0.26104984357598243 0.0 0.0"><geom name="leg_1_2_foot_geom" type="cylinder" fromto="0.26104984357598243 0.0 0.0 0.3689440293596725 0.0 0.0" size="0.04" /><joint name="leg_1_2_ankle_joint" type="ball" damping="6.0" /></body></body></body><body name="leg_1_3" pos="0 0.08989363200477699 0"><geom name="leg_1_3_upper_geom" type="capsule" fromto="0.0 0.0 0.0 0.1167947370412834 0.0 0.0" size="0.04" /><joint name="leg_1_3_hip_joint" type="ball" damping="2.0" /><body name="leg_1_3_lower" pos="0.1167947370412834 0.0 0.0"><geom name="leg_1_3_lower_geom" type="capsule" fromto="0.1167947370412834 0.0 0.0 0.31341941225367875 0.0 0.0" size="0.04" /><joint name="leg_1_3_knee_joint" type="hinge" axis="0 1 0" range="-90 90" damping="4.0" limited="true" /><body name="leg_1_3_foot" pos="0.31341941225367875 0.0 0.0"><geom name="leg_1_3_foot_geom" type="cylinder" fromto="0.31341941225367875 0.0 0.0 0.4383915247740926 0.0 0.0" size="0.04" /><joint name="leg_1_3_ankle_joint" type="ball" damping="6.0" /></body></body></body></body><geom name="flag_1" type="box" size="0.05 0.05 0.5" pos="-3.2432511693373502 -5.184202959194728 0" material="green" contype="1" conaffinity="2" /><body name="torso_2" pos="6.5 -6.5 0.75"><geom name="torso_geom_torso_2" type="box" size="0.3912732995869561 0.13930400637392873 0.09725094058869525" pos="0 0 0" contype="1" conaffinity="3" material="blue" /><joint name="torso_2_root" type="free" armature="0" damping="0" limited="false" /><site name="torso_2_site" pos="0 0 0" type="sphere" size="0.01" /><body name="leg_2_1" pos="0 0.06965200318696436 0"><geom name="leg_2_1_upper_geom" type="capsule" fromto="0.0 0.0 0.0 0.18852216835820582 0.0 0.0" size="0.04" /><joint name="leg_2_1_hip_joint" type="ball" damping="2.0" /><body name="leg_2_1_lower" pos="0.18852216835820582 0.0 0.0"><geom name="leg_2_1_lower_geom" type="capsule" fromto="0.18852216835820582 0.0 0.0 0.29578538610935773 0.0 0.0" size="0.04" /><joint name="leg_2_1_knee_joint" type="hinge" axis="0 1 0" range="-90 90" damping="4.0" limited="true" /><body name="leg_2_1_foot" pos="0.29578538610935773 0.0 0.0"><geom name="leg_2_1_foot_geom" type="cylinder" fromto="0.29578538610935773 0.0 0.0 0.4523777617762075 0.0 0.0" size="0.04" /><joint name="leg_2_1_ankle_joint" type="ball" damping="6.0" /></body></body></body><body name="leg_2_2" pos="0 -0.06965200318696436 0"><geom name="leg_2_2_upper_geom" type="capsule" fromto="0.0 0.0 0.0 0.1028696512823418 0.0 0.0" size="0.04" /><joint name="leg_2_2_hip_joint" type="ball" damping="2.0" /><body name="leg_2_2_lower" pos="0.1028696512823418 0.0 0.0"><geom name="leg_2_2_lower_geom" type="capsule" fromto="0.1028696512823418 0.0 0.0 0.23731924615119096 0.0 0.0" size="0.04" /><joint name="leg_2_2_knee_joint" type="hinge" axis="0 1 0" range="-90 90" damping="4.0" limited="true" /><body name="leg_2_2_foot" pos="0.23731924615119096 0.0 0.0"><geom name="leg_2_2_foot_geom" type="cylinder" fromto="0.23731924615119096 0.0 0.0 0.43264226846085163 0.0 0.0" size="0.04" /><joint name="leg_2_2_ankle_joint" type="ball" damping="6.0" /></body></body></body><body name="leg_2_3" pos="0 0.06965200318696436 0"><geom name="leg_2_3_upper_geom" type="capsule" fromto="0.0 0.0 0.0 0.17622753016303805 0.0 0.0" size="0.04" /><joint name="leg_2_3_hip_joint" type="ball" damping="2.0" /><body name="leg_2_3_lower" pos="0.17622753016303805 0.0 0.0"><geom name="leg_2_3_lower_geom" type="capsule" fromto="0.17622753016303805 0.0 0.0 0.2860738131580589 0.0 0.0" size="0.04" /><joint name="leg_2_3_knee_joint" type="hinge" axis="0 1 0" range="-90 90" damping="4.0" limited="true" /><body name="leg_2_3_foot" pos="0.2860738131580589 0.0 0.0"><geom name="leg_2_3_foot_geom" type="cylinder" fromto="0.2860738131580589 0.0 0.0 0.4097108421116664 0.0 0.0" size="0.04" /><joint name="leg_2_3_ankle_joint" type="ball" damping="6.0" /></body></body></body></body><geom name="flag_2" type="box" size="0.05 0.05 0.5" pos="9.383693260528094 -8.48351031738805 0" material="blue" contype="1" conaffinity="3" /><body name="torso_3" pos="-6.5 0 0.75"><geom name="torso_geom_torso_3" type="box" size="0.2544184793394433 0.11772421784333945 0.08081270812203979" pos="0 0 0" contype="1" conaffinity="4" material="yellow" /><joint name="torso_3_root" type="free" armature="0" damping="0" limited="false" /><site name="torso_3_site" pos="0 0 0" type="sphere" size="0.01" /><body name="leg_3_1" pos="0 -0.05886210892166972 0"><geom name="leg_3_1_upper_geom" type="capsule" fromto="0.0 0.0 0.0 0.16084095907861784 0.0 0.0" size="0.04" /><joint name="leg_3_1_hip_joint" type="ball" damping="2.0" /><body name="leg_3_1_lower" pos="0.16084095907861784 0.0 0.0"><geom name="leg_3_1_lower_geom" type="capsule" fromto="0.16084095907861784 0.0 0.0 0.31008997098026414 0.0 0.0" size="0.04" /><joint name="leg_3_1_knee_joint" type="hinge" axis="0 1 0" range="-90 90" damping="4.0" limited="true" /><body name="leg_3_1_foot" pos="0.31008997098026414 0.0 0.0"><geom name="leg_3_1_foot_geom" type="cylinder" fromto="0.31008997098026414 0.0 0.0 0.4890076009005362 0.0 0.0" size="0.04" /><joint name="leg_3_1_ankle_joint" type="ball" damping="6.0" /></body></body></body><body name="leg_3_2" pos="0 0.05886210892166972 0"><geom name="leg_3_2_upper_geom" type="capsule" fromto="0.0 0.0 0.0 0.10704286697957988 0.0 0.0" size="0.04" /><joint name="leg_3_2_hip_joint" type="ball" damping="2.0" /><body name="leg_3_2_lower" pos="0.10704286697957988 0.0 0.0"><geom name="leg_3_2_lower_geom" type="capsule" fromto="0.10704286697957988 0.0 0.0 0.2762859234727064 0.0 0.0" size="0.04" /><joint name="leg_3_2_knee_joint" type="hinge" axis="0 1 0" range="-90 90" damping="4.0" limited="true" /><body name="leg_3_2_foot" pos="0.2762859234727064 0.0 0.0"><geom name="leg_3_2_foot_geom" type="cylinder" fromto="0.2762859234727064 0.0 0.0 0.45856322275536965 0.0 0.0" size="0.04" /><joint name="leg_3_2_ankle_joint" type="ball" damping="6.0" /></body></body></body><body name="leg_3_3" pos="0 -0.05886210892166972 0"><geom name="leg_3_3_upper_geom" type="capsule" fromto="0.0 0.0 0.0 0.16675631754566378 0.0 0.0" size="0.04" /><joint name="leg_3_3_hip_joint" type="ball" damping="2.0" /><body name="leg_3_3_lower" pos="0.16675631754566378 0.0 0.0"><geom name="leg_3_3_lower_geom" type="capsule" fromto="0.16675631754566378 0.0 0.0 0.33982399931786206 0.0 0.0" size="0.04" /><joint name="leg_3_3_knee_joint" type="hinge" axis="0 1 0" range="-90 90" damping="4.0" limited="true" /><body name="leg_3_3_foot" pos="0.33982399931786206 0.0 0.0"><geom name="leg_3_3_foot_geom" type="cylinder" fromto="0.33982399931786206 0.0 0.0 0.4872843311649927 0.0 0.0" size="0.04" /><joint name="leg_3_3_ankle_joint" type="ball" damping="6.0" /></body></body></body></body><geom name="flag_3" type="box" size="0.05 0.05 0.5" pos="-9.999815351599246 0.03595142153308704 0" material="yellow" contype="1" conaffinity="4" /><body name="torso_4" pos="0 0 0.75"><geom name="torso_geom_torso_4" type="box" size="0.251918220768919 0.12258958378194335 0.09941292635472343" pos="0 0 0" contype="1" conaffinity="5" material="purple" /><joint name="torso_4_root" type="free" armature="0" damping="0" limited="false" /><site name="torso_4_site" pos="0 0 0" type="sphere" size="0.01" /><body name="leg_4_1" pos="0 -0.06129479189097167 0"><geom name="leg_4_1_upper_geom" type="capsule" fromto="0.0 0.0 0.0 0.11010032900565211 0.0 0.0" size="0.04" /><joint name="leg_4_1_hip_joint" type="ball" damping="2.0" /><body name="leg_4_1_lower" pos="0.11010032900565211 0.0 0.0"><geom name="leg_4_1_lower_geom" type="capsule" fromto="0.11010032900565211 0.0 0.0 0.21234838931050193 0.0 0.0" size="0.04" /><joint name="leg_4_1_knee_joint" type="hinge" axis="0 1 0" range="-90 90" damping="4.0" limited="true" /><body name="leg_4_1_foot" pos="0.21234838931050193 0.0 0.0"><geom name="leg_4_1_foot_geom" type="cylinder" fromto="0.21234838931050193 0.0 0.0 0.3204241328479647 0.0 0.0" size="0.04" /><joint name="leg_4_1_ankle_joint" type="ball" damping="6.0" /></body></body></body><body name="leg_4_2" pos="0 -0.06129479189097167 0"><geom name="leg_4_2_upper_geom" type="capsule" fromto="0.0 0.0 0.0 0.1994684050866581 0.0 0.0" size="0.04" /><joint name="leg_4_2_hip_joint" type="ball" damping="2.0" /><body name="leg_4_2_lower" pos="0.1994684050866581 0.0 0.0"><geom name="leg_4_2_lower_geom" type="capsule" fromto="0.1994684050866581 0.0 0.0 0.3419731317089022 0.0 0.0" size="0.04" /><joint name="leg_4_2_knee_joint" type="hinge" axis="0 1 0" range="-90 90" damping="4.0" limited="true" /><body name="leg_4_2_foot" pos="0.3419731317089022 0.0 0.0"><geom name="leg_4_2_foot_geom" type="cylinder" fromto="0.3419731317089022 0.0 0.0 0.47647179597251577 0.0 0.0" size="0.04" /><joint name="leg_4_2_ankle_joint" type="ball" damping="6.0" /></body></body></body><body name="leg_4_3" pos="0.1259591103844595 0 0"><geom name="leg_4_3_upper_geom" type="capsule" fromto="0.0 0.0 0.0 0.11766548489061975 0.0 0.0" size="0.04" /><joint name="leg_4_3_hip_joint" type="ball" damping="2.0" /><body name="leg_4_3_lower" pos="0.11766548489061975 0.0 0.0"><geom name="leg_4_3_lower_geom" type="capsule" fromto="0.11766548489061975 0.0 0.0 0.29417662911218634 0.0 0.0" size="0.04" /><joint name="leg_4_3_knee_joint" type="hinge" axis="0 1 0" range="-90 90" damping="4.0" limited="true" /><body name="leg_4_3_foot" pos="0.29417662911218634 0.0 0.0"><geom name="leg_4_3_foot_geom" type="cylinder" fromto="0.29417662911218634 0.0 0.0 0.4024393924541306 0.0 0.0" size="0.04" /><joint name="leg_4_3_ankle_joint" type="ball" damping="6.0" /></body></body></body><body name="leg_4_4" pos="0 0.06129479189097167 0"><geom name="leg_4_4_upper_geom" type="capsule" fromto="0.0 0.0 0.0 0.17862364451930218 0.0 0.0" size="0.04" /><joint name="leg_4_4_hip_joint" type="ball" damping="2.0" /><body name="leg_4_4_lower" pos="0.17862364451930218 0.0 0.0"><geom name="leg_4_4_lower_geom" type="capsule" fromto="0.17862364451930218 0.0 0.0 0.2926272831329448 0.0 0.0" size="0.04" /><joint name="leg_4_4_knee_joint" type="hinge" axis="0 1 0" range="-90 90" damping="4.0" limited="true" /><body name="leg_4_4_foot" pos="0.2926272831329448 0.0 0.0"><geom name="leg_4_4_foot_geom" type="cylinder" fromto="0.2926272831329448 0.0 0.0 0.4373555931873686 0.0 0.0" size="0.04" /><joint name="leg_4_4_ankle_joint" type="ball" damping="6.0" /></body></body></body></body><geom name="flag_4" type="box" size="0.05 0.05 0.5" pos="-3.3102884223667757 -1.1366576268800046 0" material="purple" contype="1" conaffinity="5" /><body name="torso_5" pos="6.5 0 0.75"><geom name="torso_geom_torso_5" type="box" size="0.32365727238942166 0.19592502692434166 0.08169301789660743" pos="0 0 0" contype="1" conaffinity="6" material="orange" /><joint name="torso_5_root" type="free" armature="0" damping="0" limited="false" /><site name="torso_5_site" pos="0 0 0" type="sphere" size="0.01" /><body name="leg_5_1" pos="0.16182863619471083 0 0"><geom name="leg_5_1_upper_geom" type="capsule" fromto="0.0 0.0 0.0 0.13087748791969914 0.0 0.0" size="0.04" /><joint name="leg_5_1_hip_joint" type="ball" damping="2.0" /><body name="leg_5_1_lower" pos="0.13087748791969914 0.0 0.0"><geom name="leg_5_1_lower_geom" type="capsule" fromto="0.13087748791969914 0.0 0.0 0.3194149201865224 0.0 0.0" size="0.04" /><joint name="leg_5_1_knee_joint" type="hinge" axis="0 1 0" range="-90 90" damping="4.0" limited="true" /><body name="leg_5_1_foot" pos="0.3194149201865224 0.0 0.0"><geom name="leg_5_1_foot_geom" type="cylinder" fromto="0.3194149201865224 0.0 0.0 0.4717330443807416 0.0 0.0" size="0.04" /><joint name="leg_5_1_ankle_joint" type="ball" damping="6.0" /></body></body></body></body><geom name="flag_5" type="box" size="0.05 0.05 0.5" pos="3.138512451079431 0.9748853565686515 0" material="orange" contype="1" conaffinity="6" /><body name="torso_6" pos="-6.5 6.5 0.75"><geom name="torso_geom_torso_6" type="box" size="0.2824796164340885 0.13061334355481422 0.06425468277419732" pos="0 0 0" contype="1" conaffinity="7" material="pink" /><joint name="torso_6_root" type="free" armature="0" damping="0" limited="false" /><site name="torso_6_site" pos="0 0 0" type="sphere" size="0.01" /><body name="leg_6_1" pos="0 -0.06530667177740711 0"><geom name="leg_6_1_upper_geom" type="capsule" fromto="0.0 0.0 0.0 0.17209529997534292 0.0 0.0" size="0.04" /><joint name="leg_6_1_hip_joint" type="ball" damping="2.0" /><body name="leg_6_1_lower" pos="0.17209529997534292 0.0 0.0"><geom name="leg_6_1_lower_geom" type="capsule" fromto="0.17209529997534292 0.0 0.0 0.36597975781652803 0.0 0.0" size="0.04" /><joint name="leg_6_1_knee_joint" type="hinge" axis="0 1 0" range="-90 90" damping="4.0" limited="true" /><body name="leg_6_1_foot" pos="0.36597975781652803 0.0 0.0"><geom name="leg_6_1_foot_geom" type="cylinder" fromto="0.36597975781652803 0.0 0.0 0.4843805310878582 0.0 0.0" size="0.04" /><joint name="leg_6_1_ankle_joint" type="ball" damping="6.0" /></body></body></body><body name="leg_6_2" pos="-0.14123980821704424 0 0"><geom name="leg_6_2_upper_geom" type="capsule" fromto="0.0 0.0 0.0 0.19704167328753416 0.0 0.0" size="0.04" /><joint name="leg_6_2_hip_joint" type="ball" damping="2.0" /><body name="leg_6_2_lower" pos="0.19704167328753416 0.0 0.0"><geom name="leg_6_2_lower_geom" type="capsule" fromto="0.19704167328753416 0.0 0.0 0.383549616995336 0.0 0.0" size="0.04" /><joint name="leg_6_2_knee_joint" type="hinge" axis="0 1 0" range="-90 90" damping="4.0" limited="true" /><body name="leg_6_2_foot" pos="0.383549616995336 0.0 0.0"><geom name="leg_6_2_foot_geom" type="cylinder" fromto="0.383549616995336 0.0 0.0 0.5000244250994783 0.0 0.0" size="0.04" /><joint name="leg_6_2_ankle_joint" type="ball" damping="6.0" /></body></body></body></body><geom name="flag_6" type="box" size="0.05 0.05 0.5" pos="-4.4107699551202 9.308045195428939 0" material="pink" contype="1" conaffinity="7" /><body name="torso_7" pos="0 6.5 0.75"><geom name="torso_geom_torso_7" type="box" size="0.45333513820564125 0.15576961188476127 0.08408604113918189" pos="0 0 0" contype="1" conaffinity="8" material="grey" /><joint name="torso_7_root" type="free" armature="0" damping="0" limited="false" /><site name="torso_7_site" pos="0 0 0" type="sphere" size="0.01" /><body name="leg_7_1" pos="0.22666756910282063 0 0"><geom name="leg_7_1_upper_geom" type="capsule" fromto="0.0 0.0 0.0 0.1996748166189401 0.0 0.0" size="0.04" /><joint name="leg_7_1_hip_joint" type="ball" damping="2.0" /><body name="leg_7_1_lower" pos="0.1996748166189401 0.0 0.0"><geom name="leg_7_1_lower_geom" type="capsule" fromto="0.1996748166189401 0.0 0.0 0.3351947541015507 0.0 0.0" size="0.04" /><joint name="leg_7_1_knee_joint" type="hinge" axis="0 1 0" range="-90 90" damping="4.0" limited="true" /><body name="leg_7_1_foot" pos="0.3351947541015507 0.0 0.0"><geom name="leg_7_1_foot_geom" type="cylinder" fromto="0.3351947541015507 0.0 0.0 0.5259321816502169 0.0 0.0" size="0.04" /><joint name="leg_7_1_ankle_joint" type="ball" damping="6.0" /></body></body></body><body name="leg_7_2" pos="-0.22666756910282063 0 0"><geom name="leg_7_2_upper_geom" type="capsule" fromto="0.0 0.0 0.0 0.11862794736412871 0.0 0.0" size="0.04" /><joint name="leg_7_2_hip_joint" type="ball" damping="2.0" /><body name="leg_7_2_lower" pos="0.11862794736412871 0.0 0.0"><geom name="leg_7_2_lower_geom" type="capsule" fromto="0.11862794736412871 0.0 0.0 0.31316505916066606 0.0 0.0" size="0.04" /><joint name="leg_7_2_knee_joint" type="hinge" axis="0 1 0" range="-90 90" damping="4.0" limited="true" /><body name="leg_7_2_foot" pos="0.31316505916066606 0.0 0.0"><geom name="leg_7_2_foot_geom" type="cylinder" fromto="0.31316505916066606 0.0 0.0 0.4965596568330549 0.0 0.0" size="0.04" /><joint name="leg_7_2_ankle_joint" type="ball" damping="6.0" /></body></body></body><body name="leg_7_3" pos="-0.22666756910282063 0 0"><geom name="leg_7_3_upper_geom" type="capsule" fromto="0.0 0.0 0.0 0.17288733351300734 0.0 0.0" size="0.04" /><joint name="leg_7_3_hip_joint" type="ball" damping="2.0" /><body name="leg_7_3_lower" pos="0.17288733351300734 0.0 0.0"><geom name="leg_7_3_lower_geom" type="capsule" fromto="0.17288733351300734 0.0 0.0 0.32739972588487953 0.0 0.0" size="0.04" /><joint name="leg_7_3_knee_joint" type="hinge" axis="0 1 0" range="-90 90" damping="4.0" limited="true" /><body name="leg_7_3_foot" pos="0.32739972588487953 0.0 0.0"><geom name="leg_7_3_foot_geom" type="cylinder" fromto="0.32739972588487953 0.0 0.0 0.5010985402115977 0.0 0.0" size="0.04" /><joint name="leg_7_3_ankle_joint" type="ball" damping="6.0" /></body></body></body><body name="leg_7_4" pos="0 0.07788480594238063 0"><geom name="leg_7_4_upper_geom" type="capsule" fromto="0.0 0.0 0.0 0.12522853315058574 0.0 0.0" size="0.04" /><joint name="leg_7_4_hip_joint" type="ball" damping="2.0" /><body name="leg_7_4_lower" pos="0.12522853315058574 0.0 0.0"><geom name="leg_7_4_lower_geom" type="capsule" fromto="0.12522853315058574 0.0 0.0 0.23752141649845568 0.0 0.0" size="0.04" /><joint name="leg_7_4_knee_joint" type="hinge" axis="0 1 0" range="-90 90" damping="4.0" limited="true" /><body name="leg_7_4_foot" pos="0.23752141649845568 0.0 0.0"><geom name="leg_7_4_foot_geom" type="cylinder" fromto="0.23752141649845568 0.0 0.0 0.43361392232786466 0.0 0.0" size="0.04" /><joint name="leg_7_4_ankle_joint" type="ball" damping="6.0" /></body></body></body></body><geom name="flag_7" type="box" size="0.05 0.05 0.5" pos="-0.5886572938236538 9.95014240147102 0" material="grey" contype="1" conaffinity="8" /><body name="torso_8" pos="6.5 6.5 0.75"><geom name="torso_geom_torso_8" type="box" size="0.4177519042212109 0.10640549632730112 0.06707896464128467" pos="0 0 0" contype="1" conaffinity="9" material="brown" /><joint name="torso_8_root" type="free" armature="0" damping="0" limited="false" /><site name="torso_8_site" pos="0 0 0" type="sphere" size="0.01" /><body name="leg_8_1" pos="-0.20887595211060545 0 0"><geom name="leg_8_1_upper_geom" type="capsule" fromto="0.0 0.0 0.0 0.14452743409470267 0.0 0.0" size="0.04" /><joint name="leg_8_1_hip_joint" type="ball" damping="2.0" /><body name="leg_8_1_lower" pos="0.14452743409470267 0.0 0.0"><geom name="leg_8_1_lower_geom" type="capsule" fromto="0.14452743409470267 0.0 0.0 0.28707663682026185 0.0 0.0" size="0.04" /><joint name="leg_8_1_knee_joint" type="hinge" axis="0 1 0" range="-90 90" damping="4.0" limited="true" /><body name="leg_8_1_foot" pos="0.28707663682026185 0.0 0.0"><geom name="leg_8_1_foot_geom" type="cylinder" fromto="0.28707663682026185 0.0 0.0 0.4408090853639206 0.0 0.0" size="0.04" /><joint name="leg_8_1_ankle_joint" type="ball" damping="6.0" /></body></body></body><body name="leg_8_2" pos="0.20887595211060545 0 0"><geom name="leg_8_2_upper_geom" type="capsule" fromto="0.0 0.0 0.0 0.19555396251796367 0.0 0.0" size="0.04" /><joint name="leg_8_2_hip_joint" type="ball" damping="2.0" /><body name="leg_8_2_lower" pos="0.19555396251796367 0.0 0.0"><geom name="leg_8_2_lower_geom" type="capsule" fromto="0.19555396251796367 0.0 0.0 0.368056866085376 0.0 0.0" size="0.04" /><joint name="leg_8_2_knee_joint" type="hinge" axis="0 1 0" range="-90 90" damping="4.0" limited="true" /><body name="leg_8_2_foot" pos="0.368056866085376 0.0 0.0"><geom name="leg_8_2_foot_geom" type="cylinder" fromto="0.368056866085376 0.0 0.0 0.48737602244845424 0.0 0.0" size="0.04" /><joint name="leg_8_2_ankle_joint" type="ball" damping="6.0" /></body></body></body></body><geom name="flag_8" type="box" size="0.05 0.05 0.5" pos="3.076414191584454 7.227365253786342 0" material="brown" contype="1" conaffinity="9" /><geom name="north_wall" type="box" pos="0 10.05 0.25" size="10.05 0.05 0.25" material="MatPlane" /><geom name="south_wall" type="box" pos="0 -10.05 0.25" size="10.05 0.05 0.25" material="MatPlane" /><geom name="east_wall" type="box" pos="10.05 0 0.25" size="0.05 10.05 0.25" material="MatPlane" /><geom name="west_wall" type="box" pos="-10.05 0 0.25" size="0.05 10.05 0.25" material="MatPlane" /></worldbody><actuator><motor name="leg_0_1_hip_motor" joint="leg_0_1_hip_joint" ctrllimited="true" ctrlrange="-1 1" gear="200" /><motor name="leg_0_1_ankle_joint_motor" joint="leg_0_1_ankle_joint" ctrllimited="true" ctrlrange="-1 1" gear="200" /><motor name="leg_0_2_hip_motor" joint="leg_0_2_hip_joint" ctrllimited="true" ctrlrange="-1 1" gear="200" /><motor name="leg_0_2_ankle_joint_motor" joint="leg_0_2_ankle_joint" ctrllimited="true" ctrlrange="-1 1" gear="200" /><motor name="leg_1_1_hip_motor" joint="leg_1_1_hip_joint" ctrllimited="true" ctrlrange="-1 1" gear="200" /><motor name="leg_1_1_ankle_joint_motor" joint="leg_1_1_ankle_joint" ctrllimited="true" ctrlrange="-1 1" gear="200" /><motor name="leg_1_2_hip_motor" joint="leg_1_2_hip_joint" ctrllimited="true" ctrlrange="-1 1" gear="200" /><motor name="leg_1_2_ankle_joint_motor" joint="leg_1_2_ankle_joint" ctrllimited="true" ctrlrange="-1 1" gear="200" /><motor name="leg_1_3_hip_motor" joint="leg_1_3_hip_joint" ctrllimited="true" ctrlrange="-1 1" gear="200" /><motor name="leg_1_3_ankle_joint_motor" joint="leg_1_3_ankle_joint" ctrllimited="true" ctrlrange="-1 1" gear="200" /><motor name="leg_2_1_hip_motor" joint="leg_2_1_hip_joint" ctrllimited="true" ctrlrange="-1 1" gear="200" /><motor name="leg_2_1_ankle_joint_motor" joint="leg_2_1_ankle_joint" ctrllimited="true" ctrlrange="-1 1" gear="200" /><motor name="leg_2_2_hip_motor" joint="leg_2_2_hip_joint" ctrllimited="true" ctrlrange="-1 1" gear="200" /><motor name="leg_2_2_ankle_joint_motor" joint="leg_2_2_ankle_joint" ctrllimited="true" ctrlrange="-1 1" gear="200" /><motor name="leg_2_3_hip_motor" joint="leg_2_3_hip_joint" ctrllimited="true" ctrlrange="-1 1" gear="200" /><motor name="leg_2_3_ankle_joint_motor" joint="leg_2_3_ankle_joint" ctrllimited="true" ctrlrange="-1 1" gear="200" /><motor name="leg_3_1_hip_motor" joint="leg_3_1_hip_joint" ctrllimited="true" ctrlrange="-1 1" gear="200" /><motor name="leg_3_1_ankle_joint_motor" joint="leg_3_1_ankle_joint" ctrllimited="true" ctrlrange="-1 1" gear="200" /><motor name="leg_3_2_hip_motor" joint="leg_3_2_hip_joint" ctrllimited="true" ctrlrange="-1 1" gear="200" /><motor name="leg_3_2_ankle_joint_motor" joint="leg_3_2_ankle_joint" ctrllimited="true" ctrlrange="-1 1" gear="200" /><motor name="leg_3_3_hip_motor" joint="leg_3_3_hip_joint" ctrllimited="true" ctrlrange="-1 1" gear="200" /><motor name="leg_3_3_ankle_joint_motor" joint="leg_3_3_ankle_joint" ctrllimited="true" ctrlrange="-1 1" gear="200" /><motor name="leg_4_1_hip_motor" joint="leg_4_1_hip_joint" ctrllimited="true" ctrlrange="-1 1" gear="200" /><motor name="leg_4_1_ankle_joint_motor" joint="leg_4_1_ankle_joint" ctrllimited="true" ctrlrange="-1 1" gear="200" /><motor name="leg_4_2_hip_motor" joint="leg_4_2_hip_joint" ctrllimited="true" ctrlrange="-1 1" gear="200" /><motor name="leg_4_2_ankle_joint_motor" joint="leg_4_2_ankle_joint" ctrllimited="true" ctrlrange="-1 1" gear="200" /><motor name="leg_4_3_hip_motor" joint="leg_4_3_hip_joint" ctrllimited="true" ctrlrange="-1 1" gear="200" /><motor name="leg_4_3_ankle_joint_motor" joint="leg_4_3_ankle_joint" ctrllimited="true" ctrlrange="-1 1" gear="200" /><motor name="leg_4_4_hip_motor" joint="leg_4_4_hip_joint" ctrllimited="true" ctrlrange="-1 1" gear="200" /><motor name="leg_4_4_ankle_joint_motor" joint="leg_4_4_ankle_joint" ctrllimited="true" ctrlrange="-1 1" gear="200" /><motor name="leg_5_1_hip_motor" joint="leg_5_1_hip_joint" ctrllimited="true" ctrlrange="-1 1" gear="200" /><motor name="leg_5_1_ankle_joint_motor" joint="leg_5_1_ankle_joint" ctrllimited="true" ctrlrange="-1 1" gear="200" /><motor name="leg_6_1_hip_motor" joint="leg_6_1_hip_joint" ctrllimited="true" ctrlrange="-1 1" gear="200" /><motor name="leg_6_1_ankle_joint_motor" joint="leg_6_1_ankle_joint" ctrllimited="true" ctrlrange="-1 1" gear="200" /><motor name="leg_6_2_hip_motor" joint="leg_6_2_hip_joint" ctrllimited="true" ctrlrange="-1 1" gear="200" /><motor name="leg_6_2_ankle_joint_motor" joint="leg_6_2_ankle_joint" ctrllimited="true" ctrlrange="-1 1" gear="200" /><motor name="leg_7_1_hip_motor" joint="leg_7_1_hip_joint" ctrllimited="true" ctrlrange="-1 1" gear="200" /><motor name="leg_7_1_ankle_joint_motor" joint="leg_7_1_ankle_joint" ctrllimited="true" ctrlrange="-1 1" gear="200" /><motor name="leg_7_2_hip_motor" joint="leg_7_2_hip_joint" ctrllimited="true" ctrlrange="-1 1" gear="200" /><motor name="leg_7_2_ankle_joint_motor" joint="leg_7_2_ankle_joint" ctrllimited="true" ctrlrange="-1 1" gear="200" /><motor name="leg_7_3_hip_motor" joint="leg_7_3_hip_joint" ctrllimited="true" ctrlrange="-1 1" gear="200" /><motor name="leg_7_3_ankle_joint_motor" joint="leg_7_3_ankle_joint" ctrllimited="true" ctrlrange="-1 1" gear="200" /><motor name="leg_7_4_hip_motor" joint="leg_7_4_hip_joint" ctrllimited="true" ctrlrange="-1 1" gear="200" /><motor name="leg_7_4_ankle_joint_motor" joint="leg_7_4_ankle_joint" ctrllimited="true" ctrlrange="-1 1" gear="200" /><motor name="leg_8_1_hip_motor" joint="leg_8_1_hip_joint" ctrllimited="true" ctrlrange="-1 1" gear="200" /><motor name="leg_8_1_ankle_joint_motor" joint="leg_8_1_ankle_joint" ctrllimited="true" ctrlrange="-1 1" gear="200" /><motor name="leg_8_2_hip_motor" joint="leg_8_2_hip_joint" ctrllimited="true" ctrlrange="-1 1" gear="200" /><motor name="leg_8_2_ankle_joint_motor" joint="leg_8_2_ankle_joint" ctrllimited="true" ctrlrange="-1 1" gear="200" /></actuator><sensor><accelerometer name="torso_0_accel" site="torso_0_site" /><gyro name="torso_0_gyro" site="torso_0_site" /><accelerometer name="torso_1_accel" site="torso_1_site" /><gyro name="torso_1_gyro" site="torso_1_site" /><accelerometer name="torso_2_accel" site="torso_2_site" /><gyro name="torso_2_gyro" site="torso_2_site" /><accelerometer name="torso_3_accel" site="torso_3_site" /><gyro name="torso_3_gyro" site="torso_3_site" /><accelerometer name="torso_4_accel" site="torso_4_site" /><gyro name="torso_4_gyro" site="torso_4_site" /><accelerometer name="torso_5_accel" site="torso_5_site" /><gyro name="torso_5_gyro" site="torso_5_site" /><accelerometer name="torso_6_accel" site="torso_6_site" /><gyro name="torso_6_gyro" site="torso_6_site" /><accelerometer name="torso_7_accel" site="torso_7_site" /><gyro name="torso_7_gyro" site="torso_7_site" /><accelerometer name="torso_8_accel" site="torso_8_site" /><gyro name="torso_8_gyro" site="torso_8_site" /></sensor></mujoco>