<mujoco><asset><texture name="checkered" type="2d" builtin="checker" rgb1="0.2 0.3 0.4" rgb2="0.9 0.9 0.9" width="512" height="512" /><material name="MatCheckered" texture="checkered" reflectance="0.5" /><material name="MatPlane" reflectance="0.5" shininess="1" specular="1" /><material name="red" rgba="1 0 0 1" /><material name="green" rgba="0 1 0 1" /><material name="blue" rgba="0 0 1 1" /><material name="yellow" rgba="1 1 0 1" /><material name="purple" rgba="0.5 0 0.5 1" /><material name="orange" rgba="1 0.5 0 1" /><material name="pink" rgba="1 0.7 0.7 1" /><material name="grey" rgba="0.5 0.5 0.5 1" /><material name="brown" rgba="0.6 0.3 0 1" /></asset><worldbody><geom name="floor" type="plane" size="10 10 0.1" pos="0 0 0" material="MatCheckered" /><body name="torso_0" pos="-6.5 -6.5 0.75"><geom name="torso_geom_torso_0" type="box" size="0.4384421147518127 0.1828265890460235 0.07428886377198642" pos="0 0 0" contype="1" conaffinity="1" material="red" /><joint name="torso_0_root" type="free" armature="0" damping="0" limited="false" /><site name="torso_0_site" pos="0 0 0" type="sphere" size="0.01" /><body name="leg_0_1" pos="0.21922105737590636 0 0"><geom name="leg_0_1_upper_geom" type="capsule" fromto="0.0 0.0 0.0 0.12723787856800509 0.0 0.0" size="0.04" /><joint name="leg_0_1_hip_joint" type="ball" damping="2.0" /><body name="leg_0_1_lower" pos="0.12723787856800509 0.0 0.0"><geom name="leg_0_1_lower_geom" type="capsule" fromto="0.12723787856800509 0.0 0.0 0.30106544602095264 0.0 0.0" size="0.04" /><joint name="leg_0_1_knee_joint" type="hinge" axis="0 1 0" range="-90 90" damping="4.0" limited="true" /><body name="leg_0_1_foot" pos="0.30106544602095264 0.0 0.0"><geom name="leg_0_1_foot_geom" type="cylinder" fromto="0.30106544602095264 0.0 0.0 0.49421903223008296 0.0 0.0" size="0.04" /><joint name="leg_0_1_ankle_joint" type="ball" damping="6.0" /></body></body></body><body name="leg_0_2" pos="-0.21922105737590636 0 0"><geom name="leg_0_2_upper_geom" type="capsule" fromto="0.0 0.0 0.0 0.18384523010486514 0.0 0.0" size="0.04" /><joint name="leg_0_2_hip_joint" type="ball" damping="2.0" /><body name="leg_0_2_lower" pos="0.18384523010486514 0.0 0.0"><geom name="leg_0_2_lower_geom" type="capsule" fromto="0.18384523010486514 0.0 0.0 0.37893598970672127 0.0 0.0" size="0.04" /><joint name="leg_0_2_knee_joint" type="hinge" axis="0 1 0" range="-90 90" damping="4.0" limited="true" /><body name="leg_0_2_foot" pos="0.37893598970672127 0.0 0.0"><geom name="leg_0_2_foot_geom" type="cylinder" fromto="0.37893598970672127 0.0 0.0 0.5440525253643766 0.0 0.0" size="0.04" /><joint name="leg_0_2_ankle_joint" type="ball" damping="6.0" /></body></body></body><body name="leg_0_3" pos="0.21922105737590636 0 0"><geom name="leg_0_3_upper_geom" type="capsule" fromto="0.0 0.0 0.0 0.1783585904967378 0.0 0.0" size="0.04" /><joint name="leg_0_3_hip_joint" type="ball" damping="2.0" /><body name="leg_0_3_lower" pos="0.1783585904967378 0.0 0.0"><geom name="leg_0_3_lower_geom" type="capsule" fromto="0.1783585904967378 0.0 0.0 0.36239198676776607 0.0 0.0" size="0.04" /><joint name="leg_0_3_knee_joint" type="hinge" axis="0 1 0" range="-90 90" damping="4.0" limited="true" /><body name="leg_0_3_foot" pos="0.36239198676776607 0.0 0.0"><geom name="leg_0_3_foot_geom" type="cylinder" fromto="0.36239198676776607 0.0 0.0 0.5260987353114779 0.0 0.0" size="0.04" /><joint name="leg_0_3_ankle_joint" type="ball" damping="6.0" /></body></body></body><body name="leg_0_4" pos="0 -0.09141329452301175 0"><geom name="leg_0_4_upper_geom" type="capsule" fromto="0.0 0.0 0.0 0.1733319591129253 0.0 0.0" size="0.04" /><joint name="leg_0_4_hip_joint" type="ball" damping="2.0" /><body name="leg_0_4_lower" pos="0.1733319591129253 0.0 0.0"><geom name="leg_0_4_lower_geom" type="capsule" fromto="0.1733319591129253 0.0 0.0 0.30600285721019704 0.0 0.0" size="0.04" /><joint name="leg_0_4_knee_joint" type="hinge" axis="0 1 0" range="-90 90" damping="4.0" limited="true" /><body name="leg_0_4_foot" pos="0.30600285721019704 0.0 0.0"><geom name="leg_0_4_foot_geom" type="cylinder" fromto="0.30600285721019704 0.0 0.0 0.4796308179991893 0.0 0.0" size="0.04" /><joint name="leg_0_4_ankle_joint" type="ball" damping="6.0" /></body></body></body></body><geom name="flag_0" type="box" size="0.05 0.05 0.5" pos="-7.450233379862263 -6.811538960317227 0" material="red" contype="1" conaffinity="1" /><body name="torso_1" pos="0 -6.5 0.75"><geom name="torso_geom_torso_1" type="box" size="0.3616448847557103 0.1419368230304678 0.0774318418483266" pos="0 0 0" contype="1" conaffinity="2" material="green" /><joint name="torso_1_root" type="free" armature="0" damping="0" limited="false" /><site name="torso_1_site" pos="0 0 0" type="sphere" size="0.01" /><body name="leg_1_1" pos="-0.18082244237785516 0 0"><geom name="leg_1_1_upper_geom" type="capsule" fromto="0.0 0.0 0.0 0.11391210742820541 0.0 0.0" size="0.04" /><joint name="leg_1_1_hip_joint" type="ball" damping="2.0" /><body name="leg_1_1_lower" pos="0.11391210742820541 0.0 0.0"><geom name="leg_1_1_lower_geom" type="capsule" fromto="0.11391210742820541 0.0 0.0 0.2913574560936691 0.0 0.0" size="0.04" /><joint name="leg_1_1_knee_joint" type="hinge" axis="0 1 0" range="-90 90" damping="4.0" limited="true" /><body name="leg_1_1_foot" pos="0.2913574560936691 0.0 0.0"><geom name="leg_1_1_foot_geom" type="cylinder" fromto="0.2913574560936691 0.0 0.0 0.42393777301908825 0.0 0.0" size="0.04" /><joint name="leg_1_1_ankle_joint" type="ball" damping="6.0" /></body></body></body></body><geom name="flag_1" type="box" size="0.05 0.05 0.5" pos="-0.5891818555668098 -5.691999541416683 0" material="green" contype="1" conaffinity="2" /><body name="torso_2" pos="6.5 -6.5 0.75"><geom name="torso_geom_torso_2" type="box" size="0.34667388521618603 0.14479468650949429 0.07681692433474215" pos="0 0 0" contype="1" conaffinity="3" material="blue" /><joint name="torso_2_root" type="free" armature="0" damping="0" limited="false" /><site name="torso_2_site" pos="0 0 0" type="sphere" size="0.01" /><body name="leg_2_1" pos="0 0.07239734325474714 0"><geom name="leg_2_1_upper_geom" type="capsule" fromto="0.0 0.0 0.0 0.19087407568699644 0.0 0.0" size="0.04" /><joint name="leg_2_1_hip_joint" type="ball" damping="2.0" /><body name="leg_2_1_lower" pos="0.19087407568699644 0.0 0.0"><geom name="leg_2_1_lower_geom" type="capsule" fromto="0.19087407568699644 0.0 0.0 0.3030091150195847 0.0 0.0" size="0.04" /><joint name="leg_2_1_knee_joint" type="hinge" axis="0 1 0" range="-90 90" damping="4.0" limited="true" /><body name="leg_2_1_foot" pos="0.3030091150195847 0.0 0.0"><geom name="leg_2_1_foot_geom" type="cylinder" fromto="0.3030091150195847 0.0 0.0 0.4687890401527088 0.0 0.0" size="0.04" /><joint name="leg_2_1_ankle_joint" type="ball" damping="6.0" /></body></body></body><body name="leg_2_2" pos="-0.17333694260809301 0 0"><geom name="leg_2_2_upper_geom" type="capsule" fromto="0.0 0.0 0.0 0.12788410536740488 0.0 0.0" size="0.04" /><joint name="leg_2_2_hip_joint" type="ball" damping="2.0" /><body name="leg_2_2_lower" pos="0.12788410536740488 0.0 0.0"><geom name="leg_2_2_lower_geom" type="capsule" fromto="0.12788410536740488 0.0 0.0 0.31837749384138575 0.0 0.0" size="0.04" /><joint name="leg_2_2_knee_joint" type="hinge" axis="0 1 0" range="-90 90" damping="4.0" limited="true" /><body name="leg_2_2_foot" pos="0.31837749384138575 0.0 0.0"><geom name="leg_2_2_foot_geom" type="cylinder" fromto="0.31837749384138575 0.0 0.0 0.4536230187188225 0.0 0.0" size="0.04" /><joint name="leg_2_2_ankle_joint" type="ball" damping="6.0" /></body></body></body><body name="leg_2_3" pos="0 -0.07239734325474714 0"><geom name="leg_2_3_upper_geom" type="capsule" fromto="0.0 0.0 0.0 0.19736799203227953 0.0 0.0" size="0.04" /><joint name="leg_2_3_hip_joint" type="ball" damping="2.0" /><body name="leg_2_3_lower" pos="0.19736799203227953 0.0 0.0"><geom name="leg_2_3_lower_geom" type="capsule" fromto="0.19736799203227953 0.0 0.0 0.3773826215066187 0.0 0.0" size="0.04" /><joint name="leg_2_3_knee_joint" type="hinge" axis="0 1 0" range="-90 90" damping="4.0" limited="true" /><body name="leg_2_3_foot" pos="0.3773826215066187 0.0 0.0"><geom name="leg_2_3_foot_geom" type="cylinder" fromto="0.3773826215066187 0.0 0.0 0.502170539979095 0.0 0.0" size="0.04" /><joint name="leg_2_3_ankle_joint" type="ball" damping="6.0" /></body></body></body><body name="leg_2_4" pos="0.17333694260809301 0 0"><geom name="leg_2_4_upper_geom" type="capsule" fromto="0.0 0.0 0.0 0.14509478289921451 0.0 0.0" size="0.04" /><joint name="leg_2_4_hip_joint" type="ball" damping="2.0" /><body name="leg_2_4_lower" pos="0.14509478289921451 0.0 0.0"><geom name="leg_2_4_lower_geom" type="capsule" fromto="0.14509478289921451 0.0 0.0 0.33314036875302633 0.0 0.0" size="0.04" /><joint name="leg_2_4_knee_joint" type="hinge" axis="0 1 0" range="-90 90" damping="4.0" limited="true" /><body name="leg_2_4_foot" pos="0.33314036875302633 0.0 0.0"><geom name="leg_2_4_foot_geom" type="cylinder" fromto="0.33314036875302633 0.0 0.0 0.5288476284196961 0.0 0.0" size="0.04" /><joint name="leg_2_4_ankle_joint" type="ball" damping="6.0" /></body></body></body></body><geom name="flag_2" type="box" size="0.05 0.05 0.5" pos="6.016131887416356 -5.624859068706793 0" material="blue" contype="1" conaffinity="3" /><body name="torso_3" pos="-6.5 0 0.75"><geom name="torso_geom_torso_3" type="box" size="0.40338059468118737 0.18737152916895272 0.053179829426269476" pos="0 0 0" contype="1" conaffinity="4" material="yellow" /><joint name="torso_3_root" type="free" armature="0" damping="0" limited="false" /><site name="torso_3_site" pos="0 0 0" type="sphere" size="0.01" /><body name="leg_3_1" pos="0 -0.09368576458447636 0"><geom name="leg_3_1_upper_geom" type="capsule" fromto="0.0 0.0 0.0 0.10140624361633091 0.0 0.0" size="0.04" /><joint name="leg_3_1_hip_joint" type="ball" damping="2.0" /><body name="leg_3_1_lower" pos="0.10140624361633091 0.0 0.0"><geom name="leg_3_1_lower_geom" type="capsule" fromto="0.10140624361633091 0.0 0.0 0.226126415781222 0.0 0.0" size="0.04" /><joint name="leg_3_1_knee_joint" type="hinge" axis="0 1 0" range="-90 90" damping="4.0" limited="true" /><body name="leg_3_1_foot" pos="0.226126415781222 0.0 0.0"><geom name="leg_3_1_foot_geom" type="cylinder" fromto="0.226126415781222 0.0 0.0 0.32630327988964175 0.0 0.0" size="0.04" /><joint name="leg_3_1_ankle_joint" type="ball" damping="6.0" /></body></body></body><body name="leg_3_2" pos="0 -0.09368576458447636 0"><geom name="leg_3_2_upper_geom" type="capsule" fromto="0.0 0.0 0.0 0.1695880624318276 0.0 0.0" size="0.04" /><joint name="leg_3_2_hip_joint" type="ball" damping="2.0" /><body name="leg_3_2_lower" pos="0.1695880624318276 0.0 0.0"><geom name="leg_3_2_lower_geom" type="capsule" fromto="0.1695880624318276 0.0 0.0 0.3129993988495433 0.0 0.0" size="0.04" /><joint name="leg_3_2_knee_joint" type="hinge" axis="0 1 0" range="-90 90" damping="4.0" limited="true" /><body name="leg_3_2_foot" pos="0.3129993988495433 0.0 0.0"><geom name="leg_3_2_foot_geom" type="cylinder" fromto="0.3129993988495433 0.0 0.0 0.46770020369756937 0.0 0.0" size="0.04" /><joint name="leg_3_2_ankle_joint" type="ball" damping="6.0" /></body></body></body></body><geom name="flag_3" type="box" size="0.05 0.05 0.5" pos="-7.180257559772274 0.7329731593808 0" material="yellow" contype="1" conaffinity="4" /><body name="torso_4" pos="0 0 0.75"><geom name="torso_geom_torso_4" type="box" size="0.2511291870787262 0.14663824384167456 0.0824059011139518" pos="0 0 0" contype="1" conaffinity="5" material="purple" /><joint name="torso_4_root" type="free" armature="0" damping="0" limited="false" /><site name="torso_4_site" pos="0 0 0" type="sphere" size="0.01" /><body name="leg_4_1" pos="0 0.07331912192083728 0"><geom name="leg_4_1_upper_geom" type="capsule" fromto="0.0 0.0 0.0 0.1693297506399168 0.0 0.0" size="0.04" /><joint name="leg_4_1_hip_joint" type="ball" damping="2.0" /><body name="leg_4_1_lower" pos="0.1693297506399168 0.0 0.0"><geom name="leg_4_1_lower_geom" type="capsule" fromto="0.1693297506399168 0.0 0.0 0.34916850549045486 0.0 0.0" size="0.04" /><joint name="leg_4_1_knee_joint" type="hinge" axis="0 1 0" range="-90 90" damping="4.0" limited="true" /><body name="leg_4_1_foot" pos="0.34916850549045486 0.0 0.0"><geom name="leg_4_1_foot_geom" type="cylinder" fromto="0.34916850549045486 0.0 0.0 0.5094913265438211 0.0 0.0" size="0.04" /><joint name="leg_4_1_ankle_joint" type="ball" damping="6.0" /></body></body></body><body name="leg_4_2" pos="0 -0.07331912192083728 0"><geom name="leg_4_2_upper_geom" type="capsule" fromto="0.0 0.0 0.0 0.11515587361860545 0.0 0.0" size="0.04" /><joint name="leg_4_2_hip_joint" type="ball" damping="2.0" /><body name="leg_4_2_lower" pos="0.11515587361860545 0.0 0.0"><geom name="leg_4_2_lower_geom" type="capsule" fromto="0.11515587361860545 0.0 0.0 0.3131448287342636 0.0 0.0" size="0.04" /><joint name="leg_4_2_knee_joint" type="hinge" axis="0 1 0" range="-90 90" damping="4.0" limited="true" /><body name="leg_4_2_foot" pos="0.3131448287342636 0.0 0.0"><geom name="leg_4_2_foot_geom" type="cylinder" fromto="0.3131448287342636 0.0 0.0 0.428788712014762 0.0 0.0" size="0.04" /><joint name="leg_4_2_ankle_joint" type="ball" damping="6.0" /></body></body></body><body name="leg_4_3" pos="0 0.07331912192083728 0"><geom name="leg_4_3_upper_geom" type="capsule" fromto="0.0 0.0 0.0 0.11473654265601346 0.0 0.0" size="0.04" /><joint name="leg_4_3_hip_joint" type="ball" damping="2.0" /><body name="leg_4_3_lower" pos="0.11473654265601346 0.0 0.0"><geom name="leg_4_3_lower_geom" type="capsule" fromto="0.11473654265601346 0.0 0.0 0.2559048947275482 0.0 0.0" size="0.04" /><joint name="leg_4_3_knee_joint" type="hinge" axis="0 1 0" range="-90 90" damping="4.0" limited="true" /><body name="leg_4_3_foot" pos="0.2559048947275482 0.0 0.0"><geom name="leg_4_3_foot_geom" type="cylinder" fromto="0.2559048947275482 0.0 0.0 0.41782046327871447 0.0 0.0" size="0.04" /><joint name="leg_4_3_ankle_joint" type="ball" damping="6.0" /></body></body></body><body name="leg_4_4" pos="-0.1255645935393631 0 0"><geom name="leg_4_4_upper_geom" type="capsule" fromto="0.0 0.0 0.0 0.10113647950587283 0.0 0.0" size="0.04" /><joint name="leg_4_4_hip_joint" type="ball" damping="2.0" /><body name="leg_4_4_lower" pos="0.10113647950587283 0.0 0.0"><geom name="leg_4_4_lower_geom" type="capsule" fromto="0.10113647950587283 0.0 0.0 0.27906336393470865 0.0 0.0" size="0.04" /><joint name="leg_4_4_knee_joint" type="hinge" axis="0 1 0" range="-90 90" damping="4.0" limited="true" /><body name="leg_4_4_foot" pos="0.27906336393470865 0.0 0.0"><geom name="leg_4_4_foot_geom" type="cylinder" fromto="0.27906336393470865 0.0 0.0 0.4768038689148357 0.0 0.0" size="0.04" /><joint name="leg_4_4_ankle_joint" type="ball" damping="6.0" /></body></body></body></body><geom name="flag_4" type="box" size="0.05 0.05 0.5" pos="-0.8148566036801473 -0.5796625875790633 0" material="purple" contype="1" conaffinity="5" /><body name="torso_5" pos="6.5 0 0.75"><geom name="torso_geom_torso_5" type="box" size="0.3053468254013878 0.10813661886956925 0.09469490419864479" pos="0 0 0" contype="1" conaffinity="6" material="orange" /><joint name="torso_5_root" type="free" armature="0" damping="0" limited="false" /><site name="torso_5_site" pos="0 0 0" type="sphere" size="0.01" /><body name="leg_5_1" pos="0 -0.05406830943478463 0"><geom name="leg_5_1_upper_geom" type="capsule" fromto="0.0 0.0 0.0 0.115308399981987 0.0 0.0" size="0.04" /><joint name="leg_5_1_hip_joint" type="ball" damping="2.0" /><body name="leg_5_1_lower" pos="0.115308399981987 0.0 0.0"><geom name="leg_5_1_lower_geom" type="capsule" fromto="0.115308399981987 0.0 0.0 0.2899777229244197 0.0 0.0" size="0.04" /><joint name="leg_5_1_knee_joint" type="hinge" axis="0 1 0" range="-90 90" damping="4.0" limited="true" /><body name="leg_5_1_foot" pos="0.2899777229244197 0.0 0.0"><geom name="leg_5_1_foot_geom" type="cylinder" fromto="0.2899777229244197 0.0 0.0 0.4473075093430339 0.0 0.0" size="0.04" /><joint name="leg_5_1_ankle_joint" type="ball" damping="6.0" /></body></body></body></body><geom name="flag_5" type="box" size="0.05 0.05 0.5" pos="5.600724604884164 -0.43738285716207165 0" material="orange" contype="1" conaffinity="6" /><body name="torso_6" pos="-6.5 6.5 0.75"><geom name="torso_geom_torso_6" type="box" size="0.38707018394165615 0.198140120471532 0.08785321313954646" pos="0 0 0" contype="1" conaffinity="7" material="pink" /><joint name="torso_6_root" type="free" armature="0" damping="0" limited="false" /><site name="torso_6_site" pos="0 0 0" type="sphere" size="0.01" /><body name="leg_6_1" pos="0.19353509197082808 0 0"><geom name="leg_6_1_upper_geom" type="capsule" fromto="0.0 0.0 0.0 0.15218873067239763 0.0 0.0" size="0.04" /><joint name="leg_6_1_hip_joint" type="ball" damping="2.0" /><body name="leg_6_1_lower" pos="0.15218873067239763 0.0 0.0"><geom name="leg_6_1_lower_geom" type="capsule" fromto="0.15218873067239763 0.0 0.0 0.3217776688467471 0.0 0.0" size="0.04" /><joint name="leg_6_1_knee_joint" type="hinge" axis="0 1 0" range="-90 90" damping="4.0" limited="true" /><body name="leg_6_1_foot" pos="0.3217776688467471 0.0 0.0"><geom name="leg_6_1_foot_geom" type="cylinder" fromto="0.3217776688467471 0.0 0.0 0.513076437960242 0.0 0.0" size="0.04" /><joint name="leg_6_1_ankle_joint" type="ball" damping="6.0" /></body></body></body><body name="leg_6_2" pos="0 -0.099070060235766 0"><geom name="leg_6_2_upper_geom" type="capsule" fromto="0.0 0.0 0.0 0.14957056666982282 0.0 0.0" size="0.04" /><joint name="leg_6_2_hip_joint" type="ball" damping="2.0" /><body name="leg_6_2_lower" pos="0.14957056666982282 0.0 0.0"><geom name="leg_6_2_lower_geom" type="capsule" fromto="0.14957056666982282 0.0 0.0 0.3172292045863759 0.0 0.0" size="0.04" /><joint name="leg_6_2_knee_joint" type="hinge" axis="0 1 0" range="-90 90" damping="4.0" limited="true" /><body name="leg_6_2_foot" pos="0.3172292045863759 0.0 0.0"><geom name="leg_6_2_foot_geom" type="cylinder" fromto="0.3172292045863759 0.0 0.0 0.4954156977096631 0.0 0.0" size="0.04" /><joint name="leg_6_2_ankle_joint" type="ball" damping="6.0" /></body></body></body></body><geom name="flag_6" type="box" size="0.05 0.05 0.5" pos="-7.483519404541246 6.319197397997614 0" material="pink" contype="1" conaffinity="7" /><body name="torso_7" pos="0 6.5 0.75"><geom name="torso_geom_torso_7" type="box" size="0.2109812898780073 0.13957969286942473 0.08766060703555875" pos="0 0 0" contype="1" conaffinity="8" material="grey" /><joint name="torso_7_root" type="free" armature="0" damping="0" limited="false" /><site name="torso_7_site" pos="0 0 0" type="sphere" size="0.01" /><body name="leg_7_1" pos="0 -0.06978984643471237 0"><geom name="leg_7_1_upper_geom" type="capsule" fromto="0.0 0.0 0.0 0.16451258774871863 0.0 0.0" size="0.04" /><joint name="leg_7_1_hip_joint" type="ball" damping="2.0" /><body name="leg_7_1_lower" pos="0.16451258774871863 0.0 0.0"><geom name="leg_7_1_lower_geom" type="capsule" fromto="0.16451258774871863 0.0 0.0 0.2686130368114106 0.0 0.0" size="0.04" /><joint name="leg_7_1_knee_joint" type="hinge" axis="0 1 0" range="-90 90" damping="4.0" limited="true" /><body name="leg_7_1_foot" pos="0.2686130368114106 0.0 0.0"><geom name="leg_7_1_foot_geom" type="cylinder" fromto="0.2686130368114106 0.0 0.0 0.3937185509861615 0.0 0.0" size="0.04" /><joint name="leg_7_1_ankle_joint" type="ball" damping="6.0" /></body></body></body><body name="leg_7_2" pos="-0.10549064493900365 0 0"><geom name="leg_7_2_upper_geom" type="capsule" fromto="0.0 0.0 0.0 0.18585607424395184 0.0 0.0" size="0.04" /><joint name="leg_7_2_hip_joint" type="ball" damping="2.0" /><body name="leg_7_2_lower" pos="0.18585607424395184 0.0 0.0"><geom name="leg_7_2_lower_geom" type="capsule" fromto="0.18585607424395184 0.0 0.0 0.31047925664176473 0.0 0.0" size="0.04" /><joint name="leg_7_2_knee_joint" type="hinge" axis="0 1 0" range="-90 90" damping="4.0" limited="true" /><body name="leg_7_2_foot" pos="0.31047925664176473 0.0 0.0"><geom name="leg_7_2_foot_geom" type="cylinder" fromto="0.31047925664176473 0.0 0.0 0.5028991407940616 0.0 0.0" size="0.04" /><joint name="leg_7_2_ankle_joint" type="ball" damping="6.0" /></body></body></body><body name="leg_7_3" pos="0 0.06978984643471237 0"><geom name="leg_7_3_upper_geom" type="capsule" fromto="0.0 0.0 0.0 0.12075793074375345 0.0 0.0" size="0.04" /><joint name="leg_7_3_hip_joint" type="ball" damping="2.0" /><body name="leg_7_3_lower" pos="0.12075793074375345 0.0 0.0"><geom name="leg_7_3_lower_geom" type="capsule" fromto="0.12075793074375345 0.0 0.0 0.24339580151632456 0.0 0.0" size="0.04" /><joint name="leg_7_3_knee_joint" type="hinge" axis="0 1 0" range="-90 90" damping="4.0" limited="true" /><body name="leg_7_3_foot" pos="0.24339580151632456 0.0 0.0"><geom name="leg_7_3_foot_geom" type="cylinder" fromto="0.24339580151632456 0.0 0.0 0.395857822388463 0.0 0.0" size="0.04" /><joint name="leg_7_3_ankle_joint" type="ball" damping="6.0" /></body></body></body></body><geom name="flag_7" type="box" size="0.05 0.05 0.5" pos="0.06455935948703709 5.502086131420841 0" material="grey" contype="1" conaffinity="8" /><body name="torso_8" pos="6.5 6.5 0.75"><geom name="torso_geom_torso_8" type="box" size="0.401851015335902 0.111948706205804 0.06278159619908388" pos="0 0 0" contype="1" conaffinity="9" material="brown" /><joint name="torso_8_root" type="free" armature="0" damping="0" limited="false" /><site name="torso_8_site" pos="0 0 0" type="sphere" size="0.01" /><body name="leg_8_1" pos="0 -0.055974353102902 0"><geom name="leg_8_1_upper_geom" type="capsule" fromto="0.0 0.0 0.0 0.1123067178182876 0.0 0.0" size="0.04" /><joint name="leg_8_1_hip_joint" type="ball" damping="2.0" /><body name="leg_8_1_lower" pos="0.1123067178182876 0.0 0.0"><geom name="leg_8_1_lower_geom" type="capsule" fromto="0.1123067178182876 0.0 0.0 0.27458868348751414 0.0 0.0" size="0.04" /><joint name="leg_8_1_knee_joint" type="hinge" axis="0 1 0" range="-90 90" damping="4.0" limited="true" /><body name="leg_8_1_foot" pos="0.27458868348751414 0.0 0.0"><geom name="leg_8_1_foot_geom" type="cylinder" fromto="0.27458868348751414 0.0 0.0 0.44774298382555333 0.0 0.0" size="0.04" /><joint name="leg_8_1_ankle_joint" type="ball" damping="6.0" /></body></body></body><body name="leg_8_2" pos="0 0.055974353102902 0"><geom name="leg_8_2_upper_geom" type="capsule" fromto="0.0 0.0 0.0 0.14649828267135095 0.0 0.0" size="0.04" /><joint name="leg_8_2_hip_joint" type="ball" damping="2.0" /><body name="leg_8_2_lower" pos="0.14649828267135095 0.0 0.0"><geom name="leg_8_2_lower_geom" type="capsule" fromto="0.14649828267135095 0.0 0.0 0.25396391247882416 0.0 0.0" size="0.04" /><joint name="leg_8_2_knee_joint" type="hinge" axis="0 1 0" range="-90 90" damping="4.0" limited="true" /><body name="leg_8_2_foot" pos="0.25396391247882416 0.0 0.0"><geom name="leg_8_2_foot_geom" type="cylinder" fromto="0.25396391247882416 0.0 0.0 0.35857681597971564 0.0 0.0" size="0.04" /><joint name="leg_8_2_ankle_joint" type="ball" damping="6.0" /></body></body></body></body><geom name="flag_8" type="box" size="0.05 0.05 0.5" pos="7.477656976099359 6.710206653282564 0" material="brown" contype="1" conaffinity="9" /><geom name="north_wall" type="box" pos="0 10.05 0.25" size="10.05 0.05 0.25" material="MatPlane" /><geom name="south_wall" type="box" pos="0 -10.05 0.25" size="10.05 0.05 0.25" material="MatPlane" /><geom name="east_wall" type="box" pos="10.05 0 0.25" size="0.05 10.05 0.25" material="MatPlane" /><geom name="west_wall" type="box" pos="-10.05 0 0.25" size="0.05 10.05 0.25" material="MatPlane" /></worldbody><actuator><motor name="leg_0_1_hip_motor" joint="leg_0_1_hip_joint" ctrllimited="true" ctrlrange="-1 1" gear="200" /><motor name="leg_0_1_ankle_joint_motor" joint="leg_0_1_ankle_joint" ctrllimited="true" ctrlrange="-1 1" gear="200" /><motor name="leg_0_2_hip_motor" joint="leg_0_2_hip_joint" ctrllimited="true" ctrlrange="-1 1" gear="200" /><motor name="leg_0_2_ankle_joint_motor" joint="leg_0_2_ankle_joint" ctrllimited="true" ctrlrange="-1 1" gear="200" /><motor name="leg_0_3_hip_motor" joint="leg_0_3_hip_joint" ctrllimited="true" ctrlrange="-1 1" gear="200" /><motor name="leg_0_3_ankle_joint_motor" joint="leg_0_3_ankle_joint" ctrllimited="true" ctrlrange="-1 1" gear="200" /><motor name="leg_0_4_hip_motor" joint="leg_0_4_hip_joint" ctrllimited="true" ctrlrange="-1 1" gear="200" /><motor name="leg_0_4_ankle_joint_motor" joint="leg_0_4_ankle_joint" ctrllimited="true" ctrlrange="-1 1" gear="200" /><motor name="leg_1_1_hip_motor" joint="leg_1_1_hip_joint" ctrllimited="true" ctrlrange="-1 1" gear="200" /><motor name="leg_1_1_ankle_joint_motor" joint="leg_1_1_ankle_joint" ctrllimited="true" ctrlrange="-1 1" gear="200" /><motor name="leg_2_1_hip_motor" joint="leg_2_1_hip_joint" ctrllimited="true" ctrlrange="-1 1" gear="200" /><motor name="leg_2_1_ankle_joint_motor" joint="leg_2_1_ankle_joint" ctrllimited="true" ctrlrange="-1 1" gear="200" /><motor name="leg_2_2_hip_motor" joint="leg_2_2_hip_joint" ctrllimited="true" ctrlrange="-1 1" gear="200" /><motor name="leg_2_2_ankle_joint_motor" joint="leg_2_2_ankle_joint" ctrllimited="true" ctrlrange="-1 1" gear="200" /><motor name="leg_2_3_hip_motor" joint="leg_2_3_hip_joint" ctrllimited="true" ctrlrange="-1 1" gear="200" /><motor name="leg_2_3_ankle_joint_motor" joint="leg_2_3_ankle_joint" ctrllimited="true" ctrlrange="-1 1" gear="200" /><motor name="leg_2_4_hip_motor" joint="leg_2_4_hip_joint" ctrllimited="true" ctrlrange="-1 1" gear="200" /><motor name="leg_2_4_ankle_joint_motor" joint="leg_2_4_ankle_joint" ctrllimited="true" ctrlrange="-1 1" gear="200" /><motor name="leg_3_1_hip_motor" joint="leg_3_1_hip_joint" ctrllimited="true" ctrlrange="-1 1" gear="200" /><motor name="leg_3_1_ankle_joint_motor" joint="leg_3_1_ankle_joint" ctrllimited="true" ctrlrange="-1 1" gear="200" /><motor name="leg_3_2_hip_motor" joint="leg_3_2_hip_joint" ctrllimited="true" ctrlrange="-1 1" gear="200" /><motor name="leg_3_2_ankle_joint_motor" joint="leg_3_2_ankle_joint" ctrllimited="true" ctrlrange="-1 1" gear="200" /><motor name="leg_4_1_hip_motor" joint="leg_4_1_hip_joint" ctrllimited="true" ctrlrange="-1 1" gear="200" /><motor name="leg_4_1_ankle_joint_motor" joint="leg_4_1_ankle_joint" ctrllimited="true" ctrlrange="-1 1" gear="200" /><motor name="leg_4_2_hip_motor" joint="leg_4_2_hip_joint" ctrllimited="true" ctrlrange="-1 1" gear="200" /><motor name="leg_4_2_ankle_joint_motor" joint="leg_4_2_ankle_joint" ctrllimited="true" ctrlrange="-1 1" gear="200" /><motor name="leg_4_3_hip_motor" joint="leg_4_3_hip_joint" ctrllimited="true" ctrlrange="-1 1" gear="200" /><motor name="leg_4_3_ankle_joint_motor" joint="leg_4_3_ankle_joint" ctrllimited="true" ctrlrange="-1 1" gear="200" /><motor name="leg_4_4_hip_motor" joint="leg_4_4_hip_joint" ctrllimited="true" ctrlrange="-1 1" gear="200" /><motor name="leg_4_4_ankle_joint_motor" joint="leg_4_4_ankle_joint" ctrllimited="true" ctrlrange="-1 1" gear="200" /><motor name="leg_5_1_hip_motor" joint="leg_5_1_hip_joint" ctrllimited="true" ctrlrange="-1 1" gear="200" /><motor name="leg_5_1_ankle_joint_motor" joint="leg_5_1_ankle_joint" ctrllimited="true" ctrlrange="-1 1" gear="200" /><motor name="leg_6_1_hip_motor" joint="leg_6_1_hip_joint" ctrllimited="true" ctrlrange="-1 1" gear="200" /><motor name="leg_6_1_ankle_joint_motor" joint="leg_6_1_ankle_joint" ctrllimited="true" ctrlrange="-1 1" gear="200" /><motor name="leg_6_2_hip_motor" joint="leg_6_2_hip_joint" ctrllimited="true" ctrlrange="-1 1" gear="200" /><motor name="leg_6_2_ankle_joint_motor" joint="leg_6_2_ankle_joint" ctrllimited="true" ctrlrange="-1 1" gear="200" /><motor name="leg_7_1_hip_motor" joint="leg_7_1_hip_joint" ctrllimited="true" ctrlrange="-1 1" gear="200" /><motor name="leg_7_1_ankle_joint_motor" joint="leg_7_1_ankle_joint" ctrllimited="true" ctrlrange="-1 1" gear="200" /><motor name="leg_7_2_hip_motor" joint="leg_7_2_hip_joint" ctrllimited="true" ctrlrange="-1 1" gear="200" /><motor name="leg_7_2_ankle_joint_motor" joint="leg_7_2_ankle_joint" ctrllimited="true" ctrlrange="-1 1" gear="200" /><motor name="leg_7_3_hip_motor" joint="leg_7_3_hip_joint" ctrllimited="true" ctrlrange="-1 1" gear="200" /><motor name="leg_7_3_ankle_joint_motor" joint="leg_7_3_ankle_joint" ctrllimited="true" ctrlrange="-1 1" gear="200" /><motor name="leg_8_1_hip_motor" joint="leg_8_1_hip_joint" ctrllimited="true" ctrlrange="-1 1" gear="200" /><motor name="leg_8_1_ankle_joint_motor" joint="leg_8_1_ankle_joint" ctrllimited="true" ctrlrange="-1 1" gear="200" /><motor name="leg_8_2_hip_motor" joint="leg_8_2_hip_joint" ctrllimited="true" ctrlrange="-1 1" gear="200" /><motor name="leg_8_2_ankle_joint_motor" joint="leg_8_2_ankle_joint" ctrllimited="true" ctrlrange="-1 1" gear="200" /></actuator><sensor><accelerometer name="torso_0_accel" site="torso_0_site" /><gyro name="torso_0_gyro" site="torso_0_site" /><accelerometer name="torso_1_accel" site="torso_1_site" /><gyro name="torso_1_gyro" site="torso_1_site" /><accelerometer name="torso_2_accel" site="torso_2_site" /><gyro name="torso_2_gyro" site="torso_2_site" /><accelerometer name="torso_3_accel" site="torso_3_site" /><gyro name="torso_3_gyro" site="torso_3_site" /><accelerometer name="torso_4_accel" site="torso_4_site" /><gyro name="torso_4_gyro" site="torso_4_site" /><accelerometer name="torso_5_accel" site="torso_5_site" /><gyro name="torso_5_gyro" site="torso_5_site" /><accelerometer name="torso_6_accel" site="torso_6_site" /><gyro name="torso_6_gyro" site="torso_6_site" /><accelerometer name="torso_7_accel" site="torso_7_site" /><gyro name="torso_7_gyro" site="torso_7_site" /><accelerometer name="torso_8_accel" site="torso_8_site" /><gyro name="torso_8_gyro" site="torso_8_site" /></sensor></mujoco>