<mujoco><option timestep="0.002" /><asset><texture name="checkered" type="2d" builtin="checker" rgb1="0.2 0.3 0.4" rgb2="0.9 0.9 0.9" width="512" height="512" /><material name="MatCheckered" texture="checkered" reflectance="0.5" /><material name="MatPlane" reflectance="0.5" shininess="1" specular="1" /><material name="red" rgba="1 0 0 1" /><material name="green" rgba="0 1 0 1" /><material name="blue" rgba="0 0 1 1" /><material name="yellow" rgba="1 1 0 1" /><material name="purple" rgba="0.5 0 0.5 1" /><material name="orange" rgba="1 0.5 0 1" /><material name="pink" rgba="1 0.7 0.7 1" /><material name="grey" rgba="0.5 0.5 0.5 1" /><material name="brown" rgba="0.6 0.3 0 1" /></asset><worldbody><geom name="floor" type="plane" size="10 10 0.1" pos="0 0 0" material="MatCheckered" /><body name="torso_0" pos="-6.5 -6.5 0.75"><geom name="torso_geom_torso_0" type="box" size="0.2715485036837782 0.1564616013803122 0.08722629893335843" pos="0 0 0" contype="1" conaffinity="1" material="red" /><joint name="torso_0_root" type="free" armature="0" damping="0" limited="false" /><site name="torso_0_site" pos="0 0 0" type="sphere" size="0.01" /><body name="leg_0_1" pos="0.1357742518418891 0 0"><geom name="leg_0_1_upper_geom" type="capsule" fromto="0.0 0.0 0.0 0.13562162647162107 0.0 0.0" size="0.04" /><joint name="leg_0_1_hip_joint" type="ball" damping="2.0" /><body name="leg_0_1_lower" pos="0.13562162647162107 0.0 0.0"><geom name="leg_0_1_lower_geom" type="capsule" fromto="0.13562162647162107 0.0 0.0 0.33354921485505895 0.0 0.0" size="0.04" /><joint name="leg_0_1_knee_joint" type="hinge" axis="0 1 0" range="-90 90" damping="4.0" limited="true" /><body name="leg_0_1_foot" pos="0.33354921485505895 0.0 0.0"><geom name="leg_0_1_foot_geom" type="cylinder" fromto="0.33354921485505895 0.0 0.0 0.4711827492103236 0.0 0.0" size="0.04" /><joint name="leg_0_1_ankle_joint" type="ball" damping="6.0" /></body></body></body></body><geom name="flag_0" type="box" size="0.05 0.05 0.5" pos="-9.50556305023548 -8.293485642836092 0" material="red" contype="1" conaffinity="1" /><body name="torso_1" pos="0 -6.5 0.75"><geom name="torso_geom_torso_1" type="box" size="0.499949666755045 0.13842242802780602 0.0641584101805017" pos="0 0 0" contype="1" conaffinity="2" material="green" /><joint name="torso_1_root" type="free" armature="0" damping="0" limited="false" /><site name="torso_1_site" pos="0 0 0" type="sphere" size="0.01" /><body name="leg_1_1" pos="0 0.06921121401390301 0"><geom name="leg_1_1_upper_geom" type="capsule" fromto="0.0 0.0 0.0 0.17722462562847033 0.0 0.0" size="0.04" /><joint name="leg_1_1_hip_joint" type="ball" damping="2.0" /><body name="leg_1_1_lower" pos="0.17722462562847033 0.0 0.0"><geom name="leg_1_1_lower_geom" type="capsule" fromto="0.17722462562847033 0.0 0.0 0.3434400944607545 0.0 0.0" size="0.04" /><joint name="leg_1_1_knee_joint" type="hinge" axis="0 1 0" range="-90 90" damping="4.0" limited="true" /><body name="leg_1_1_foot" pos="0.3434400944607545 0.0 0.0"><geom name="leg_1_1_foot_geom" type="cylinder" fromto="0.3434400944607545 0.0 0.0 0.447050208322283 0.0 0.0" size="0.04" /><joint name="leg_1_1_ankle_joint" type="ball" damping="6.0" /></body></body></body></body><geom name="flag_1" type="box" size="0.05 0.05 0.5" pos="-1.4032252502028253 -3.293606559201878 0" material="green" contype="1" conaffinity="2" /><body name="torso_2" pos="6.5 -6.5 0.75"><geom name="torso_geom_torso_2" type="box" size="0.4907053094326949 0.16632560117891104 0.09764812327818276" pos="0 0 0" contype="1" conaffinity="3" material="blue" /><joint name="torso_2_root" type="free" armature="0" damping="0" limited="false" /><site name="torso_2_site" pos="0 0 0" type="sphere" size="0.01" /><body name="leg_2_1" pos="0 0.08316280058945552 0"><geom name="leg_2_1_upper_geom" type="capsule" fromto="0.0 0.0 0.0 0.11267121036545757 0.0 0.0" size="0.04" /><joint name="leg_2_1_hip_joint" type="ball" damping="2.0" /><body name="leg_2_1_lower" pos="0.11267121036545757 0.0 0.0"><geom name="leg_2_1_lower_geom" type="capsule" fromto="0.11267121036545757 0.0 0.0 0.27223789071704746 0.0 0.0" size="0.04" /><joint name="leg_2_1_knee_joint" type="hinge" axis="0 1 0" range="-90 90" damping="4.0" limited="true" /><body name="leg_2_1_foot" pos="0.27223789071704746 0.0 0.0"><geom name="leg_2_1_foot_geom" type="cylinder" fromto="0.27223789071704746 0.0 0.0 0.4195034054328575 0.0 0.0" size="0.04" /><joint name="leg_2_1_ankle_joint" type="ball" damping="6.0" /></body></body></body></body><geom name="flag_2" type="box" size="0.05 0.05 0.5" pos="4.497045453951098 -3.629778216502767 0" material="blue" contype="1" conaffinity="3" /><body name="torso_3" pos="-6.5 0 0.75"><geom name="torso_geom_torso_3" type="box" size="0.25973375803101256 0.11461685359610245 0.09213482328298264" pos="0 0 0" contype="1" conaffinity="4" material="yellow" /><joint name="torso_3_root" type="free" armature="0" damping="0" limited="false" /><site name="torso_3_site" pos="0 0 0" type="sphere" size="0.01" /><body name="leg_3_1" pos="0.12986687901550628 0 0"><geom name="leg_3_1_upper_geom" type="capsule" fromto="0.0 0.0 0.0 0.14390702247672765 0.0 0.0" size="0.04" /><joint name="leg_3_1_hip_joint" type="ball" damping="2.0" /><body name="leg_3_1_lower" pos="0.14390702247672765 0.0 0.0"><geom name="leg_3_1_lower_geom" type="capsule" fromto="0.14390702247672765 0.0 0.0 0.29534469833342625 0.0 0.0" size="0.04" /><joint name="leg_3_1_knee_joint" type="hinge" axis="0 1 0" range="-90 90" damping="4.0" limited="true" /><body name="leg_3_1_foot" pos="0.29534469833342625 0.0 0.0"><geom name="leg_3_1_foot_geom" type="cylinder" fromto="0.29534469833342625 0.0 0.0 0.43432670351174785 0.0 0.0" size="0.04" /><joint name="leg_3_1_ankle_joint" type="ball" damping="6.0" /></body></body></body><body name="leg_3_2" pos="0.12986687901550628 0 0"><geom name="leg_3_2_upper_geom" type="capsule" fromto="0.0 0.0 0.0 0.17194260274238252 0.0 0.0" size="0.04" /><joint name="leg_3_2_hip_joint" type="ball" damping="2.0" /><body name="leg_3_2_lower" pos="0.17194260274238252 0.0 0.0"><geom name="leg_3_2_lower_geom" type="capsule" fromto="0.17194260274238252 0.0 0.0 0.36419859897490403 0.0 0.0" size="0.04" /><joint name="leg_3_2_knee_joint" type="hinge" axis="0 1 0" range="-90 90" damping="4.0" limited="true" /><body name="leg_3_2_foot" pos="0.36419859897490403 0.0 0.0"><geom name="leg_3_2_foot_geom" type="cylinder" fromto="0.36419859897490403 0.0 0.0 0.5014318890749311 0.0 0.0" size="0.04" /><joint name="leg_3_2_ankle_joint" type="ball" damping="6.0" /></body></body></body></body><geom name="flag_3" type="box" size="0.05 0.05 0.5" pos="-8.467390898868404 -2.8947146752399924 0" material="yellow" contype="1" conaffinity="4" /><body name="torso_4" pos="0 0 0.75"><geom name="torso_geom_torso_4" type="box" size="0.2315539002163724 0.14996227838703424 0.09444832378987704" pos="0 0 0" contype="1" conaffinity="5" material="purple" /><joint name="torso_4_root" type="free" armature="0" damping="0" limited="false" /><site name="torso_4_site" pos="0 0 0" type="sphere" size="0.01" /><body name="leg_4_1" pos="-0.1157769501081862 0 0"><geom name="leg_4_1_upper_geom" type="capsule" fromto="0.0 0.0 0.0 0.10721426061670214 0.0 0.0" size="0.04" /><joint name="leg_4_1_hip_joint" type="ball" damping="2.0" /><body name="leg_4_1_lower" pos="0.10721426061670214 0.0 0.0"><geom name="leg_4_1_lower_geom" type="capsule" fromto="0.10721426061670214 0.0 0.0 0.2950198339300012 0.0 0.0" size="0.04" /><joint name="leg_4_1_knee_joint" type="hinge" axis="0 1 0" range="-90 90" damping="4.0" limited="true" /><body name="leg_4_1_foot" pos="0.2950198339300012 0.0 0.0"><geom name="leg_4_1_foot_geom" type="cylinder" fromto="0.2950198339300012 0.0 0.0 0.49311512302213123 0.0 0.0" size="0.04" /><joint name="leg_4_1_ankle_joint" type="ball" damping="6.0" /></body></body></body><body name="leg_4_2" pos="-0.1157769501081862 0 0"><geom name="leg_4_2_upper_geom" type="capsule" fromto="0.0 0.0 0.0 0.12207754287495746 0.0 0.0" size="0.04" /><joint name="leg_4_2_hip_joint" type="ball" damping="2.0" /><body name="leg_4_2_lower" pos="0.12207754287495746 0.0 0.0"><geom name="leg_4_2_lower_geom" type="capsule" fromto="0.12207754287495746 0.0 0.0 0.2965197657220431 0.0 0.0" size="0.04" /><joint name="leg_4_2_knee_joint" type="hinge" axis="0 1 0" range="-90 90" damping="4.0" limited="true" /><body name="leg_4_2_foot" pos="0.2965197657220431 0.0 0.0"><geom name="leg_4_2_foot_geom" type="cylinder" fromto="0.2965197657220431 0.0 0.0 0.43600588844838273 0.0 0.0" size="0.04" /><joint name="leg_4_2_ankle_joint" type="ball" damping="6.0" /></body></body></body><body name="leg_4_3" pos="0 -0.07498113919351712 0"><geom name="leg_4_3_upper_geom" type="capsule" fromto="0.0 0.0 0.0 0.146348428184574 0.0 0.0" size="0.04" /><joint name="leg_4_3_hip_joint" type="ball" damping="2.0" /><body name="leg_4_3_lower" pos="0.146348428184574 0.0 0.0"><geom name="leg_4_3_lower_geom" type="capsule" fromto="0.146348428184574 0.0 0.0 0.334939287919123 0.0 0.0" size="0.04" /><joint name="leg_4_3_knee_joint" type="hinge" axis="0 1 0" range="-90 90" damping="4.0" limited="true" /><body name="leg_4_3_foot" pos="0.334939287919123 0.0 0.0"><geom name="leg_4_3_foot_geom" type="cylinder" fromto="0.334939287919123 0.0 0.0 0.4473874776007986 0.0 0.0" size="0.04" /><joint name="leg_4_3_ankle_joint" type="ball" damping="6.0" /></body></body></body><body name="leg_4_4" pos="0 0.07498113919351712 0"><geom name="leg_4_4_upper_geom" type="capsule" fromto="0.0 0.0 0.0 0.1950478481356456 0.0 0.0" size="0.04" /><joint name="leg_4_4_hip_joint" type="ball" damping="2.0" /><body name="leg_4_4_lower" pos="0.1950478481356456 0.0 0.0"><geom name="leg_4_4_lower_geom" type="capsule" fromto="0.1950478481356456 0.0 0.0 0.3833317117301943 0.0 0.0" size="0.04" /><joint name="leg_4_4_knee_joint" type="hinge" axis="0 1 0" range="-90 90" damping="4.0" limited="true" /><body name="leg_4_4_foot" pos="0.3833317117301943 0.0 0.0"><geom name="leg_4_4_foot_geom" type="cylinder" fromto="0.3833317117301943 0.0 0.0 0.5519253821454432 0.0 0.0" size="0.04" /><joint name="leg_4_4_ankle_joint" type="ball" damping="6.0" /></body></body></body></body><geom name="flag_4" type="box" size="0.05 0.05 0.5" pos="-0.4418685100386583 3.4719954233604944 0" material="purple" contype="1" conaffinity="5" /><body name="torso_5" pos="6.5 0 0.75"><geom name="torso_geom_torso_5" type="box" size="0.4314175594061537 0.1595285614907394 0.06890047664544138" pos="0 0 0" contype="1" conaffinity="6" material="orange" /><joint name="torso_5_root" type="free" armature="0" damping="0" limited="false" /><site name="torso_5_site" pos="0 0 0" type="sphere" size="0.01" /><body name="leg_5_1" pos="0 -0.0797642807453697 0"><geom name="leg_5_1_upper_geom" type="capsule" fromto="0.0 0.0 0.0 0.16135347268223516 0.0 0.0" size="0.04" /><joint name="leg_5_1_hip_joint" type="ball" damping="2.0" /><body name="leg_5_1_lower" pos="0.16135347268223516 0.0 0.0"><geom name="leg_5_1_lower_geom" type="capsule" fromto="0.16135347268223516 0.0 0.0 0.3162003177663587 0.0 0.0" size="0.04" /><joint name="leg_5_1_knee_joint" type="hinge" axis="0 1 0" range="-90 90" damping="4.0" limited="true" /><body name="leg_5_1_foot" pos="0.3162003177663587 0.0 0.0"><geom name="leg_5_1_foot_geom" type="cylinder" fromto="0.3162003177663587 0.0 0.0 0.4261156051908098 0.0 0.0" size="0.04" /><joint name="leg_5_1_ankle_joint" type="ball" damping="6.0" /></body></body></body></body><geom name="flag_5" type="box" size="0.05 0.05 0.5" pos="9.639758181068494 -1.5465828669726898 0" material="orange" contype="1" conaffinity="6" /><body name="torso_6" pos="-6.5 6.5 0.75"><geom name="torso_geom_torso_6" type="box" size="0.2717046804219661 0.1572042956546676 0.061619634218001235" pos="0 0 0" contype="1" conaffinity="7" material="pink" /><joint name="torso_6_root" type="free" armature="0" damping="0" limited="false" /><site name="torso_6_site" pos="0 0 0" type="sphere" size="0.01" /><body name="leg_6_1" pos="-0.13585234021098305 0 0"><geom name="leg_6_1_upper_geom" type="capsule" fromto="0.0 0.0 0.0 0.13925627251408038 0.0 0.0" size="0.04" /><joint name="leg_6_1_hip_joint" type="ball" damping="2.0" /><body name="leg_6_1_lower" pos="0.13925627251408038 0.0 0.0"><geom name="leg_6_1_lower_geom" type="capsule" fromto="0.13925627251408038 0.0 0.0 0.2545689868484067 0.0 0.0" size="0.04" /><joint name="leg_6_1_knee_joint" type="hinge" axis="0 1 0" range="-90 90" damping="4.0" limited="true" /><body name="leg_6_1_foot" pos="0.2545689868484067 0.0 0.0"><geom name="leg_6_1_foot_geom" type="cylinder" fromto="0.2545689868484067 0.0 0.0 0.45295433204825297 0.0 0.0" size="0.04" /><joint name="leg_6_1_ankle_joint" type="ball" damping="6.0" /></body></body></body><body name="leg_6_2" pos="0.13585234021098305 0 0"><geom name="leg_6_2_upper_geom" type="capsule" fromto="0.0 0.0 0.0 0.11025670490450876 0.0 0.0" size="0.04" /><joint name="leg_6_2_hip_joint" type="ball" damping="2.0" /><body name="leg_6_2_lower" pos="0.11025670490450876 0.0 0.0"><geom name="leg_6_2_lower_geom" type="capsule" fromto="0.11025670490450876 0.0 0.0 0.25547199230233997 0.0 0.0" size="0.04" /><joint name="leg_6_2_knee_joint" type="hinge" axis="0 1 0" range="-90 90" damping="4.0" limited="true" /><body name="leg_6_2_foot" pos="0.25547199230233997 0.0 0.0"><geom name="leg_6_2_foot_geom" type="cylinder" fromto="0.25547199230233997 0.0 0.0 0.41005586585052756 0.0 0.0" size="0.04" /><joint name="leg_6_2_ankle_joint" type="ball" damping="6.0" /></body></body></body><body name="leg_6_3" pos="0 0.0786021478273338 0"><geom name="leg_6_3_upper_geom" type="capsule" fromto="0.0 0.0 0.0 0.1834326909225371 0.0 0.0" size="0.04" /><joint name="leg_6_3_hip_joint" type="ball" damping="2.0" /><body name="leg_6_3_lower" pos="0.1834326909225371 0.0 0.0"><geom name="leg_6_3_lower_geom" type="capsule" fromto="0.1834326909225371 0.0 0.0 0.33356441175308416 0.0 0.0" size="0.04" /><joint name="leg_6_3_knee_joint" type="hinge" axis="0 1 0" range="-90 90" damping="4.0" limited="true" /><body name="leg_6_3_foot" pos="0.33356441175308416 0.0 0.0"><geom name="leg_6_3_foot_geom" type="cylinder" fromto="0.33356441175308416 0.0 0.0 0.44201205218942974 0.0 0.0" size="0.04" /><joint name="leg_6_3_ankle_joint" type="ball" damping="6.0" /></body></body></body><body name="leg_6_4" pos="0 -0.0786021478273338 0"><geom name="leg_6_4_upper_geom" type="capsule" fromto="0.0 0.0 0.0 0.1270739612095142 0.0 0.0" size="0.04" /><joint name="leg_6_4_hip_joint" type="ball" damping="2.0" /><body name="leg_6_4_lower" pos="0.1270739612095142 0.0 0.0"><geom name="leg_6_4_lower_geom" type="capsule" fromto="0.1270739612095142 0.0 0.0 0.23764648829598609 0.0 0.0" size="0.04" /><joint name="leg_6_4_knee_joint" type="hinge" axis="0 1 0" range="-90 90" damping="4.0" limited="true" /><body name="leg_6_4_foot" pos="0.23764648829598609 0.0 0.0"><geom name="leg_6_4_foot_geom" type="cylinder" fromto="0.23764648829598609 0.0 0.0 0.39365109933968484 0.0 0.0" size="0.04" /><joint name="leg_6_4_ankle_joint" type="ball" damping="6.0" /></body></body></body></body><geom name="flag_6" type="box" size="0.05 0.05 0.5" pos="-9.934225239682554 5.824650458556979 0" material="pink" contype="1" conaffinity="7" /><body name="torso_7" pos="0 6.5 0.75"><geom name="torso_geom_torso_7" type="box" size="0.22337774622492437 0.13548108736951733 0.0723163127633951" pos="0 0 0" contype="1" conaffinity="8" material="grey" /><joint name="torso_7_root" type="free" armature="0" damping="0" limited="false" /><site name="torso_7_site" pos="0 0 0" type="sphere" size="0.01" /><body name="leg_7_1" pos="-0.11168887311246219 0 0"><geom name="leg_7_1_upper_geom" type="capsule" fromto="0.0 0.0 0.0 0.1271388670468418 0.0 0.0" size="0.04" /><joint name="leg_7_1_hip_joint" type="ball" damping="2.0" /><body name="leg_7_1_lower" pos="0.1271388670468418 0.0 0.0"><geom name="leg_7_1_lower_geom" type="capsule" fromto="0.1271388670468418 0.0 0.0 0.23107350108565633 0.0 0.0" size="0.04" /><joint name="leg_7_1_knee_joint" type="hinge" axis="0 1 0" range="-90 90" damping="4.0" limited="true" /><body name="leg_7_1_foot" pos="0.23107350108565633 0.0 0.0"><geom name="leg_7_1_foot_geom" type="cylinder" fromto="0.23107350108565633 0.0 0.0 0.4138833997737046 0.0 0.0" size="0.04" /><joint name="leg_7_1_ankle_joint" type="ball" damping="6.0" /></body></body></body><body name="leg_7_2" pos="-0.11168887311246219 0 0"><geom name="leg_7_2_upper_geom" type="capsule" fromto="0.0 0.0 0.0 0.12459998695623453 0.0 0.0" size="0.04" /><joint name="leg_7_2_hip_joint" type="ball" damping="2.0" /><body name="leg_7_2_lower" pos="0.12459998695623453 0.0 0.0"><geom name="leg_7_2_lower_geom" type="capsule" fromto="0.12459998695623453 0.0 0.0 0.25724954319954624 0.0 0.0" size="0.04" /><joint name="leg_7_2_knee_joint" type="hinge" axis="0 1 0" range="-90 90" damping="4.0" limited="true" /><body name="leg_7_2_foot" pos="0.25724954319954624 0.0 0.0"><geom name="leg_7_2_foot_geom" type="cylinder" fromto="0.25724954319954624 0.0 0.0 0.38328433784226945 0.0 0.0" size="0.04" /><joint name="leg_7_2_ankle_joint" type="ball" damping="6.0" /></body></body></body></body><geom name="flag_7" type="box" size="0.05 0.05 0.5" pos="-1.7508815370407698 9.530579786649701 0" material="grey" contype="1" conaffinity="8" /><body name="torso_8" pos="6.5 6.5 0.75"><geom name="torso_geom_torso_8" type="box" size="0.48970260473817084 0.17706476752130434 0.06990537791543541" pos="0 0 0" contype="1" conaffinity="9" material="brown" /><joint name="torso_8_root" type="free" armature="0" damping="0" limited="false" /><site name="torso_8_site" pos="0 0 0" type="sphere" size="0.01" /><body name="leg_8_1" pos="0 -0.08853238376065217 0"><geom name="leg_8_1_upper_geom" type="capsule" fromto="0.0 0.0 0.0 0.14492323134518384 0.0 0.0" size="0.04" /><joint name="leg_8_1_hip_joint" type="ball" damping="2.0" /><body name="leg_8_1_lower" pos="0.14492323134518384 0.0 0.0"><geom name="leg_8_1_lower_geom" type="capsule" fromto="0.14492323134518384 0.0 0.0 0.28661779988010794 0.0 0.0" size="0.04" /><joint name="leg_8_1_knee_joint" type="hinge" axis="0 1 0" range="-90 90" damping="4.0" limited="true" /><body name="leg_8_1_foot" pos="0.28661779988010794 0.0 0.0"><geom name="leg_8_1_foot_geom" type="cylinder" fromto="0.28661779988010794 0.0 0.0 0.4695453059619124 0.0 0.0" size="0.04" /><joint name="leg_8_1_ankle_joint" type="ball" damping="6.0" /></body></body></body><body name="leg_8_2" pos="-0.24485130236908542 0 0"><geom name="leg_8_2_upper_geom" type="capsule" fromto="0.0 0.0 0.0 0.16776006517678993 0.0 0.0" size="0.04" /><joint name="leg_8_2_hip_joint" type="ball" damping="2.0" /><body name="leg_8_2_lower" pos="0.16776006517678993 0.0 0.0"><geom name="leg_8_2_lower_geom" type="capsule" fromto="0.16776006517678993 0.0 0.0 0.30491274345857977 0.0 0.0" size="0.04" /><joint name="leg_8_2_knee_joint" type="hinge" axis="0 1 0" range="-90 90" damping="4.0" limited="true" /><body name="leg_8_2_foot" pos="0.30491274345857977 0.0 0.0"><geom name="leg_8_2_foot_geom" type="cylinder" fromto="0.30491274345857977 0.0 0.0 0.4526553588463047 0.0 0.0" size="0.04" /><joint name="leg_8_2_ankle_joint" type="ball" damping="6.0" /></body></body></body><body name="leg_8_3" pos="0 0.08853238376065217 0"><geom name="leg_8_3_upper_geom" type="capsule" fromto="0.0 0.0 0.0 0.14291870560021586 0.0 0.0" size="0.04" /><joint name="leg_8_3_hip_joint" type="ball" damping="2.0" /><body name="leg_8_3_lower" pos="0.14291870560021586 0.0 0.0"><geom name="leg_8_3_lower_geom" type="capsule" fromto="0.14291870560021586 0.0 0.0 0.3113160470268765 0.0 0.0" size="0.04" /><joint name="leg_8_3_knee_joint" type="hinge" axis="0 1 0" range="-90 90" damping="4.0" limited="true" /><body name="leg_8_3_foot" pos="0.3113160470268765 0.0 0.0"><geom name="leg_8_3_foot_geom" type="cylinder" fromto="0.3113160470268765 0.0 0.0 0.456784628927765 0.0 0.0" size="0.04" /><joint name="leg_8_3_ankle_joint" type="ball" damping="6.0" /></body></body></body><body name="leg_8_4" pos="0 -0.08853238376065217 0"><geom name="leg_8_4_upper_geom" type="capsule" fromto="0.0 0.0 0.0 0.13940369271260386 0.0 0.0" size="0.04" /><joint name="leg_8_4_hip_joint" type="ball" damping="2.0" /><body name="leg_8_4_lower" pos="0.13940369271260386 0.0 0.0"><geom name="leg_8_4_lower_geom" type="capsule" fromto="0.13940369271260386 0.0 0.0 0.33763773478187664 0.0 0.0" size="0.04" /><joint name="leg_8_4_knee_joint" type="hinge" axis="0 1 0" range="-90 90" damping="4.0" limited="true" /><body name="leg_8_4_foot" pos="0.33763773478187664 0.0 0.0"><geom name="leg_8_4_foot_geom" type="cylinder" fromto="0.33763773478187664 0.0 0.0 0.5141559283619651 0.0 0.0" size="0.04" /><joint name="leg_8_4_ankle_joint" type="ball" damping="6.0" /></body></body></body></body><geom name="flag_8" type="box" size="0.05 0.05 0.5" pos="5.609720079087355 9.884878382219924 0" material="brown" contype="1" conaffinity="9" /><geom name="north_wall" type="box" pos="0 10.05 0.25" size="10.05 0.05 0.25" material="MatPlane" /><geom name="south_wall" type="box" pos="0 -10.05 0.25" size="10.05 0.05 0.25" material="MatPlane" /><geom name="east_wall" type="box" pos="10.05 0 0.25" size="0.05 10.05 0.25" material="MatPlane" /><geom name="west_wall" type="box" pos="-10.05 0 0.25" size="0.05 10.05 0.25" material="MatPlane" /></worldbody><actuator><motor name="leg_0_1_hip_motor" joint="leg_0_1_hip_joint" ctrllimited="true" ctrlrange="-1 1" gear="200" /><motor name="leg_0_1_ankle_joint_motor" joint="leg_0_1_ankle_joint" ctrllimited="true" ctrlrange="-1 1" gear="200" /><motor name="leg_1_1_hip_motor" joint="leg_1_1_hip_joint" ctrllimited="true" ctrlrange="-1 1" gear="200" /><motor name="leg_1_1_ankle_joint_motor" joint="leg_1_1_ankle_joint" ctrllimited="true" ctrlrange="-1 1" gear="200" /><motor name="leg_2_1_hip_motor" joint="leg_2_1_hip_joint" ctrllimited="true" ctrlrange="-1 1" gear="200" /><motor name="leg_2_1_ankle_joint_motor" joint="leg_2_1_ankle_joint" ctrllimited="true" ctrlrange="-1 1" gear="200" /><motor name="leg_3_1_hip_motor" joint="leg_3_1_hip_joint" ctrllimited="true" ctrlrange="-1 1" gear="200" /><motor name="leg_3_1_ankle_joint_motor" joint="leg_3_1_ankle_joint" ctrllimited="true" ctrlrange="-1 1" gear="200" /><motor name="leg_3_2_hip_motor" joint="leg_3_2_hip_joint" ctrllimited="true" ctrlrange="-1 1" gear="200" /><motor name="leg_3_2_ankle_joint_motor" joint="leg_3_2_ankle_joint" ctrllimited="true" ctrlrange="-1 1" gear="200" /><motor name="leg_4_1_hip_motor" joint="leg_4_1_hip_joint" ctrllimited="true" ctrlrange="-1 1" gear="200" /><motor name="leg_4_1_ankle_joint_motor" joint="leg_4_1_ankle_joint" ctrllimited="true" ctrlrange="-1 1" gear="200" /><motor name="leg_4_2_hip_motor" joint="leg_4_2_hip_joint" ctrllimited="true" ctrlrange="-1 1" gear="200" /><motor name="leg_4_2_ankle_joint_motor" joint="leg_4_2_ankle_joint" ctrllimited="true" ctrlrange="-1 1" gear="200" /><motor name="leg_4_3_hip_motor" joint="leg_4_3_hip_joint" ctrllimited="true" ctrlrange="-1 1" gear="200" /><motor name="leg_4_3_ankle_joint_motor" joint="leg_4_3_ankle_joint" ctrllimited="true" ctrlrange="-1 1" gear="200" /><motor name="leg_4_4_hip_motor" joint="leg_4_4_hip_joint" ctrllimited="true" ctrlrange="-1 1" gear="200" /><motor name="leg_4_4_ankle_joint_motor" joint="leg_4_4_ankle_joint" ctrllimited="true" ctrlrange="-1 1" gear="200" /><motor name="leg_5_1_hip_motor" joint="leg_5_1_hip_joint" ctrllimited="true" ctrlrange="-1 1" gear="200" /><motor name="leg_5_1_ankle_joint_motor" joint="leg_5_1_ankle_joint" ctrllimited="true" ctrlrange="-1 1" gear="200" /><motor name="leg_6_1_hip_motor" joint="leg_6_1_hip_joint" ctrllimited="true" ctrlrange="-1 1" gear="200" /><motor name="leg_6_1_ankle_joint_motor" joint="leg_6_1_ankle_joint" ctrllimited="true" ctrlrange="-1 1" gear="200" /><motor name="leg_6_2_hip_motor" joint="leg_6_2_hip_joint" ctrllimited="true" ctrlrange="-1 1" gear="200" /><motor name="leg_6_2_ankle_joint_motor" joint="leg_6_2_ankle_joint" ctrllimited="true" ctrlrange="-1 1" gear="200" /><motor name="leg_6_3_hip_motor" joint="leg_6_3_hip_joint" ctrllimited="true" ctrlrange="-1 1" gear="200" /><motor name="leg_6_3_ankle_joint_motor" joint="leg_6_3_ankle_joint" ctrllimited="true" ctrlrange="-1 1" gear="200" /><motor name="leg_6_4_hip_motor" joint="leg_6_4_hip_joint" ctrllimited="true" ctrlrange="-1 1" gear="200" /><motor name="leg_6_4_ankle_joint_motor" joint="leg_6_4_ankle_joint" ctrllimited="true" ctrlrange="-1 1" gear="200" /><motor name="leg_7_1_hip_motor" joint="leg_7_1_hip_joint" ctrllimited="true" ctrlrange="-1 1" gear="200" /><motor name="leg_7_1_ankle_joint_motor" joint="leg_7_1_ankle_joint" ctrllimited="true" ctrlrange="-1 1" gear="200" /><motor name="leg_7_2_hip_motor" joint="leg_7_2_hip_joint" ctrllimited="true" ctrlrange="-1 1" gear="200" /><motor name="leg_7_2_ankle_joint_motor" joint="leg_7_2_ankle_joint" ctrllimited="true" ctrlrange="-1 1" gear="200" /><motor name="leg_8_1_hip_motor" joint="leg_8_1_hip_joint" ctrllimited="true" ctrlrange="-1 1" gear="200" /><motor name="leg_8_1_ankle_joint_motor" joint="leg_8_1_ankle_joint" ctrllimited="true" ctrlrange="-1 1" gear="200" /><motor name="leg_8_2_hip_motor" joint="leg_8_2_hip_joint" ctrllimited="true" ctrlrange="-1 1" gear="200" /><motor name="leg_8_2_ankle_joint_motor" joint="leg_8_2_ankle_joint" ctrllimited="true" ctrlrange="-1 1" gear="200" /><motor name="leg_8_3_hip_motor" joint="leg_8_3_hip_joint" ctrllimited="true" ctrlrange="-1 1" gear="200" /><motor name="leg_8_3_ankle_joint_motor" joint="leg_8_3_ankle_joint" ctrllimited="true" ctrlrange="-1 1" gear="200" /><motor name="leg_8_4_hip_motor" joint="leg_8_4_hip_joint" ctrllimited="true" ctrlrange="-1 1" gear="200" /><motor name="leg_8_4_ankle_joint_motor" joint="leg_8_4_ankle_joint" ctrllimited="true" ctrlrange="-1 1" gear="200" /></actuator><sensor><accelerometer name="torso_0_accel" site="torso_0_site" /><gyro name="torso_0_gyro" site="torso_0_site" /><accelerometer name="torso_1_accel" site="torso_1_site" /><gyro name="torso_1_gyro" site="torso_1_site" /><accelerometer name="torso_2_accel" site="torso_2_site" /><gyro name="torso_2_gyro" site="torso_2_site" /><accelerometer name="torso_3_accel" site="torso_3_site" /><gyro name="torso_3_gyro" site="torso_3_site" /><accelerometer name="torso_4_accel" site="torso_4_site" /><gyro name="torso_4_gyro" site="torso_4_site" /><accelerometer name="torso_5_accel" site="torso_5_site" /><gyro name="torso_5_gyro" site="torso_5_site" /><accelerometer name="torso_6_accel" site="torso_6_site" /><gyro name="torso_6_gyro" site="torso_6_site" /><accelerometer name="torso_7_accel" site="torso_7_site" /><gyro name="torso_7_gyro" site="torso_7_site" /><accelerometer name="torso_8_accel" site="torso_8_site" /><gyro name="torso_8_gyro" site="torso_8_site" /></sensor></mujoco>