<mujoco><option timestep="0.002" /><asset><texture name="checkered" type="2d" builtin="checker" rgb1="0.2 0.3 0.4" rgb2="0.9 0.9 0.9" width="512" height="512" /><material name="MatCheckered" texture="checkered" reflectance="0.5" /><material name="MatPlane" reflectance="0.5" shininess="1" specular="1" /><material name="red" rgba="1 0 0 1" /><material name="green" rgba="0 1 0 1" /><material name="blue" rgba="0 0 1 1" /><material name="yellow" rgba="1 1 0 1" /><material name="purple" rgba="0.5 0 0.5 1" /><material name="orange" rgba="1 0.5 0 1" /><material name="pink" rgba="1 0.7 0.7 1" /><material name="grey" rgba="0.5 0.5 0.5 1" /><material name="brown" rgba="0.6 0.3 0 1" /></asset><worldbody><geom name="floor" type="plane" size="10 10 0.1" pos="0 0 0" material="MatCheckered" /><body name="torso_0" pos="-6.5 -6.5 0.75"><geom name="torso_geom_torso_0" type="box" size="0.3686314084574217 0.18798020838017312 0.0941634634562076" pos="0 0 0" contype="1" conaffinity="1" material="red" /><joint name="torso_0_root" type="free" armature="0" damping="0" limited="false" /><site name="torso_0_site" pos="0 0 0" type="sphere" size="0.01" /><body name="leg_0_1" pos="0 -0.09399010419008656 0"><geom name="leg_0_1_upper_geom" type="capsule" fromto="0.0 0.0 0.0 0.1267791883949616 0.0 0.0" size="0.04" /><joint name="leg_0_1_hip_joint" type="ball" damping="2.0" /><body name="leg_0_1_lower" pos="0.1267791883949616 0.0 0.0"><geom name="leg_0_1_lower_geom" type="capsule" fromto="0.1267791883949616 0.0 0.0 0.3163305929933821 0.0 0.0" size="0.04" /><joint name="leg_0_1_knee_joint" type="hinge" axis="0 1 0" range="-90 90" damping="4.0" limited="true" /><body name="leg_0_1_foot" pos="0.3163305929933821 0.0 0.0"><geom name="leg_0_1_foot_geom" type="cylinder" fromto="0.3163305929933821 0.0 0.0 0.4702252551314453 0.0 0.0" size="0.04" /><joint name="leg_0_1_ankle_joint" type="ball" damping="6.0" /></body></body></body></body><geom name="flag_0" type="box" size="0.05 0.05 0.5" pos="-9.872024552930439 -7.437790176123783 0" material="red" contype="1" conaffinity="1" /><body name="torso_1" pos="0 -6.5 0.75"><geom name="torso_geom_torso_1" type="box" size="0.4058207039541576 0.18275589542413936 0.0802255788183169" pos="0 0 0" contype="1" conaffinity="2" material="green" /><joint name="torso_1_root" type="free" armature="0" damping="0" limited="false" /><site name="torso_1_site" pos="0 0 0" type="sphere" size="0.01" /><body name="leg_1_1" pos="0 0.09137794771206968 0"><geom name="leg_1_1_upper_geom" type="capsule" fromto="0.0 0.0 0.0 0.11384979679507923 0.0 0.0" size="0.04" /><joint name="leg_1_1_hip_joint" type="ball" damping="2.0" /><body name="leg_1_1_lower" pos="0.11384979679507923 0.0 0.0"><geom name="leg_1_1_lower_geom" type="capsule" fromto="0.11384979679507923 0.0 0.0 0.23965887314124676 0.0 0.0" size="0.04" /><joint name="leg_1_1_knee_joint" type="hinge" axis="0 1 0" range="-90 90" damping="4.0" limited="true" /><body name="leg_1_1_foot" pos="0.23965887314124676 0.0 0.0"><geom name="leg_1_1_foot_geom" type="cylinder" fromto="0.23965887314124676 0.0 0.0 0.34962226201581825 0.0 0.0" size="0.04" /><joint name="leg_1_1_ankle_joint" type="ball" damping="6.0" /></body></body></body><body name="leg_1_2" pos="-0.2029103519770788 0 0"><geom name="leg_1_2_upper_geom" type="capsule" fromto="0.0 0.0 0.0 0.1223014023662833 0.0 0.0" size="0.04" /><joint name="leg_1_2_hip_joint" type="ball" damping="2.0" /><body name="leg_1_2_lower" pos="0.1223014023662833 0.0 0.0"><geom name="leg_1_2_lower_geom" type="capsule" fromto="0.1223014023662833 0.0 0.0 0.26825555246109617 0.0 0.0" size="0.04" /><joint name="leg_1_2_knee_joint" type="hinge" axis="0 1 0" range="-90 90" damping="4.0" limited="true" /><body name="leg_1_2_foot" pos="0.26825555246109617 0.0 0.0"><geom name="leg_1_2_foot_geom" type="cylinder" fromto="0.26825555246109617 0.0 0.0 0.4207388754882805 0.0 0.0" size="0.04" /><joint name="leg_1_2_ankle_joint" type="ball" damping="6.0" /></body></body></body><body name="leg_1_3" pos="0.2029103519770788 0 0"><geom name="leg_1_3_upper_geom" type="capsule" fromto="0.0 0.0 0.0 0.1948001736603241 0.0 0.0" size="0.04" /><joint name="leg_1_3_hip_joint" type="ball" damping="2.0" /><body name="leg_1_3_lower" pos="0.1948001736603241 0.0 0.0"><geom name="leg_1_3_lower_geom" type="capsule" fromto="0.1948001736603241 0.0 0.0 0.31631550094978333 0.0 0.0" size="0.04" /><joint name="leg_1_3_knee_joint" type="hinge" axis="0 1 0" range="-90 90" damping="4.0" limited="true" /><body name="leg_1_3_foot" pos="0.31631550094978333 0.0 0.0"><geom name="leg_1_3_foot_geom" type="cylinder" fromto="0.31631550094978333 0.0 0.0 0.47139638646261994 0.0 0.0" size="0.04" /><joint name="leg_1_3_ankle_joint" type="ball" damping="6.0" /></body></body></body><body name="leg_1_4" pos="0 -0.09137794771206968 0"><geom name="leg_1_4_upper_geom" type="capsule" fromto="0.0 0.0 0.0 0.18556834115102555 0.0 0.0" size="0.04" /><joint name="leg_1_4_hip_joint" type="ball" damping="2.0" /><body name="leg_1_4_lower" pos="0.18556834115102555 0.0 0.0"><geom name="leg_1_4_lower_geom" type="capsule" fromto="0.18556834115102555 0.0 0.0 0.31463184072345196 0.0 0.0" size="0.04" /><joint name="leg_1_4_knee_joint" type="hinge" axis="0 1 0" range="-90 90" damping="4.0" limited="true" /><body name="leg_1_4_foot" pos="0.31463184072345196 0.0 0.0"><geom name="leg_1_4_foot_geom" type="cylinder" fromto="0.31463184072345196 0.0 0.0 0.4770140077363208 0.0 0.0" size="0.04" /><joint name="leg_1_4_ankle_joint" type="ball" damping="6.0" /></body></body></body></body><geom name="flag_1" type="box" size="0.05 0.05 0.5" pos="2.129550333121509 -3.7224083491805224 0" material="green" contype="1" conaffinity="2" /><body name="torso_2" pos="6.5 -6.5 0.75"><geom name="torso_geom_torso_2" type="box" size="0.39606022850899425 0.13911704695921495 0.06126800156183784" pos="0 0 0" contype="1" conaffinity="3" material="blue" /><joint name="torso_2_root" type="free" armature="0" damping="0" limited="false" /><site name="torso_2_site" pos="0 0 0" type="sphere" size="0.01" /><body name="leg_2_1" pos="0.19803011425449712 0 0"><geom name="leg_2_1_upper_geom" type="capsule" fromto="0.0 0.0 0.0 0.1440390326204518 0.0 0.0" size="0.04" /><joint name="leg_2_1_hip_joint" type="ball" damping="2.0" /><body name="leg_2_1_lower" pos="0.1440390326204518 0.0 0.0"><geom name="leg_2_1_lower_geom" type="capsule" fromto="0.1440390326204518 0.0 0.0 0.29072555869099426 0.0 0.0" size="0.04" /><joint name="leg_2_1_knee_joint" type="hinge" axis="0 1 0" range="-90 90" damping="4.0" limited="true" /><body name="leg_2_1_foot" pos="0.29072555869099426 0.0 0.0"><geom name="leg_2_1_foot_geom" type="cylinder" fromto="0.29072555869099426 0.0 0.0 0.46654056239979613 0.0 0.0" size="0.04" /><joint name="leg_2_1_ankle_joint" type="ball" damping="6.0" /></body></body></body><body name="leg_2_2" pos="0.19803011425449712 0 0"><geom name="leg_2_2_upper_geom" type="capsule" fromto="0.0 0.0 0.0 0.16104797196506082 0.0 0.0" size="0.04" /><joint name="leg_2_2_hip_joint" type="ball" damping="2.0" /><body name="leg_2_2_lower" pos="0.16104797196506082 0.0 0.0"><geom name="leg_2_2_lower_geom" type="capsule" fromto="0.16104797196506082 0.0 0.0 0.33167359721116274 0.0 0.0" size="0.04" /><joint name="leg_2_2_knee_joint" type="hinge" axis="0 1 0" range="-90 90" damping="4.0" limited="true" /><body name="leg_2_2_foot" pos="0.33167359721116274 0.0 0.0"><geom name="leg_2_2_foot_geom" type="cylinder" fromto="0.33167359721116274 0.0 0.0 0.44112788877400977 0.0 0.0" size="0.04" /><joint name="leg_2_2_ankle_joint" type="ball" damping="6.0" /></body></body></body><body name="leg_2_3" pos="-0.19803011425449712 0 0"><geom name="leg_2_3_upper_geom" type="capsule" fromto="0.0 0.0 0.0 0.12586475945696368 0.0 0.0" size="0.04" /><joint name="leg_2_3_hip_joint" type="ball" damping="2.0" /><body name="leg_2_3_lower" pos="0.12586475945696368 0.0 0.0"><geom name="leg_2_3_lower_geom" type="capsule" fromto="0.12586475945696368 0.0 0.0 0.294141236938309 0.0 0.0" size="0.04" /><joint name="leg_2_3_knee_joint" type="hinge" axis="0 1 0" range="-90 90" damping="4.0" limited="true" /><body name="leg_2_3_foot" pos="0.294141236938309 0.0 0.0"><geom name="leg_2_3_foot_geom" type="cylinder" fromto="0.294141236938309 0.0 0.0 0.4748545851750672 0.0 0.0" size="0.04" /><joint name="leg_2_3_ankle_joint" type="ball" damping="6.0" /></body></body></body><body name="leg_2_4" pos="0 -0.06955852347960748 0"><geom name="leg_2_4_upper_geom" type="capsule" fromto="0.0 0.0 0.0 0.12986833589324748 0.0 0.0" size="0.04" /><joint name="leg_2_4_hip_joint" type="ball" damping="2.0" /><body name="leg_2_4_lower" pos="0.12986833589324748 0.0 0.0"><geom name="leg_2_4_lower_geom" type="capsule" fromto="0.12986833589324748 0.0 0.0 0.25937765589587924 0.0 0.0" size="0.04" /><joint name="leg_2_4_knee_joint" type="hinge" axis="0 1 0" range="-90 90" damping="4.0" limited="true" /><body name="leg_2_4_foot" pos="0.25937765589587924 0.0 0.0"><geom name="leg_2_4_foot_geom" type="cylinder" fromto="0.25937765589587924 0.0 0.0 0.36047487167634434 0.0 0.0" size="0.04" /><joint name="leg_2_4_ankle_joint" type="ball" damping="6.0" /></body></body></body></body><geom name="flag_2" type="box" size="0.05 0.05 0.5" pos="5.4337822245339975 -9.833643600518858 0" material="blue" contype="1" conaffinity="3" /><body name="torso_3" pos="-6.5 0 0.75"><geom name="torso_geom_torso_3" type="box" size="0.43394952197864434 0.12617451768986515 0.09267146784115324" pos="0 0 0" contype="1" conaffinity="4" material="yellow" /><joint name="torso_3_root" type="free" armature="0" damping="0" limited="false" /><site name="torso_3_site" pos="0 0 0" type="sphere" size="0.01" /><body name="leg_3_1" pos="0 0.06308725884493258 0"><geom name="leg_3_1_upper_geom" type="capsule" fromto="0.0 0.0 0.0 0.17980911015324938 0.0 0.0" size="0.04" /><joint name="leg_3_1_hip_joint" type="ball" damping="2.0" /><body name="leg_3_1_lower" pos="0.17980911015324938 0.0 0.0"><geom name="leg_3_1_lower_geom" type="capsule" fromto="0.17980911015324938 0.0 0.0 0.35543738280709747 0.0 0.0" size="0.04" /><joint name="leg_3_1_knee_joint" type="hinge" axis="0 1 0" range="-90 90" damping="4.0" limited="true" /><body name="leg_3_1_foot" pos="0.35543738280709747 0.0 0.0"><geom name="leg_3_1_foot_geom" type="cylinder" fromto="0.35543738280709747 0.0 0.0 0.493540492840835 0.0 0.0" size="0.04" /><joint name="leg_3_1_ankle_joint" type="ball" damping="6.0" /></body></body></body></body><geom name="flag_3" type="box" size="0.05 0.05 0.5" pos="-9.892341349706745 -0.8614059246776868 0" material="yellow" contype="1" conaffinity="4" /><body name="torso_4" pos="0 0 0.75"><geom name="torso_geom_torso_4" type="box" size="0.23868216813954532 0.11844897239747185 0.09765569383705021" pos="0 0 0" contype="1" conaffinity="5" material="purple" /><joint name="torso_4_root" type="free" armature="0" damping="0" limited="false" /><site name="torso_4_site" pos="0 0 0" type="sphere" size="0.01" /><body name="leg_4_1" pos="-0.11934108406977266 0 0"><geom name="leg_4_1_upper_geom" type="capsule" fromto="0.0 0.0 0.0 0.13663269198411837 0.0 0.0" size="0.04" /><joint name="leg_4_1_hip_joint" type="ball" damping="2.0" /><body name="leg_4_1_lower" pos="0.13663269198411837 0.0 0.0"><geom name="leg_4_1_lower_geom" type="capsule" fromto="0.13663269198411837 0.0 0.0 0.3068154461040389 0.0 0.0" size="0.04" /><joint name="leg_4_1_knee_joint" type="hinge" axis="0 1 0" range="-90 90" damping="4.0" limited="true" /><body name="leg_4_1_foot" pos="0.3068154461040389 0.0 0.0"><geom name="leg_4_1_foot_geom" type="cylinder" fromto="0.3068154461040389 0.0 0.0 0.42732843576895185 0.0 0.0" size="0.04" /><joint name="leg_4_1_ankle_joint" type="ball" damping="6.0" /></body></body></body><body name="leg_4_2" pos="0 -0.05922448619873592 0"><geom name="leg_4_2_upper_geom" type="capsule" fromto="0.0 0.0 0.0 0.15620912366507425 0.0 0.0" size="0.04" /><joint name="leg_4_2_hip_joint" type="ball" damping="2.0" /><body name="leg_4_2_lower" pos="0.15620912366507425 0.0 0.0"><geom name="leg_4_2_lower_geom" type="capsule" fromto="0.15620912366507425 0.0 0.0 0.29915840464656346 0.0 0.0" size="0.04" /><joint name="leg_4_2_knee_joint" type="hinge" axis="0 1 0" range="-90 90" damping="4.0" limited="true" /><body name="leg_4_2_foot" pos="0.29915840464656346 0.0 0.0"><geom name="leg_4_2_foot_geom" type="cylinder" fromto="0.29915840464656346 0.0 0.0 0.40145061017447964 0.0 0.0" size="0.04" /><joint name="leg_4_2_ankle_joint" type="ball" damping="6.0" /></body></body></body></body><geom name="flag_4" type="box" size="0.05 0.05 0.5" pos="2.5801679383640423 2.364896067449529 0" material="purple" contype="1" conaffinity="5" /><body name="torso_5" pos="6.5 0 0.75"><geom name="torso_geom_torso_5" type="box" size="0.36049029115554687 0.10299650721130654 0.06400861501999679" pos="0 0 0" contype="1" conaffinity="6" material="orange" /><joint name="torso_5_root" type="free" armature="0" damping="0" limited="false" /><site name="torso_5_site" pos="0 0 0" type="sphere" size="0.01" /><body name="leg_5_1" pos="0.18024514557777344 0 0"><geom name="leg_5_1_upper_geom" type="capsule" fromto="0.0 0.0 0.0 0.1920047839457443 0.0 0.0" size="0.04" /><joint name="leg_5_1_hip_joint" type="ball" damping="2.0" /><body name="leg_5_1_lower" pos="0.1920047839457443 0.0 0.0"><geom name="leg_5_1_lower_geom" type="capsule" fromto="0.1920047839457443 0.0 0.0 0.3332764677652206 0.0 0.0" size="0.04" /><joint name="leg_5_1_knee_joint" type="hinge" axis="0 1 0" range="-90 90" damping="4.0" limited="true" /><body name="leg_5_1_foot" pos="0.3332764677652206 0.0 0.0"><geom name="leg_5_1_foot_geom" type="cylinder" fromto="0.3332764677652206 0.0 0.0 0.5009585837006161 0.0 0.0" size="0.04" /><joint name="leg_5_1_ankle_joint" type="ball" damping="6.0" /></body></body></body><body name="leg_5_2" pos="0 -0.05149825360565327 0"><geom name="leg_5_2_upper_geom" type="capsule" fromto="0.0 0.0 0.0 0.1912122905627416 0.0 0.0" size="0.04" /><joint name="leg_5_2_hip_joint" type="ball" damping="2.0" /><body name="leg_5_2_lower" pos="0.1912122905627416 0.0 0.0"><geom name="leg_5_2_lower_geom" type="capsule" fromto="0.1912122905627416 0.0 0.0 0.3322157205587532 0.0 0.0" size="0.04" /><joint name="leg_5_2_knee_joint" type="hinge" axis="0 1 0" range="-90 90" damping="4.0" limited="true" /><body name="leg_5_2_foot" pos="0.3322157205587532 0.0 0.0"><geom name="leg_5_2_foot_geom" type="cylinder" fromto="0.3322157205587532 0.0 0.0 0.5284334273415062 0.0 0.0" size="0.04" /><joint name="leg_5_2_ankle_joint" type="ball" damping="6.0" /></body></body></body></body><geom name="flag_5" type="box" size="0.05 0.05 0.5" pos="3.5454464221229007 -1.8763297032914104 0" material="orange" contype="1" conaffinity="6" /><body name="torso_6" pos="-6.5 6.5 0.75"><geom name="torso_geom_torso_6" type="box" size="0.30329478923319986 0.19388882349293535 0.09935334668034476" pos="0 0 0" contype="1" conaffinity="7" material="pink" /><joint name="torso_6_root" type="free" armature="0" damping="0" limited="false" /><site name="torso_6_site" pos="0 0 0" type="sphere" size="0.01" /><body name="leg_6_1" pos="-0.15164739461659993 0 0"><geom name="leg_6_1_upper_geom" type="capsule" fromto="0.0 0.0 0.0 0.17786402168274656 0.0 0.0" size="0.04" /><joint name="leg_6_1_hip_joint" type="ball" damping="2.0" /><body name="leg_6_1_lower" pos="0.17786402168274656 0.0 0.0"><geom name="leg_6_1_lower_geom" type="capsule" fromto="0.17786402168274656 0.0 0.0 0.3596506940701031 0.0 0.0" size="0.04" /><joint name="leg_6_1_knee_joint" type="hinge" axis="0 1 0" range="-90 90" damping="4.0" limited="true" /><body name="leg_6_1_foot" pos="0.3596506940701031 0.0 0.0"><geom name="leg_6_1_foot_geom" type="cylinder" fromto="0.3596506940701031 0.0 0.0 0.48331056120385135 0.0 0.0" size="0.04" /><joint name="leg_6_1_ankle_joint" type="ball" damping="6.0" /></body></body></body></body><geom name="flag_6" type="box" size="0.05 0.05 0.5" pos="-3.5623624725152103 8.40270485286422 0" material="pink" contype="1" conaffinity="7" /><body name="torso_7" pos="0 6.5 0.75"><geom name="torso_geom_torso_7" type="box" size="0.41601178730600985 0.14769683656829075 0.06648914307562892" pos="0 0 0" contype="1" conaffinity="8" material="grey" /><joint name="torso_7_root" type="free" armature="0" damping="0" limited="false" /><site name="torso_7_site" pos="0 0 0" type="sphere" size="0.01" /><body name="leg_7_1" pos="-0.20800589365300493 0 0"><geom name="leg_7_1_upper_geom" type="capsule" fromto="0.0 0.0 0.0 0.11039779431916981 0.0 0.0" size="0.04" /><joint name="leg_7_1_hip_joint" type="ball" damping="2.0" /><body name="leg_7_1_lower" pos="0.11039779431916981 0.0 0.0"><geom name="leg_7_1_lower_geom" type="capsule" fromto="0.11039779431916981 0.0 0.0 0.2852225928910833 0.0 0.0" size="0.04" /><joint name="leg_7_1_knee_joint" type="hinge" axis="0 1 0" range="-90 90" damping="4.0" limited="true" /><body name="leg_7_1_foot" pos="0.2852225928910833 0.0 0.0"><geom name="leg_7_1_foot_geom" type="cylinder" fromto="0.2852225928910833 0.0 0.0 0.3922549690795939 0.0 0.0" size="0.04" /><joint name="leg_7_1_ankle_joint" type="ball" damping="6.0" /></body></body></body><body name="leg_7_2" pos="0 -0.07384841828414537 0"><geom name="leg_7_2_upper_geom" type="capsule" fromto="0.0 0.0 0.0 0.12770199892698106 0.0 0.0" size="0.04" /><joint name="leg_7_2_hip_joint" type="ball" damping="2.0" /><body name="leg_7_2_lower" pos="0.12770199892698106 0.0 0.0"><geom name="leg_7_2_lower_geom" type="capsule" fromto="0.12770199892698106 0.0 0.0 0.2854683620967763 0.0 0.0" size="0.04" /><joint name="leg_7_2_knee_joint" type="hinge" axis="0 1 0" range="-90 90" damping="4.0" limited="true" /><body name="leg_7_2_foot" pos="0.2854683620967763 0.0 0.0"><geom name="leg_7_2_foot_geom" type="cylinder" fromto="0.2854683620967763 0.0 0.0 0.48106288628886673 0.0 0.0" size="0.04" /><joint name="leg_7_2_ankle_joint" type="ball" damping="6.0" /></body></body></body></body><geom name="flag_7" type="box" size="0.05 0.05 0.5" pos="-3.070992503875911 8.17898929154952 0" material="grey" contype="1" conaffinity="8" /><body name="torso_8" pos="6.5 6.5 0.75"><geom name="torso_geom_torso_8" type="box" size="0.4530049499005504 0.12377698243112165 0.09765105436003976" pos="0 0 0" contype="1" conaffinity="9" material="brown" /><joint name="torso_8_root" type="free" armature="0" damping="0" limited="false" /><site name="torso_8_site" pos="0 0 0" type="sphere" size="0.01" /><body name="leg_8_1" pos="0 -0.06188849121556082 0"><geom name="leg_8_1_upper_geom" type="capsule" fromto="0.0 0.0 0.0 0.1861542144066951 0.0 0.0" size="0.04" /><joint name="leg_8_1_hip_joint" type="ball" damping="2.0" /><body name="leg_8_1_lower" pos="0.1861542144066951 0.0 0.0"><geom name="leg_8_1_lower_geom" type="capsule" fromto="0.1861542144066951 0.0 0.0 0.3200828579019609 0.0 0.0" size="0.04" /><joint name="leg_8_1_knee_joint" type="hinge" axis="0 1 0" range="-90 90" damping="4.0" limited="true" /><body name="leg_8_1_foot" pos="0.3200828579019609 0.0 0.0"><geom name="leg_8_1_foot_geom" type="cylinder" fromto="0.3200828579019609 0.0 0.0 0.4482361378555679 0.0 0.0" size="0.04" /><joint name="leg_8_1_ankle_joint" type="ball" damping="6.0" /></body></body></body><body name="leg_8_2" pos="0 -0.06188849121556082 0"><geom name="leg_8_2_upper_geom" type="capsule" fromto="0.0 0.0 0.0 0.15955570754040785 0.0 0.0" size="0.04" /><joint name="leg_8_2_hip_joint" type="ball" damping="2.0" /><body name="leg_8_2_lower" pos="0.15955570754040785 0.0 0.0"><geom name="leg_8_2_lower_geom" type="capsule" fromto="0.15955570754040785 0.0 0.0 0.31385490503792235 0.0 0.0" size="0.04" /><joint name="leg_8_2_knee_joint" type="hinge" axis="0 1 0" range="-90 90" damping="4.0" limited="true" /><body name="leg_8_2_foot" pos="0.31385490503792235 0.0 0.0"><geom name="leg_8_2_foot_geom" type="cylinder" fromto="0.31385490503792235 0.0 0.0 0.4241532380654516 0.0 0.0" size="0.04" /><joint name="leg_8_2_ankle_joint" type="ball" damping="6.0" /></body></body></body><body name="leg_8_3" pos="0 -0.06188849121556082 0"><geom name="leg_8_3_upper_geom" type="capsule" fromto="0.0 0.0 0.0 0.13244878656825818 0.0 0.0" size="0.04" /><joint name="leg_8_3_hip_joint" type="ball" damping="2.0" /><body name="leg_8_3_lower" pos="0.13244878656825818 0.0 0.0"><geom name="leg_8_3_lower_geom" type="capsule" fromto="0.13244878656825818 0.0 0.0 0.2964427147327303 0.0 0.0" size="0.04" /><joint name="leg_8_3_knee_joint" type="hinge" axis="0 1 0" range="-90 90" damping="4.0" limited="true" /><body name="leg_8_3_foot" pos="0.2964427147327303 0.0 0.0"><geom name="leg_8_3_foot_geom" type="cylinder" fromto="0.2964427147327303 0.0 0.0 0.4609100063803377 0.0 0.0" size="0.04" /><joint name="leg_8_3_ankle_joint" type="ball" damping="6.0" /></body></body></body><body name="leg_8_4" pos="-0.2265024749502752 0 0"><geom name="leg_8_4_upper_geom" type="capsule" fromto="0.0 0.0 0.0 0.10247787684866003 0.0 0.0" size="0.04" /><joint name="leg_8_4_hip_joint" type="ball" damping="2.0" /><body name="leg_8_4_lower" pos="0.10247787684866003 0.0 0.0"><geom name="leg_8_4_lower_geom" type="capsule" fromto="0.10247787684866003 0.0 0.0 0.20507159494654845 0.0 0.0" size="0.04" /><joint name="leg_8_4_knee_joint" type="hinge" axis="0 1 0" range="-90 90" damping="4.0" limited="true" /><body name="leg_8_4_foot" pos="0.20507159494654845 0.0 0.0"><geom name="leg_8_4_foot_geom" type="cylinder" fromto="0.20507159494654845 0.0 0.0 0.39518275115613166 0.0 0.0" size="0.04" /><joint name="leg_8_4_ankle_joint" type="ball" damping="6.0" /></body></body></body></body><geom name="flag_8" type="box" size="0.05 0.05 0.5" pos="9.391640150191584 8.471907006377327 0" material="brown" contype="1" conaffinity="9" /><geom name="north_wall" type="box" pos="0 10.05 0.25" size="10.05 0.05 0.25" material="MatPlane" /><geom name="south_wall" type="box" pos="0 -10.05 0.25" size="10.05 0.05 0.25" material="MatPlane" /><geom name="east_wall" type="box" pos="10.05 0 0.25" size="0.05 10.05 0.25" material="MatPlane" /><geom name="west_wall" type="box" pos="-10.05 0 0.25" size="0.05 10.05 0.25" material="MatPlane" /></worldbody><actuator><motor name="leg_0_1_hip_motor" joint="leg_0_1_hip_joint" ctrllimited="true" ctrlrange="-1 1" gear="200" /><motor name="leg_0_1_ankle_joint_motor" joint="leg_0_1_ankle_joint" ctrllimited="true" ctrlrange="-1 1" gear="200" /><motor name="leg_1_1_hip_motor" joint="leg_1_1_hip_joint" ctrllimited="true" ctrlrange="-1 1" gear="200" /><motor name="leg_1_1_ankle_joint_motor" joint="leg_1_1_ankle_joint" ctrllimited="true" ctrlrange="-1 1" gear="200" /><motor name="leg_1_2_hip_motor" joint="leg_1_2_hip_joint" ctrllimited="true" ctrlrange="-1 1" gear="200" /><motor name="leg_1_2_ankle_joint_motor" joint="leg_1_2_ankle_joint" ctrllimited="true" ctrlrange="-1 1" gear="200" /><motor name="leg_1_3_hip_motor" joint="leg_1_3_hip_joint" ctrllimited="true" ctrlrange="-1 1" gear="200" /><motor name="leg_1_3_ankle_joint_motor" joint="leg_1_3_ankle_joint" ctrllimited="true" ctrlrange="-1 1" gear="200" /><motor name="leg_1_4_hip_motor" joint="leg_1_4_hip_joint" ctrllimited="true" ctrlrange="-1 1" gear="200" /><motor name="leg_1_4_ankle_joint_motor" joint="leg_1_4_ankle_joint" ctrllimited="true" ctrlrange="-1 1" gear="200" /><motor name="leg_2_1_hip_motor" joint="leg_2_1_hip_joint" ctrllimited="true" ctrlrange="-1 1" gear="200" /><motor name="leg_2_1_ankle_joint_motor" joint="leg_2_1_ankle_joint" ctrllimited="true" ctrlrange="-1 1" gear="200" /><motor name="leg_2_2_hip_motor" joint="leg_2_2_hip_joint" ctrllimited="true" ctrlrange="-1 1" gear="200" /><motor name="leg_2_2_ankle_joint_motor" joint="leg_2_2_ankle_joint" ctrllimited="true" ctrlrange="-1 1" gear="200" /><motor name="leg_2_3_hip_motor" joint="leg_2_3_hip_joint" ctrllimited="true" ctrlrange="-1 1" gear="200" /><motor name="leg_2_3_ankle_joint_motor" joint="leg_2_3_ankle_joint" ctrllimited="true" ctrlrange="-1 1" gear="200" /><motor name="leg_2_4_hip_motor" joint="leg_2_4_hip_joint" ctrllimited="true" ctrlrange="-1 1" gear="200" /><motor name="leg_2_4_ankle_joint_motor" joint="leg_2_4_ankle_joint" ctrllimited="true" ctrlrange="-1 1" gear="200" /><motor name="leg_3_1_hip_motor" joint="leg_3_1_hip_joint" ctrllimited="true" ctrlrange="-1 1" gear="200" /><motor name="leg_3_1_ankle_joint_motor" joint="leg_3_1_ankle_joint" ctrllimited="true" ctrlrange="-1 1" gear="200" /><motor name="leg_4_1_hip_motor" joint="leg_4_1_hip_joint" ctrllimited="true" ctrlrange="-1 1" gear="200" /><motor name="leg_4_1_ankle_joint_motor" joint="leg_4_1_ankle_joint" ctrllimited="true" ctrlrange="-1 1" gear="200" /><motor name="leg_4_2_hip_motor" joint="leg_4_2_hip_joint" ctrllimited="true" ctrlrange="-1 1" gear="200" /><motor name="leg_4_2_ankle_joint_motor" joint="leg_4_2_ankle_joint" ctrllimited="true" ctrlrange="-1 1" gear="200" /><motor name="leg_5_1_hip_motor" joint="leg_5_1_hip_joint" ctrllimited="true" ctrlrange="-1 1" gear="200" /><motor name="leg_5_1_ankle_joint_motor" joint="leg_5_1_ankle_joint" ctrllimited="true" ctrlrange="-1 1" gear="200" /><motor name="leg_5_2_hip_motor" joint="leg_5_2_hip_joint" ctrllimited="true" ctrlrange="-1 1" gear="200" /><motor name="leg_5_2_ankle_joint_motor" joint="leg_5_2_ankle_joint" ctrllimited="true" ctrlrange="-1 1" gear="200" /><motor name="leg_6_1_hip_motor" joint="leg_6_1_hip_joint" ctrllimited="true" ctrlrange="-1 1" gear="200" /><motor name="leg_6_1_ankle_joint_motor" joint="leg_6_1_ankle_joint" ctrllimited="true" ctrlrange="-1 1" gear="200" /><motor name="leg_7_1_hip_motor" joint="leg_7_1_hip_joint" ctrllimited="true" ctrlrange="-1 1" gear="200" /><motor name="leg_7_1_ankle_joint_motor" joint="leg_7_1_ankle_joint" ctrllimited="true" ctrlrange="-1 1" gear="200" /><motor name="leg_7_2_hip_motor" joint="leg_7_2_hip_joint" ctrllimited="true" ctrlrange="-1 1" gear="200" /><motor name="leg_7_2_ankle_joint_motor" joint="leg_7_2_ankle_joint" ctrllimited="true" ctrlrange="-1 1" gear="200" /><motor name="leg_8_1_hip_motor" joint="leg_8_1_hip_joint" ctrllimited="true" ctrlrange="-1 1" gear="200" /><motor name="leg_8_1_ankle_joint_motor" joint="leg_8_1_ankle_joint" ctrllimited="true" ctrlrange="-1 1" gear="200" /><motor name="leg_8_2_hip_motor" joint="leg_8_2_hip_joint" ctrllimited="true" ctrlrange="-1 1" gear="200" /><motor name="leg_8_2_ankle_joint_motor" joint="leg_8_2_ankle_joint" ctrllimited="true" ctrlrange="-1 1" gear="200" /><motor name="leg_8_3_hip_motor" joint="leg_8_3_hip_joint" ctrllimited="true" ctrlrange="-1 1" gear="200" /><motor name="leg_8_3_ankle_joint_motor" joint="leg_8_3_ankle_joint" ctrllimited="true" ctrlrange="-1 1" gear="200" /><motor name="leg_8_4_hip_motor" joint="leg_8_4_hip_joint" ctrllimited="true" ctrlrange="-1 1" gear="200" /><motor name="leg_8_4_ankle_joint_motor" joint="leg_8_4_ankle_joint" ctrllimited="true" ctrlrange="-1 1" gear="200" /></actuator><sensor><accelerometer name="torso_0_accel" site="torso_0_site" /><gyro name="torso_0_gyro" site="torso_0_site" /><accelerometer name="torso_1_accel" site="torso_1_site" /><gyro name="torso_1_gyro" site="torso_1_site" /><accelerometer name="torso_2_accel" site="torso_2_site" /><gyro name="torso_2_gyro" site="torso_2_site" /><accelerometer name="torso_3_accel" site="torso_3_site" /><gyro name="torso_3_gyro" site="torso_3_site" /><accelerometer name="torso_4_accel" site="torso_4_site" /><gyro name="torso_4_gyro" site="torso_4_site" /><accelerometer name="torso_5_accel" site="torso_5_site" /><gyro name="torso_5_gyro" site="torso_5_site" /><accelerometer name="torso_6_accel" site="torso_6_site" /><gyro name="torso_6_gyro" site="torso_6_site" /><accelerometer name="torso_7_accel" site="torso_7_site" /><gyro name="torso_7_gyro" site="torso_7_site" /><accelerometer name="torso_8_accel" site="torso_8_site" /><gyro name="torso_8_gyro" site="torso_8_site" /></sensor></mujoco>