<mujoco><option timestep="0.002" /><asset><texture name="checkered" type="2d" builtin="checker" rgb1="0.2 0.3 0.4" rgb2="0.9 0.9 0.9" width="512" height="512" /><material name="MatCheckered" texture="checkered" reflectance="0.5" /><material name="MatPlane" reflectance="0.5" shininess="1" specular="1" /><material name="red" rgba="1 0 0 1" /><material name="green" rgba="0 1 0 1" /><material name="blue" rgba="0 0 1 1" /><material name="yellow" rgba="1 1 0 1" /><material name="purple" rgba="0.5 0 0.5 1" /><material name="orange" rgba="1 0.5 0 1" /><material name="pink" rgba="1 0.7 0.7 1" /><material name="grey" rgba="0.5 0.5 0.5 1" /><material name="brown" rgba="0.6 0.3 0 1" /></asset><worldbody><geom name="floor" type="plane" size="10 10 0.1" pos="0 0 0" material="MatCheckered" /><body name="torso_0" pos="-6.5 -6.5 0.75"><geom name="torso_geom_torso_0" type="box" size="0.45673066282082714 0.18031773918686675 0.09983389958844013" pos="0 0 0" contype="1" conaffinity="1" material="red" /><joint name="torso_0_root" type="free" armature="0" damping="0" limited="false" /><site name="torso_0_site" pos="0 0 0" type="sphere" size="0.01" /><body name="leg_0_1" pos="-0.22836533141041357 0 0"><geom name="leg_0_1_upper_geom" type="capsule" fromto="0.0 0.0 0.0 0.19134875010583652 0.0 0.0" size="0.04" /><joint name="leg_0_1_hip_joint" type="ball" damping="2.0" /><body name="leg_0_1_lower" pos="0.19134875010583652 0.0 0.0"><geom name="leg_0_1_lower_geom" type="capsule" fromto="0.19134875010583652 0.0 0.0 0.37852999139530136 0.0 0.0" size="0.04" /><joint name="leg_0_1_knee_joint" type="hinge" axis="0 1 0" range="-90 90" damping="4.0" limited="true" /><body name="leg_0_1_foot" pos="0.37852999139530136 0.0 0.0"><geom name="leg_0_1_foot_geom" type="cylinder" fromto="0.37852999139530136 0.0 0.0 0.5137162706306135 0.0 0.0" size="0.04" /><joint name="leg_0_1_ankle_joint" type="ball" damping="6.0" /></body></body></body><body name="leg_0_2" pos="-0.22836533141041357 0 0"><geom name="leg_0_2_upper_geom" type="capsule" fromto="0.0 0.0 0.0 0.1251175439799218 0.0 0.0" size="0.04" /><joint name="leg_0_2_hip_joint" type="ball" damping="2.0" /><body name="leg_0_2_lower" pos="0.1251175439799218 0.0 0.0"><geom name="leg_0_2_lower_geom" type="capsule" fromto="0.1251175439799218 0.0 0.0 0.3032230212060134 0.0 0.0" size="0.04" /><joint name="leg_0_2_knee_joint" type="hinge" axis="0 1 0" range="-90 90" damping="4.0" limited="true" /><body name="leg_0_2_foot" pos="0.3032230212060134 0.0 0.0"><geom name="leg_0_2_foot_geom" type="cylinder" fromto="0.3032230212060134 0.0 0.0 0.49339589541612516 0.0 0.0" size="0.04" /><joint name="leg_0_2_ankle_joint" type="ball" damping="6.0" /></body></body></body><body name="leg_0_3" pos="-0.22836533141041357 0 0"><geom name="leg_0_3_upper_geom" type="capsule" fromto="0.0 0.0 0.0 0.14583288129909064 0.0 0.0" size="0.04" /><joint name="leg_0_3_hip_joint" type="ball" damping="2.0" /><body name="leg_0_3_lower" pos="0.14583288129909064 0.0 0.0"><geom name="leg_0_3_lower_geom" type="capsule" fromto="0.14583288129909064 0.0 0.0 0.2670044036594843 0.0 0.0" size="0.04" /><joint name="leg_0_3_knee_joint" type="hinge" axis="0 1 0" range="-90 90" damping="4.0" limited="true" /><body name="leg_0_3_foot" pos="0.2670044036594843 0.0 0.0"><geom name="leg_0_3_foot_geom" type="cylinder" fromto="0.2670044036594843 0.0 0.0 0.3973557180265023 0.0 0.0" size="0.04" /><joint name="leg_0_3_ankle_joint" type="ball" damping="6.0" /></body></body></body></body><geom name="flag_0" type="box" size="0.05 0.05 0.5" pos="-9.715502872661746 -7.882223308985947 0" material="red" contype="1" conaffinity="1" /><body name="torso_1" pos="0 -6.5 0.75"><geom name="torso_geom_torso_1" type="box" size="0.4361155428149704 0.1853569618573218 0.07967056476117033" pos="0 0 0" contype="1" conaffinity="2" material="green" /><joint name="torso_1_root" type="free" armature="0" damping="0" limited="false" /><site name="torso_1_site" pos="0 0 0" type="sphere" size="0.01" /><body name="leg_1_1" pos="0 0.0926784809286609 0"><geom name="leg_1_1_upper_geom" type="capsule" fromto="0.0 0.0 0.0 0.11647771207757 0.0 0.0" size="0.04" /><joint name="leg_1_1_hip_joint" type="ball" damping="2.0" /><body name="leg_1_1_lower" pos="0.11647771207757 0.0 0.0"><geom name="leg_1_1_lower_geom" type="capsule" fromto="0.11647771207757 0.0 0.0 0.29065504208876797 0.0 0.0" size="0.04" /><joint name="leg_1_1_knee_joint" type="hinge" axis="0 1 0" range="-90 90" damping="4.0" limited="true" /><body name="leg_1_1_foot" pos="0.29065504208876797 0.0 0.0"><geom name="leg_1_1_foot_geom" type="cylinder" fromto="0.29065504208876797 0.0 0.0 0.4394491817589016 0.0 0.0" size="0.04" /><joint name="leg_1_1_ankle_joint" type="ball" damping="6.0" /></body></body></body><body name="leg_1_2" pos="0 0.0926784809286609 0"><geom name="leg_1_2_upper_geom" type="capsule" fromto="0.0 0.0 0.0 0.19848603360304248 0.0 0.0" size="0.04" /><joint name="leg_1_2_hip_joint" type="ball" damping="2.0" /><body name="leg_1_2_lower" pos="0.19848603360304248 0.0 0.0"><geom name="leg_1_2_lower_geom" type="capsule" fromto="0.19848603360304248 0.0 0.0 0.35335942091159783 0.0 0.0" size="0.04" /><joint name="leg_1_2_knee_joint" type="hinge" axis="0 1 0" range="-90 90" damping="4.0" limited="true" /><body name="leg_1_2_foot" pos="0.35335942091159783 0.0 0.0"><geom name="leg_1_2_foot_geom" type="cylinder" fromto="0.35335942091159783 0.0 0.0 0.5411384136035422 0.0 0.0" size="0.04" /><joint name="leg_1_2_ankle_joint" type="ball" damping="6.0" /></body></body></body><body name="leg_1_3" pos="-0.2180577714074852 0 0"><geom name="leg_1_3_upper_geom" type="capsule" fromto="0.0 0.0 0.0 0.1322498566570886 0.0 0.0" size="0.04" /><joint name="leg_1_3_hip_joint" type="ball" damping="2.0" /><body name="leg_1_3_lower" pos="0.1322498566570886 0.0 0.0"><geom name="leg_1_3_lower_geom" type="capsule" fromto="0.1322498566570886 0.0 0.0 0.26793260223526116 0.0 0.0" size="0.04" /><joint name="leg_1_3_knee_joint" type="hinge" axis="0 1 0" range="-90 90" damping="4.0" limited="true" /><body name="leg_1_3_foot" pos="0.26793260223526116 0.0 0.0"><geom name="leg_1_3_foot_geom" type="cylinder" fromto="0.26793260223526116 0.0 0.0 0.38986656143791676 0.0 0.0" size="0.04" /><joint name="leg_1_3_ankle_joint" type="ball" damping="6.0" /></body></body></body></body><geom name="flag_1" type="box" size="0.05 0.05 0.5" pos="-2.702629906381044 -4.276086424985271 0" material="green" contype="1" conaffinity="2" /><body name="torso_2" pos="6.5 -6.5 0.75"><geom name="torso_geom_torso_2" type="box" size="0.27710142291960344 0.18385307976890158 0.07352698970238292" pos="0 0 0" contype="1" conaffinity="3" material="blue" /><joint name="torso_2_root" type="free" armature="0" damping="0" limited="false" /><site name="torso_2_site" pos="0 0 0" type="sphere" size="0.01" /><body name="leg_2_1" pos="0.13855071145980172 0 0"><geom name="leg_2_1_upper_geom" type="capsule" fromto="0.0 0.0 0.0 0.1475986095326487 0.0 0.0" size="0.04" /><joint name="leg_2_1_hip_joint" type="ball" damping="2.0" /><body name="leg_2_1_lower" pos="0.1475986095326487 0.0 0.0"><geom name="leg_2_1_lower_geom" type="capsule" fromto="0.1475986095326487 0.0 0.0 0.3147290617853762 0.0 0.0" size="0.04" /><joint name="leg_2_1_knee_joint" type="hinge" axis="0 1 0" range="-90 90" damping="4.0" limited="true" /><body name="leg_2_1_foot" pos="0.3147290617853762 0.0 0.0"><geom name="leg_2_1_foot_geom" type="cylinder" fromto="0.3147290617853762 0.0 0.0 0.48499941278908454 0.0 0.0" size="0.04" /><joint name="leg_2_1_ankle_joint" type="ball" damping="6.0" /></body></body></body><body name="leg_2_2" pos="0 -0.09192653988445079 0"><geom name="leg_2_2_upper_geom" type="capsule" fromto="0.0 0.0 0.0 0.12382817809722703 0.0 0.0" size="0.04" /><joint name="leg_2_2_hip_joint" type="ball" damping="2.0" /><body name="leg_2_2_lower" pos="0.12382817809722703 0.0 0.0"><geom name="leg_2_2_lower_geom" type="capsule" fromto="0.12382817809722703 0.0 0.0 0.2685634560439831 0.0 0.0" size="0.04" /><joint name="leg_2_2_knee_joint" type="hinge" axis="0 1 0" range="-90 90" damping="4.0" limited="true" /><body name="leg_2_2_foot" pos="0.2685634560439831 0.0 0.0"><geom name="leg_2_2_foot_geom" type="cylinder" fromto="0.2685634560439831 0.0 0.0 0.41962847793161295 0.0 0.0" size="0.04" /><joint name="leg_2_2_ankle_joint" type="ball" damping="6.0" /></body></body></body></body><geom name="flag_2" type="box" size="0.05 0.05 0.5" pos="4.200801388571732 -9.138879638256798 0" material="blue" contype="1" conaffinity="3" /><body name="torso_3" pos="-6.5 0 0.75"><geom name="torso_geom_torso_3" type="box" size="0.2667361206778316 0.1890291781063165 0.06752250962156768" pos="0 0 0" contype="1" conaffinity="4" material="yellow" /><joint name="torso_3_root" type="free" armature="0" damping="0" limited="false" /><site name="torso_3_site" pos="0 0 0" type="sphere" size="0.01" /><body name="leg_3_1" pos="0.1333680603389158 0 0"><geom name="leg_3_1_upper_geom" type="capsule" fromto="0.0 0.0 0.0 0.11752958113271068 0.0 0.0" size="0.04" /><joint name="leg_3_1_hip_joint" type="ball" damping="2.0" /><body name="leg_3_1_lower" pos="0.11752958113271068 0.0 0.0"><geom name="leg_3_1_lower_geom" type="capsule" fromto="0.11752958113271068 0.0 0.0 0.24753236078776086 0.0 0.0" size="0.04" /><joint name="leg_3_1_knee_joint" type="hinge" axis="0 1 0" range="-90 90" damping="4.0" limited="true" /><body name="leg_3_1_foot" pos="0.24753236078776086 0.0 0.0"><geom name="leg_3_1_foot_geom" type="cylinder" fromto="0.24753236078776086 0.0 0.0 0.4023332760425279 0.0 0.0" size="0.04" /><joint name="leg_3_1_ankle_joint" type="ball" damping="6.0" /></body></body></body><body name="leg_3_2" pos="0 0.09451458905315825 0"><geom name="leg_3_2_upper_geom" type="capsule" fromto="0.0 0.0 0.0 0.12786140470453047 0.0 0.0" size="0.04" /><joint name="leg_3_2_hip_joint" type="ball" damping="2.0" /><body name="leg_3_2_lower" pos="0.12786140470453047 0.0 0.0"><geom name="leg_3_2_lower_geom" type="capsule" fromto="0.12786140470453047 0.0 0.0 0.29212740537773285 0.0 0.0" size="0.04" /><joint name="leg_3_2_knee_joint" type="hinge" axis="0 1 0" range="-90 90" damping="4.0" limited="true" /><body name="leg_3_2_foot" pos="0.29212740537773285 0.0 0.0"><geom name="leg_3_2_foot_geom" type="cylinder" fromto="0.29212740537773285 0.0 0.0 0.4096014507658057 0.0 0.0" size="0.04" /><joint name="leg_3_2_ankle_joint" type="ball" damping="6.0" /></body></body></body><body name="leg_3_3" pos="-0.1333680603389158 0 0"><geom name="leg_3_3_upper_geom" type="capsule" fromto="0.0 0.0 0.0 0.1618008323869887 0.0 0.0" size="0.04" /><joint name="leg_3_3_hip_joint" type="ball" damping="2.0" /><body name="leg_3_3_lower" pos="0.1618008323869887 0.0 0.0"><geom name="leg_3_3_lower_geom" type="capsule" fromto="0.1618008323869887 0.0 0.0 0.2867447121978153 0.0 0.0" size="0.04" /><joint name="leg_3_3_knee_joint" type="hinge" axis="0 1 0" range="-90 90" damping="4.0" limited="true" /><body name="leg_3_3_foot" pos="0.2867447121978153 0.0 0.0"><geom name="leg_3_3_foot_geom" type="cylinder" fromto="0.2867447121978153 0.0 0.0 0.47296085840796076 0.0 0.0" size="0.04" /><joint name="leg_3_3_ankle_joint" type="ball" damping="6.0" /></body></body></body></body><geom name="flag_3" type="box" size="0.05 0.05 0.5" pos="-3.8584770375979724 -2.296161239787576 0" material="yellow" contype="1" conaffinity="4" /><body name="torso_4" pos="0 0 0.75"><geom name="torso_geom_torso_4" type="box" size="0.33677437006201405 0.12088301522371618 0.07653703224081529" pos="0 0 0" contype="1" conaffinity="5" material="purple" /><joint name="torso_4_root" type="free" armature="0" damping="0" limited="false" /><site name="torso_4_site" pos="0 0 0" type="sphere" size="0.01" /><body name="leg_4_1" pos="0 -0.06044150761185809 0"><geom name="leg_4_1_upper_geom" type="capsule" fromto="0.0 0.0 0.0 0.14596158616241114 0.0 0.0" size="0.04" /><joint name="leg_4_1_hip_joint" type="ball" damping="2.0" /><body name="leg_4_1_lower" pos="0.14596158616241114 0.0 0.0"><geom name="leg_4_1_lower_geom" type="capsule" fromto="0.14596158616241114 0.0 0.0 0.279742887019907 0.0 0.0" size="0.04" /><joint name="leg_4_1_knee_joint" type="hinge" axis="0 1 0" range="-90 90" damping="4.0" limited="true" /><body name="leg_4_1_foot" pos="0.279742887019907 0.0 0.0"><geom name="leg_4_1_foot_geom" type="cylinder" fromto="0.279742887019907 0.0 0.0 0.4237752228046575 0.0 0.0" size="0.04" /><joint name="leg_4_1_ankle_joint" type="ball" damping="6.0" /></body></body></body></body><geom name="flag_4" type="box" size="0.05 0.05 0.5" pos="-1.595599832349964 3.1151342146053302 0" material="purple" contype="1" conaffinity="5" /><body name="torso_5" pos="6.5 0 0.75"><geom name="torso_geom_torso_5" type="box" size="0.27910796986527076 0.19385913140496652 0.06810284901716221" pos="0 0 0" contype="1" conaffinity="6" material="orange" /><joint name="torso_5_root" type="free" armature="0" damping="0" limited="false" /><site name="torso_5_site" pos="0 0 0" type="sphere" size="0.01" /><body name="leg_5_1" pos="0.13955398493263538 0 0"><geom name="leg_5_1_upper_geom" type="capsule" fromto="0.0 0.0 0.0 0.15884223762782185 0.0 0.0" size="0.04" /><joint name="leg_5_1_hip_joint" type="ball" damping="2.0" /><body name="leg_5_1_lower" pos="0.15884223762782185 0.0 0.0"><geom name="leg_5_1_lower_geom" type="capsule" fromto="0.15884223762782185 0.0 0.0 0.3461261877342965 0.0 0.0" size="0.04" /><joint name="leg_5_1_knee_joint" type="hinge" axis="0 1 0" range="-90 90" damping="4.0" limited="true" /><body name="leg_5_1_foot" pos="0.3461261877342965 0.0 0.0"><geom name="leg_5_1_foot_geom" type="cylinder" fromto="0.3461261877342965 0.0 0.0 0.5322099372082175 0.0 0.0" size="0.04" /><joint name="leg_5_1_ankle_joint" type="ball" damping="6.0" /></body></body></body></body><geom name="flag_5" type="box" size="0.05 0.05 0.5" pos="9.982538084529573 -0.34918260237459164 0" material="orange" contype="1" conaffinity="6" /><body name="torso_6" pos="-6.5 6.5 0.75"><geom name="torso_geom_torso_6" type="box" size="0.29137715618754184 0.18632517681537722 0.05353026217323795" pos="0 0 0" contype="1" conaffinity="7" material="pink" /><joint name="torso_6_root" type="free" armature="0" damping="0" limited="false" /><site name="torso_6_site" pos="0 0 0" type="sphere" size="0.01" /><body name="leg_6_1" pos="0 -0.09316258840768861 0"><geom name="leg_6_1_upper_geom" type="capsule" fromto="0.0 0.0 0.0 0.18501982875361223 0.0 0.0" size="0.04" /><joint name="leg_6_1_hip_joint" type="ball" damping="2.0" /><body name="leg_6_1_lower" pos="0.18501982875361223 0.0 0.0"><geom name="leg_6_1_lower_geom" type="capsule" fromto="0.18501982875361223 0.0 0.0 0.33158454665107273 0.0 0.0" size="0.04" /><joint name="leg_6_1_knee_joint" type="hinge" axis="0 1 0" range="-90 90" damping="4.0" limited="true" /><body name="leg_6_1_foot" pos="0.33158454665107273 0.0 0.0"><geom name="leg_6_1_foot_geom" type="cylinder" fromto="0.33158454665107273 0.0 0.0 0.5161514691046316 0.0 0.0" size="0.04" /><joint name="leg_6_1_ankle_joint" type="ball" damping="6.0" /></body></body></body><body name="leg_6_2" pos="0 -0.09316258840768861 0"><geom name="leg_6_2_upper_geom" type="capsule" fromto="0.0 0.0 0.0 0.12628140099512358 0.0 0.0" size="0.04" /><joint name="leg_6_2_hip_joint" type="ball" damping="2.0" /><body name="leg_6_2_lower" pos="0.12628140099512358 0.0 0.0"><geom name="leg_6_2_lower_geom" type="capsule" fromto="0.12628140099512358 0.0 0.0 0.25289257737624526 0.0 0.0" size="0.04" /><joint name="leg_6_2_knee_joint" type="hinge" axis="0 1 0" range="-90 90" damping="4.0" limited="true" /><body name="leg_6_2_foot" pos="0.25289257737624526 0.0 0.0"><geom name="leg_6_2_foot_geom" type="cylinder" fromto="0.25289257737624526 0.0 0.0 0.416903476540581 0.0 0.0" size="0.04" /><joint name="leg_6_2_ankle_joint" type="ball" damping="6.0" /></body></body></body><body name="leg_6_3" pos="0 -0.09316258840768861 0"><geom name="leg_6_3_upper_geom" type="capsule" fromto="0.0 0.0 0.0 0.15481660872583805 0.0 0.0" size="0.04" /><joint name="leg_6_3_hip_joint" type="ball" damping="2.0" /><body name="leg_6_3_lower" pos="0.15481660872583805 0.0 0.0"><geom name="leg_6_3_lower_geom" type="capsule" fromto="0.15481660872583805 0.0 0.0 0.2857181441085962 0.0 0.0" size="0.04" /><joint name="leg_6_3_knee_joint" type="hinge" axis="0 1 0" range="-90 90" damping="4.0" limited="true" /><body name="leg_6_3_foot" pos="0.2857181441085962 0.0 0.0"><geom name="leg_6_3_foot_geom" type="cylinder" fromto="0.2857181441085962 0.0 0.0 0.45838974200002824 0.0 0.0" size="0.04" /><joint name="leg_6_3_ankle_joint" type="ball" damping="6.0" /></body></body></body></body><geom name="flag_6" type="box" size="0.05 0.05 0.5" pos="-3.4815412435326354 8.27169600538735 0" material="pink" contype="1" conaffinity="7" /><body name="torso_7" pos="0 6.5 0.75"><geom name="torso_geom_torso_7" type="box" size="0.4869551706574689 0.18423844265559644 0.07303456001066934" pos="0 0 0" contype="1" conaffinity="8" material="grey" /><joint name="torso_7_root" type="free" armature="0" damping="0" limited="false" /><site name="torso_7_site" pos="0 0 0" type="sphere" size="0.01" /><body name="leg_7_1" pos="0 -0.09211922132779822 0"><geom name="leg_7_1_upper_geom" type="capsule" fromto="0.0 0.0 0.0 0.15041793830888592 0.0 0.0" size="0.04" /><joint name="leg_7_1_hip_joint" type="ball" damping="2.0" /><body name="leg_7_1_lower" pos="0.15041793830888592 0.0 0.0"><geom name="leg_7_1_lower_geom" type="capsule" fromto="0.15041793830888592 0.0 0.0 0.3398287850489801 0.0 0.0" size="0.04" /><joint name="leg_7_1_knee_joint" type="hinge" axis="0 1 0" range="-90 90" damping="4.0" limited="true" /><body name="leg_7_1_foot" pos="0.3398287850489801 0.0 0.0"><geom name="leg_7_1_foot_geom" type="cylinder" fromto="0.3398287850489801 0.0 0.0 0.5199871593237864 0.0 0.0" size="0.04" /><joint name="leg_7_1_ankle_joint" type="ball" damping="6.0" /></body></body></body><body name="leg_7_2" pos="0.24347758532873445 0 0"><geom name="leg_7_2_upper_geom" type="capsule" fromto="0.0 0.0 0.0 0.1920029125222797 0.0 0.0" size="0.04" /><joint name="leg_7_2_hip_joint" type="ball" damping="2.0" /><body name="leg_7_2_lower" pos="0.1920029125222797 0.0 0.0"><geom name="leg_7_2_lower_geom" type="capsule" fromto="0.1920029125222797 0.0 0.0 0.3108622592127082 0.0 0.0" size="0.04" /><joint name="leg_7_2_knee_joint" type="hinge" axis="0 1 0" range="-90 90" damping="4.0" limited="true" /><body name="leg_7_2_foot" pos="0.3108622592127082 0.0 0.0"><geom name="leg_7_2_foot_geom" type="cylinder" fromto="0.3108622592127082 0.0 0.0 0.4657449276293985 0.0 0.0" size="0.04" /><joint name="leg_7_2_ankle_joint" type="ball" damping="6.0" /></body></body></body><body name="leg_7_3" pos="0.24347758532873445 0 0"><geom name="leg_7_3_upper_geom" type="capsule" fromto="0.0 0.0 0.0 0.17026008864513145 0.0 0.0" size="0.04" /><joint name="leg_7_3_hip_joint" type="ball" damping="2.0" /><body name="leg_7_3_lower" pos="0.17026008864513145 0.0 0.0"><geom name="leg_7_3_lower_geom" type="capsule" fromto="0.17026008864513145 0.0 0.0 0.35950564773794824 0.0 0.0" size="0.04" /><joint name="leg_7_3_knee_joint" type="hinge" axis="0 1 0" range="-90 90" damping="4.0" limited="true" /><body name="leg_7_3_foot" pos="0.35950564773794824 0.0 0.0"><geom name="leg_7_3_foot_geom" type="cylinder" fromto="0.35950564773794824 0.0 0.0 0.49613280687904054 0.0 0.0" size="0.04" /><joint name="leg_7_3_ankle_joint" type="ball" damping="6.0" /></body></body></body><body name="leg_7_4" pos="0.24347758532873445 0 0"><geom name="leg_7_4_upper_geom" type="capsule" fromto="0.0 0.0 0.0 0.1786128234715569 0.0 0.0" size="0.04" /><joint name="leg_7_4_hip_joint" type="ball" damping="2.0" /><body name="leg_7_4_lower" pos="0.1786128234715569 0.0 0.0"><geom name="leg_7_4_lower_geom" type="capsule" fromto="0.1786128234715569 0.0 0.0 0.3722628273647567 0.0 0.0" size="0.04" /><joint name="leg_7_4_knee_joint" type="hinge" axis="0 1 0" range="-90 90" damping="4.0" limited="true" /><body name="leg_7_4_foot" pos="0.3722628273647567 0.0 0.0"><geom name="leg_7_4_foot_geom" type="cylinder" fromto="0.3722628273647567 0.0 0.0 0.5455859172804947 0.0 0.0" size="0.04" /><joint name="leg_7_4_ankle_joint" type="ball" damping="6.0" /></body></body></body></body><geom name="flag_7" type="box" size="0.05 0.05 0.5" pos="0.12390716769328443 9.997806028611969 0" material="grey" contype="1" conaffinity="8" /><body name="torso_8" pos="6.5 6.5 0.75"><geom name="torso_geom_torso_8" type="box" size="0.34864485038335136 0.19233670913998374 0.05502190046291183" pos="0 0 0" contype="1" conaffinity="9" material="brown" /><joint name="torso_8_root" type="free" armature="0" damping="0" limited="false" /><site name="torso_8_site" pos="0 0 0" type="sphere" size="0.01" /><body name="leg_8_1" pos="-0.17432242519167568 0 0"><geom name="leg_8_1_upper_geom" type="capsule" fromto="0.0 0.0 0.0 0.1394766231845218 0.0 0.0" size="0.04" /><joint name="leg_8_1_hip_joint" type="ball" damping="2.0" /><body name="leg_8_1_lower" pos="0.1394766231845218 0.0 0.0"><geom name="leg_8_1_lower_geom" type="capsule" fromto="0.1394766231845218 0.0 0.0 0.3308827223944103 0.0 0.0" size="0.04" /><joint name="leg_8_1_knee_joint" type="hinge" axis="0 1 0" range="-90 90" damping="4.0" limited="true" /><body name="leg_8_1_foot" pos="0.3308827223944103 0.0 0.0"><geom name="leg_8_1_foot_geom" type="cylinder" fromto="0.3308827223944103 0.0 0.0 0.44431492585091903 0.0 0.0" size="0.04" /><joint name="leg_8_1_ankle_joint" type="ball" damping="6.0" /></body></body></body><body name="leg_8_2" pos="0.17432242519167568 0 0"><geom name="leg_8_2_upper_geom" type="capsule" fromto="0.0 0.0 0.0 0.11867884462175021 0.0 0.0" size="0.04" /><joint name="leg_8_2_hip_joint" type="ball" damping="2.0" /><body name="leg_8_2_lower" pos="0.11867884462175021 0.0 0.0"><geom name="leg_8_2_lower_geom" type="capsule" fromto="0.11867884462175021 0.0 0.0 0.26560036327234726 0.0 0.0" size="0.04" /><joint name="leg_8_2_knee_joint" type="hinge" axis="0 1 0" range="-90 90" damping="4.0" limited="true" /><body name="leg_8_2_foot" pos="0.26560036327234726 0.0 0.0"><geom name="leg_8_2_foot_geom" type="cylinder" fromto="0.26560036327234726 0.0 0.0 0.4320577198948149 0.0 0.0" size="0.04" /><joint name="leg_8_2_ankle_joint" type="ball" damping="6.0" /></body></body></body></body><geom name="flag_8" type="box" size="0.05 0.05 0.5" pos="4.400815812293695 9.300611673560585 0" material="brown" contype="1" conaffinity="9" /><geom name="north_wall" type="box" pos="0 10.05 0.25" size="10.05 0.05 0.25" material="MatPlane" /><geom name="south_wall" type="box" pos="0 -10.05 0.25" size="10.05 0.05 0.25" material="MatPlane" /><geom name="east_wall" type="box" pos="10.05 0 0.25" size="0.05 10.05 0.25" material="MatPlane" /><geom name="west_wall" type="box" pos="-10.05 0 0.25" size="0.05 10.05 0.25" material="MatPlane" /></worldbody><actuator><motor name="leg_0_1_hip_motor" joint="leg_0_1_hip_joint" ctrllimited="true" ctrlrange="-1 1" gear="200" /><motor name="leg_0_1_ankle_joint_motor" joint="leg_0_1_ankle_joint" ctrllimited="true" ctrlrange="-1 1" gear="200" /><motor name="leg_0_2_hip_motor" joint="leg_0_2_hip_joint" ctrllimited="true" ctrlrange="-1 1" gear="200" /><motor name="leg_0_2_ankle_joint_motor" joint="leg_0_2_ankle_joint" ctrllimited="true" ctrlrange="-1 1" gear="200" /><motor name="leg_0_3_hip_motor" joint="leg_0_3_hip_joint" ctrllimited="true" ctrlrange="-1 1" gear="200" /><motor name="leg_0_3_ankle_joint_motor" joint="leg_0_3_ankle_joint" ctrllimited="true" ctrlrange="-1 1" gear="200" /><motor name="leg_1_1_hip_motor" joint="leg_1_1_hip_joint" ctrllimited="true" ctrlrange="-1 1" gear="200" /><motor name="leg_1_1_ankle_joint_motor" joint="leg_1_1_ankle_joint" ctrllimited="true" ctrlrange="-1 1" gear="200" /><motor name="leg_1_2_hip_motor" joint="leg_1_2_hip_joint" ctrllimited="true" ctrlrange="-1 1" gear="200" /><motor name="leg_1_2_ankle_joint_motor" joint="leg_1_2_ankle_joint" ctrllimited="true" ctrlrange="-1 1" gear="200" /><motor name="leg_1_3_hip_motor" joint="leg_1_3_hip_joint" ctrllimited="true" ctrlrange="-1 1" gear="200" /><motor name="leg_1_3_ankle_joint_motor" joint="leg_1_3_ankle_joint" ctrllimited="true" ctrlrange="-1 1" gear="200" /><motor name="leg_2_1_hip_motor" joint="leg_2_1_hip_joint" ctrllimited="true" ctrlrange="-1 1" gear="200" /><motor name="leg_2_1_ankle_joint_motor" joint="leg_2_1_ankle_joint" ctrllimited="true" ctrlrange="-1 1" gear="200" /><motor name="leg_2_2_hip_motor" joint="leg_2_2_hip_joint" ctrllimited="true" ctrlrange="-1 1" gear="200" /><motor name="leg_2_2_ankle_joint_motor" joint="leg_2_2_ankle_joint" ctrllimited="true" ctrlrange="-1 1" gear="200" /><motor name="leg_3_1_hip_motor" joint="leg_3_1_hip_joint" ctrllimited="true" ctrlrange="-1 1" gear="200" /><motor name="leg_3_1_ankle_joint_motor" joint="leg_3_1_ankle_joint" ctrllimited="true" ctrlrange="-1 1" gear="200" /><motor name="leg_3_2_hip_motor" joint="leg_3_2_hip_joint" ctrllimited="true" ctrlrange="-1 1" gear="200" /><motor name="leg_3_2_ankle_joint_motor" joint="leg_3_2_ankle_joint" ctrllimited="true" ctrlrange="-1 1" gear="200" /><motor name="leg_3_3_hip_motor" joint="leg_3_3_hip_joint" ctrllimited="true" ctrlrange="-1 1" gear="200" /><motor name="leg_3_3_ankle_joint_motor" joint="leg_3_3_ankle_joint" ctrllimited="true" ctrlrange="-1 1" gear="200" /><motor name="leg_4_1_hip_motor" joint="leg_4_1_hip_joint" ctrllimited="true" ctrlrange="-1 1" gear="200" /><motor name="leg_4_1_ankle_joint_motor" joint="leg_4_1_ankle_joint" ctrllimited="true" ctrlrange="-1 1" gear="200" /><motor name="leg_5_1_hip_motor" joint="leg_5_1_hip_joint" ctrllimited="true" ctrlrange="-1 1" gear="200" /><motor name="leg_5_1_ankle_joint_motor" joint="leg_5_1_ankle_joint" ctrllimited="true" ctrlrange="-1 1" gear="200" /><motor name="leg_6_1_hip_motor" joint="leg_6_1_hip_joint" ctrllimited="true" ctrlrange="-1 1" gear="200" /><motor name="leg_6_1_ankle_joint_motor" joint="leg_6_1_ankle_joint" ctrllimited="true" ctrlrange="-1 1" gear="200" /><motor name="leg_6_2_hip_motor" joint="leg_6_2_hip_joint" ctrllimited="true" ctrlrange="-1 1" gear="200" /><motor name="leg_6_2_ankle_joint_motor" joint="leg_6_2_ankle_joint" ctrllimited="true" ctrlrange="-1 1" gear="200" /><motor name="leg_6_3_hip_motor" joint="leg_6_3_hip_joint" ctrllimited="true" ctrlrange="-1 1" gear="200" /><motor name="leg_6_3_ankle_joint_motor" joint="leg_6_3_ankle_joint" ctrllimited="true" ctrlrange="-1 1" gear="200" /><motor name="leg_7_1_hip_motor" joint="leg_7_1_hip_joint" ctrllimited="true" ctrlrange="-1 1" gear="200" /><motor name="leg_7_1_ankle_joint_motor" joint="leg_7_1_ankle_joint" ctrllimited="true" ctrlrange="-1 1" gear="200" /><motor name="leg_7_2_hip_motor" joint="leg_7_2_hip_joint" ctrllimited="true" ctrlrange="-1 1" gear="200" /><motor name="leg_7_2_ankle_joint_motor" joint="leg_7_2_ankle_joint" ctrllimited="true" ctrlrange="-1 1" gear="200" /><motor name="leg_7_3_hip_motor" joint="leg_7_3_hip_joint" ctrllimited="true" ctrlrange="-1 1" gear="200" /><motor name="leg_7_3_ankle_joint_motor" joint="leg_7_3_ankle_joint" ctrllimited="true" ctrlrange="-1 1" gear="200" /><motor name="leg_7_4_hip_motor" joint="leg_7_4_hip_joint" ctrllimited="true" ctrlrange="-1 1" gear="200" /><motor name="leg_7_4_ankle_joint_motor" joint="leg_7_4_ankle_joint" ctrllimited="true" ctrlrange="-1 1" gear="200" /><motor name="leg_8_1_hip_motor" joint="leg_8_1_hip_joint" ctrllimited="true" ctrlrange="-1 1" gear="200" /><motor name="leg_8_1_ankle_joint_motor" joint="leg_8_1_ankle_joint" ctrllimited="true" ctrlrange="-1 1" gear="200" /><motor name="leg_8_2_hip_motor" joint="leg_8_2_hip_joint" ctrllimited="true" ctrlrange="-1 1" gear="200" /><motor name="leg_8_2_ankle_joint_motor" joint="leg_8_2_ankle_joint" ctrllimited="true" ctrlrange="-1 1" gear="200" /></actuator><sensor><accelerometer name="torso_0_accel" site="torso_0_site" /><gyro name="torso_0_gyro" site="torso_0_site" /><accelerometer name="torso_1_accel" site="torso_1_site" /><gyro name="torso_1_gyro" site="torso_1_site" /><accelerometer name="torso_2_accel" site="torso_2_site" /><gyro name="torso_2_gyro" site="torso_2_site" /><accelerometer name="torso_3_accel" site="torso_3_site" /><gyro name="torso_3_gyro" site="torso_3_site" /><accelerometer name="torso_4_accel" site="torso_4_site" /><gyro name="torso_4_gyro" site="torso_4_site" /><accelerometer name="torso_5_accel" site="torso_5_site" /><gyro name="torso_5_gyro" site="torso_5_site" /><accelerometer name="torso_6_accel" site="torso_6_site" /><gyro name="torso_6_gyro" site="torso_6_site" /><accelerometer name="torso_7_accel" site="torso_7_site" /><gyro name="torso_7_gyro" site="torso_7_site" /><accelerometer name="torso_8_accel" site="torso_8_site" /><gyro name="torso_8_gyro" site="torso_8_site" /></sensor></mujoco>