<mujoco><option timestep="0.002" /><asset><texture name="checkered" type="2d" builtin="checker" rgb1="0.2 0.3 0.4" rgb2="0.9 0.9 0.9" width="512" height="512" /><material name="MatCheckered" texture="checkered" reflectance="0.5" /><material name="MatPlane" reflectance="0.5" shininess="1" specular="1" /><material name="red" rgba="1 0 0 1" /><material name="green" rgba="0 1 0 1" /><material name="blue" rgba="0 0 1 1" /><material name="yellow" rgba="1 1 0 1" /><material name="purple" rgba="0.5 0 0.5 1" /><material name="orange" rgba="1 0.5 0 1" /><material name="pink" rgba="1 0.7 0.7 1" /><material name="grey" rgba="0.5 0.5 0.5 1" /><material name="brown" rgba="0.6 0.3 0 1" /></asset><worldbody><geom name="floor" type="plane" size="10 10 0.1" pos="0 0 0" material="MatCheckered" /><body name="torso_0" pos="-6.5 -6.5 0.75"><geom name="torso_geom_torso_0" type="box" size="0.2227067932787442 0.13673996213910158 0.08442764344773176" pos="0 0 0" contype="1" conaffinity="1" material="red" /><joint name="torso_0_root" type="free" armature="0" damping="0" limited="false" /><site name="torso_0_site" pos="0 0 0" type="sphere" size="0.01" /><body name="leg_0_1" pos="0 0.06836998106955079 0"><geom name="leg_0_1_upper_geom" type="capsule" fromto="0.0 0.0 0.0 0.14552714767220581 0.0 0.0" size="0.04" /><joint name="leg_0_1_hip_joint" type="ball" damping="2.0" /><body name="leg_0_1_lower" pos="0.14552714767220581 0.0 0.0"><geom name="leg_0_1_lower_geom" type="capsule" fromto="0.14552714767220581 0.0 0.0 0.32343242023968966 0.0 0.0" size="0.04" /><joint name="leg_0_1_knee_joint" type="hinge" axis="0 1 0" range="-90 90" damping="4.0" limited="true" /><body name="leg_0_1_foot" pos="0.32343242023968966 0.0 0.0"><geom name="leg_0_1_foot_geom" type="cylinder" fromto="0.32343242023968966 0.0 0.0 0.44453812422186184 0.0 0.0" size="0.04" /><joint name="leg_0_1_ankle_joint" type="ball" damping="6.0" /></body></body></body></body><geom name="flag_0" type="box" size="0.05 0.05 0.5" pos="-9.266764355506266 -4.35640138992861 0" material="red" contype="1" conaffinity="1" /><body name="torso_1" pos="0 -6.5 0.75"><geom name="torso_geom_torso_1" type="box" size="0.40728499319575273 0.1930806543685259 0.0651113869433847" pos="0 0 0" contype="1" conaffinity="2" material="green" /><joint name="torso_1_root" type="free" armature="0" damping="0" limited="false" /><site name="torso_1_site" pos="0 0 0" type="sphere" size="0.01" /><body name="leg_1_1" pos="-0.20364249659787637 0 0"><geom name="leg_1_1_upper_geom" type="capsule" fromto="0.0 0.0 0.0 0.1848010148360092 0.0 0.0" size="0.04" /><joint name="leg_1_1_hip_joint" type="ball" damping="2.0" /><body name="leg_1_1_lower" pos="0.1848010148360092 0.0 0.0"><geom name="leg_1_1_lower_geom" type="capsule" fromto="0.1848010148360092 0.0 0.0 0.30193274476679577 0.0 0.0" size="0.04" /><joint name="leg_1_1_knee_joint" type="hinge" axis="0 1 0" range="-90 90" damping="4.0" limited="true" /><body name="leg_1_1_foot" pos="0.30193274476679577 0.0 0.0"><geom name="leg_1_1_foot_geom" type="cylinder" fromto="0.30193274476679577 0.0 0.0 0.45388000903011405 0.0 0.0" size="0.04" /><joint name="leg_1_1_ankle_joint" type="ball" damping="6.0" /></body></body></body><body name="leg_1_2" pos="0 -0.09654032718426295 0"><geom name="leg_1_2_upper_geom" type="capsule" fromto="0.0 0.0 0.0 0.12891196907114916 0.0 0.0" size="0.04" /><joint name="leg_1_2_hip_joint" type="ball" damping="2.0" /><body name="leg_1_2_lower" pos="0.12891196907114916 0.0 0.0"><geom name="leg_1_2_lower_geom" type="capsule" fromto="0.12891196907114916 0.0 0.0 0.26823189268572756 0.0 0.0" size="0.04" /><joint name="leg_1_2_knee_joint" type="hinge" axis="0 1 0" range="-90 90" damping="4.0" limited="true" /><body name="leg_1_2_foot" pos="0.26823189268572756 0.0 0.0"><geom name="leg_1_2_foot_geom" type="cylinder" fromto="0.26823189268572756 0.0 0.0 0.44233909948691014 0.0 0.0" size="0.04" /><joint name="leg_1_2_ankle_joint" type="ball" damping="6.0" /></body></body></body><body name="leg_1_3" pos="0 0.09654032718426295 0"><geom name="leg_1_3_upper_geom" type="capsule" fromto="0.0 0.0 0.0 0.13262527512560773 0.0 0.0" size="0.04" /><joint name="leg_1_3_hip_joint" type="ball" damping="2.0" /><body name="leg_1_3_lower" pos="0.13262527512560773 0.0 0.0"><geom name="leg_1_3_lower_geom" type="capsule" fromto="0.13262527512560773 0.0 0.0 0.2856559013416591 0.0 0.0" size="0.04" /><joint name="leg_1_3_knee_joint" type="hinge" axis="0 1 0" range="-90 90" damping="4.0" limited="true" /><body name="leg_1_3_foot" pos="0.2856559013416591 0.0 0.0"><geom name="leg_1_3_foot_geom" type="cylinder" fromto="0.2856559013416591 0.0 0.0 0.4494873924827916 0.0 0.0" size="0.04" /><joint name="leg_1_3_ankle_joint" type="ball" damping="6.0" /></body></body></body></body><geom name="flag_1" type="box" size="0.05 0.05 0.5" pos="-2.784581637940917 -8.620402108479022 0" material="green" contype="1" conaffinity="2" /><body name="torso_2" pos="6.5 -6.5 0.75"><geom name="torso_geom_torso_2" type="box" size="0.429851179017582 0.1341247765512264 0.058787970398088085" pos="0 0 0" contype="1" conaffinity="3" material="blue" /><joint name="torso_2_root" type="free" armature="0" damping="0" limited="false" /><site name="torso_2_site" pos="0 0 0" type="sphere" size="0.01" /><body name="leg_2_1" pos="0 -0.0670623882756132 0"><geom name="leg_2_1_upper_geom" type="capsule" fromto="0.0 0.0 0.0 0.1626434258977103 0.0 0.0" size="0.04" /><joint name="leg_2_1_hip_joint" type="ball" damping="2.0" /><body name="leg_2_1_lower" pos="0.1626434258977103 0.0 0.0"><geom name="leg_2_1_lower_geom" type="capsule" fromto="0.1626434258977103 0.0 0.0 0.31481340837706384 0.0 0.0" size="0.04" /><joint name="leg_2_1_knee_joint" type="hinge" axis="0 1 0" range="-90 90" damping="4.0" limited="true" /><body name="leg_2_1_foot" pos="0.31481340837706384 0.0 0.0"><geom name="leg_2_1_foot_geom" type="cylinder" fromto="0.31481340837706384 0.0 0.0 0.4421404203410306 0.0 0.0" size="0.04" /><joint name="leg_2_1_ankle_joint" type="ball" damping="6.0" /></body></body></body></body><geom name="flag_2" type="box" size="0.05 0.05 0.5" pos="9.468744536885445 -8.353794992633441 0" material="blue" contype="1" conaffinity="3" /><body name="torso_3" pos="-6.5 0 0.75"><geom name="torso_geom_torso_3" type="box" size="0.2111429319049632 0.18562595548976296 0.05607046761870743" pos="0 0 0" contype="1" conaffinity="4" material="yellow" /><joint name="torso_3_root" type="free" armature="0" damping="0" limited="false" /><site name="torso_3_site" pos="0 0 0" type="sphere" size="0.01" /><body name="leg_3_1" pos="0 -0.09281297774488148 0"><geom name="leg_3_1_upper_geom" type="capsule" fromto="0.0 0.0 0.0 0.10068880350528203 0.0 0.0" size="0.04" /><joint name="leg_3_1_hip_joint" type="ball" damping="2.0" /><body name="leg_3_1_lower" pos="0.10068880350528203 0.0 0.0"><geom name="leg_3_1_lower_geom" type="capsule" fromto="0.10068880350528203 0.0 0.0 0.273625355925596 0.0 0.0" size="0.04" /><joint name="leg_3_1_knee_joint" type="hinge" axis="0 1 0" range="-90 90" damping="4.0" limited="true" /><body name="leg_3_1_foot" pos="0.273625355925596 0.0 0.0"><geom name="leg_3_1_foot_geom" type="cylinder" fromto="0.273625355925596 0.0 0.0 0.42136980152046394 0.0 0.0" size="0.04" /><joint name="leg_3_1_ankle_joint" type="ball" damping="6.0" /></body></body></body></body><geom name="flag_3" type="box" size="0.05 0.05 0.5" pos="-8.724638416355322 -2.7020332929991966 0" material="yellow" contype="1" conaffinity="4" /><body name="torso_4" pos="0 0 0.75"><geom name="torso_geom_torso_4" type="box" size="0.30879902132628945 0.10998512741101503 0.06299637934040733" pos="0 0 0" contype="1" conaffinity="5" material="purple" /><joint name="torso_4_root" type="free" armature="0" damping="0" limited="false" /><site name="torso_4_site" pos="0 0 0" type="sphere" size="0.01" /><body name="leg_4_1" pos="0.15439951066314472 0 0"><geom name="leg_4_1_upper_geom" type="capsule" fromto="0.0 0.0 0.0 0.19446078593081906 0.0 0.0" size="0.04" /><joint name="leg_4_1_hip_joint" type="ball" damping="2.0" /><body name="leg_4_1_lower" pos="0.19446078593081906 0.0 0.0"><geom name="leg_4_1_lower_geom" type="capsule" fromto="0.19446078593081906 0.0 0.0 0.3324128448043428 0.0 0.0" size="0.04" /><joint name="leg_4_1_knee_joint" type="hinge" axis="0 1 0" range="-90 90" damping="4.0" limited="true" /><body name="leg_4_1_foot" pos="0.3324128448043428 0.0 0.0"><geom name="leg_4_1_foot_geom" type="cylinder" fromto="0.3324128448043428 0.0 0.0 0.45227875841120113 0.0 0.0" size="0.04" /><joint name="leg_4_1_ankle_joint" type="ball" damping="6.0" /></body></body></body><body name="leg_4_2" pos="0 0.054992563705507515 0"><geom name="leg_4_2_upper_geom" type="capsule" fromto="0.0 0.0 0.0 0.16843888542889596 0.0 0.0" size="0.04" /><joint name="leg_4_2_hip_joint" type="ball" damping="2.0" /><body name="leg_4_2_lower" pos="0.16843888542889596 0.0 0.0"><geom name="leg_4_2_lower_geom" type="capsule" fromto="0.16843888542889596 0.0 0.0 0.2946134324324967 0.0 0.0" size="0.04" /><joint name="leg_4_2_knee_joint" type="hinge" axis="0 1 0" range="-90 90" damping="4.0" limited="true" /><body name="leg_4_2_foot" pos="0.2946134324324967 0.0 0.0"><geom name="leg_4_2_foot_geom" type="cylinder" fromto="0.2946134324324967 0.0 0.0 0.48785536310888006 0.0 0.0" size="0.04" /><joint name="leg_4_2_ankle_joint" type="ball" damping="6.0" /></body></body></body></body><geom name="flag_4" type="box" size="0.05 0.05 0.5" pos="-3.494609772260917 -0.1941714181297058 0" material="purple" contype="1" conaffinity="5" /><body name="torso_5" pos="6.5 0 0.75"><geom name="torso_geom_torso_5" type="box" size="0.30823930687382384 0.19819068417255883 0.06748901014346327" pos="0 0 0" contype="1" conaffinity="6" material="orange" /><joint name="torso_5_root" type="free" armature="0" damping="0" limited="false" /><site name="torso_5_site" pos="0 0 0" type="sphere" size="0.01" /><body name="leg_5_1" pos="0.15411965343691192 0 0"><geom name="leg_5_1_upper_geom" type="capsule" fromto="0.0 0.0 0.0 0.10266053988654102 0.0 0.0" size="0.04" /><joint name="leg_5_1_hip_joint" type="ball" damping="2.0" /><body name="leg_5_1_lower" pos="0.10266053988654102 0.0 0.0"><geom name="leg_5_1_lower_geom" type="capsule" fromto="0.10266053988654102 0.0 0.0 0.21124342628020923 0.0 0.0" size="0.04" /><joint name="leg_5_1_knee_joint" type="hinge" axis="0 1 0" range="-90 90" damping="4.0" limited="true" /><body name="leg_5_1_foot" pos="0.21124342628020923 0.0 0.0"><geom name="leg_5_1_foot_geom" type="cylinder" fromto="0.21124342628020923 0.0 0.0 0.3669837011976216 0.0 0.0" size="0.04" /><joint name="leg_5_1_ankle_joint" type="ball" damping="6.0" /></body></body></body><body name="leg_5_2" pos="0 -0.09909534208627942 0"><geom name="leg_5_2_upper_geom" type="capsule" fromto="0.0 0.0 0.0 0.11897872677785055 0.0 0.0" size="0.04" /><joint name="leg_5_2_hip_joint" type="ball" damping="2.0" /><body name="leg_5_2_lower" pos="0.11897872677785055 0.0 0.0"><geom name="leg_5_2_lower_geom" type="capsule" fromto="0.11897872677785055 0.0 0.0 0.2986384849048338 0.0 0.0" size="0.04" /><joint name="leg_5_2_knee_joint" type="hinge" axis="0 1 0" range="-90 90" damping="4.0" limited="true" /><body name="leg_5_2_foot" pos="0.2986384849048338 0.0 0.0"><geom name="leg_5_2_foot_geom" type="cylinder" fromto="0.2986384849048338 0.0 0.0 0.4552964427719733 0.0 0.0" size="0.04" /><joint name="leg_5_2_ankle_joint" type="ball" damping="6.0" /></body></body></body><body name="leg_5_3" pos="0 0.09909534208627942 0"><geom name="leg_5_3_upper_geom" type="capsule" fromto="0.0 0.0 0.0 0.14475475089606166 0.0 0.0" size="0.04" /><joint name="leg_5_3_hip_joint" type="ball" damping="2.0" /><body name="leg_5_3_lower" pos="0.14475475089606166 0.0 0.0"><geom name="leg_5_3_lower_geom" type="capsule" fromto="0.14475475089606166 0.0 0.0 0.24829787290027394 0.0 0.0" size="0.04" /><joint name="leg_5_3_knee_joint" type="hinge" axis="0 1 0" range="-90 90" damping="4.0" limited="true" /><body name="leg_5_3_foot" pos="0.24829787290027394 0.0 0.0"><geom name="leg_5_3_foot_geom" type="cylinder" fromto="0.24829787290027394 0.0 0.0 0.4246830207797605 0.0 0.0" size="0.04" /><joint name="leg_5_3_ankle_joint" type="ball" damping="6.0" /></body></body></body></body><geom name="flag_5" type="box" size="0.05 0.05 0.5" pos="9.031807291485261 2.4165992300714803 0" material="orange" contype="1" conaffinity="6" /><body name="torso_6" pos="-6.5 6.5 0.75"><geom name="torso_geom_torso_6" type="box" size="0.26371616814831994 0.17634651151124267 0.06607094903497564" pos="0 0 0" contype="1" conaffinity="7" material="pink" /><joint name="torso_6_root" type="free" armature="0" damping="0" limited="false" /><site name="torso_6_site" pos="0 0 0" type="sphere" size="0.01" /><body name="leg_6_1" pos="0 -0.08817325575562134 0"><geom name="leg_6_1_upper_geom" type="capsule" fromto="0.0 0.0 0.0 0.11300646566478323 0.0 0.0" size="0.04" /><joint name="leg_6_1_hip_joint" type="ball" damping="2.0" /><body name="leg_6_1_lower" pos="0.11300646566478323 0.0 0.0"><geom name="leg_6_1_lower_geom" type="capsule" fromto="0.11300646566478323 0.0 0.0 0.30056562753752125 0.0 0.0" size="0.04" /><joint name="leg_6_1_knee_joint" type="hinge" axis="0 1 0" range="-90 90" damping="4.0" limited="true" /><body name="leg_6_1_foot" pos="0.30056562753752125 0.0 0.0"><geom name="leg_6_1_foot_geom" type="cylinder" fromto="0.30056562753752125 0.0 0.0 0.4908883483956812 0.0 0.0" size="0.04" /><joint name="leg_6_1_ankle_joint" type="ball" damping="6.0" /></body></body></body></body><geom name="flag_6" type="box" size="0.05 0.05 0.5" pos="-8.070016605701648 9.62810611358072 0" material="pink" contype="1" conaffinity="7" /><body name="torso_7" pos="0 6.5 0.75"><geom name="torso_geom_torso_7" type="box" size="0.337317275757508 0.10628280798551129 0.07278876406905876" pos="0 0 0" contype="1" conaffinity="8" material="grey" /><joint name="torso_7_root" type="free" armature="0" damping="0" limited="false" /><site name="torso_7_site" pos="0 0 0" type="sphere" size="0.01" /><body name="leg_7_1" pos="0.168658637878754 0 0"><geom name="leg_7_1_upper_geom" type="capsule" fromto="0.0 0.0 0.0 0.19005078288363614 0.0 0.0" size="0.04" /><joint name="leg_7_1_hip_joint" type="ball" damping="2.0" /><body name="leg_7_1_lower" pos="0.19005078288363614 0.0 0.0"><geom name="leg_7_1_lower_geom" type="capsule" fromto="0.19005078288363614 0.0 0.0 0.30005793614040244 0.0 0.0" size="0.04" /><joint name="leg_7_1_knee_joint" type="hinge" axis="0 1 0" range="-90 90" damping="4.0" limited="true" /><body name="leg_7_1_foot" pos="0.30005793614040244 0.0 0.0"><geom name="leg_7_1_foot_geom" type="cylinder" fromto="0.30005793614040244 0.0 0.0 0.49427498605730436 0.0 0.0" size="0.04" /><joint name="leg_7_1_ankle_joint" type="ball" damping="6.0" /></body></body></body><body name="leg_7_2" pos="0 0.053141403992755645 0"><geom name="leg_7_2_upper_geom" type="capsule" fromto="0.0 0.0 0.0 0.18535870391995468 0.0 0.0" size="0.04" /><joint name="leg_7_2_hip_joint" type="ball" damping="2.0" /><body name="leg_7_2_lower" pos="0.18535870391995468 0.0 0.0"><geom name="leg_7_2_lower_geom" type="capsule" fromto="0.18535870391995468 0.0 0.0 0.33690306720684016 0.0 0.0" size="0.04" /><joint name="leg_7_2_knee_joint" type="hinge" axis="0 1 0" range="-90 90" damping="4.0" limited="true" /><body name="leg_7_2_foot" pos="0.33690306720684016 0.0 0.0"><geom name="leg_7_2_foot_geom" type="cylinder" fromto="0.33690306720684016 0.0 0.0 0.5004794861436073 0.0 0.0" size="0.04" /><joint name="leg_7_2_ankle_joint" type="ball" damping="6.0" /></body></body></body><body name="leg_7_3" pos="0.168658637878754 0 0"><geom name="leg_7_3_upper_geom" type="capsule" fromto="0.0 0.0 0.0 0.17003394328607668 0.0 0.0" size="0.04" /><joint name="leg_7_3_hip_joint" type="ball" damping="2.0" /><body name="leg_7_3_lower" pos="0.17003394328607668 0.0 0.0"><geom name="leg_7_3_lower_geom" type="capsule" fromto="0.17003394328607668 0.0 0.0 0.3412915278532436 0.0 0.0" size="0.04" /><joint name="leg_7_3_knee_joint" type="hinge" axis="0 1 0" range="-90 90" damping="4.0" limited="true" /><body name="leg_7_3_foot" pos="0.3412915278532436 0.0 0.0"><geom name="leg_7_3_foot_geom" type="cylinder" fromto="0.3412915278532436 0.0 0.0 0.5362706830735041 0.0 0.0" size="0.04" /><joint name="leg_7_3_ankle_joint" type="ball" damping="6.0" /></body></body></body><body name="leg_7_4" pos="0 -0.053141403992755645 0"><geom name="leg_7_4_upper_geom" type="capsule" fromto="0.0 0.0 0.0 0.11931487119587542 0.0 0.0" size="0.04" /><joint name="leg_7_4_hip_joint" type="ball" damping="2.0" /><body name="leg_7_4_lower" pos="0.11931487119587542 0.0 0.0"><geom name="leg_7_4_lower_geom" type="capsule" fromto="0.11931487119587542 0.0 0.0 0.2885854577443455 0.0 0.0" size="0.04" /><joint name="leg_7_4_knee_joint" type="hinge" axis="0 1 0" range="-90 90" damping="4.0" limited="true" /><body name="leg_7_4_foot" pos="0.2885854577443455 0.0 0.0"><geom name="leg_7_4_foot_geom" type="cylinder" fromto="0.2885854577443455 0.0 0.0 0.4722952152382479 0.0 0.0" size="0.04" /><joint name="leg_7_4_ankle_joint" type="ball" damping="6.0" /></body></body></body></body><geom name="flag_7" type="box" size="0.05 0.05 0.5" pos="-1.8969802390127009 3.558662553735917 0" material="grey" contype="1" conaffinity="8" /><body name="torso_8" pos="6.5 6.5 0.75"><geom name="torso_geom_torso_8" type="box" size="0.4271906429409304 0.10306085041496241 0.09822451894765913" pos="0 0 0" contype="1" conaffinity="9" material="brown" /><joint name="torso_8_root" type="free" armature="0" damping="0" limited="false" /><site name="torso_8_site" pos="0 0 0" type="sphere" size="0.01" /><body name="leg_8_1" pos="0 -0.051530425207481204 0"><geom name="leg_8_1_upper_geom" type="capsule" fromto="0.0 0.0 0.0 0.17140836234782222 0.0 0.0" size="0.04" /><joint name="leg_8_1_hip_joint" type="ball" damping="2.0" /><body name="leg_8_1_lower" pos="0.17140836234782222 0.0 0.0"><geom name="leg_8_1_lower_geom" type="capsule" fromto="0.17140836234782222 0.0 0.0 0.28921088270807294 0.0 0.0" size="0.04" /><joint name="leg_8_1_knee_joint" type="hinge" axis="0 1 0" range="-90 90" damping="4.0" limited="true" /><body name="leg_8_1_foot" pos="0.28921088270807294 0.0 0.0"><geom name="leg_8_1_foot_geom" type="cylinder" fromto="0.28921088270807294 0.0 0.0 0.4127998505641652 0.0 0.0" size="0.04" /><joint name="leg_8_1_ankle_joint" type="ball" damping="6.0" /></body></body></body><body name="leg_8_2" pos="0 0.051530425207481204 0"><geom name="leg_8_2_upper_geom" type="capsule" fromto="0.0 0.0 0.0 0.15076687655623042 0.0 0.0" size="0.04" /><joint name="leg_8_2_hip_joint" type="ball" damping="2.0" /><body name="leg_8_2_lower" pos="0.15076687655623042 0.0 0.0"><geom name="leg_8_2_lower_geom" type="capsule" fromto="0.15076687655623042 0.0 0.0 0.2625497390542252 0.0 0.0" size="0.04" /><joint name="leg_8_2_knee_joint" type="hinge" axis="0 1 0" range="-90 90" damping="4.0" limited="true" /><body name="leg_8_2_foot" pos="0.2625497390542252 0.0 0.0"><geom name="leg_8_2_foot_geom" type="cylinder" fromto="0.2625497390542252 0.0 0.0 0.4436113180687583 0.0 0.0" size="0.04" /><joint name="leg_8_2_ankle_joint" type="ball" damping="6.0" /></body></body></body></body><geom name="flag_8" type="box" size="0.05 0.05 0.5" pos="9.160686538727383 4.226072309277425 0" material="brown" contype="1" conaffinity="9" /><geom name="north_wall" type="box" pos="0 10.05 0.25" size="10.05 0.05 0.25" material="MatPlane" /><geom name="south_wall" type="box" pos="0 -10.05 0.25" size="10.05 0.05 0.25" material="MatPlane" /><geom name="east_wall" type="box" pos="10.05 0 0.25" size="0.05 10.05 0.25" material="MatPlane" /><geom name="west_wall" type="box" pos="-10.05 0 0.25" size="0.05 10.05 0.25" material="MatPlane" /></worldbody><actuator><motor name="leg_0_1_hip_motor" joint="leg_0_1_hip_joint" ctrllimited="true" ctrlrange="-1 1" gear="200" /><motor name="leg_0_1_ankle_joint_motor" joint="leg_0_1_ankle_joint" ctrllimited="true" ctrlrange="-1 1" gear="200" /><motor name="leg_1_1_hip_motor" joint="leg_1_1_hip_joint" ctrllimited="true" ctrlrange="-1 1" gear="200" /><motor name="leg_1_1_ankle_joint_motor" joint="leg_1_1_ankle_joint" ctrllimited="true" ctrlrange="-1 1" gear="200" /><motor name="leg_1_2_hip_motor" joint="leg_1_2_hip_joint" ctrllimited="true" ctrlrange="-1 1" gear="200" /><motor name="leg_1_2_ankle_joint_motor" joint="leg_1_2_ankle_joint" ctrllimited="true" ctrlrange="-1 1" gear="200" /><motor name="leg_1_3_hip_motor" joint="leg_1_3_hip_joint" ctrllimited="true" ctrlrange="-1 1" gear="200" /><motor name="leg_1_3_ankle_joint_motor" joint="leg_1_3_ankle_joint" ctrllimited="true" ctrlrange="-1 1" gear="200" /><motor name="leg_2_1_hip_motor" joint="leg_2_1_hip_joint" ctrllimited="true" ctrlrange="-1 1" gear="200" /><motor name="leg_2_1_ankle_joint_motor" joint="leg_2_1_ankle_joint" ctrllimited="true" ctrlrange="-1 1" gear="200" /><motor name="leg_3_1_hip_motor" joint="leg_3_1_hip_joint" ctrllimited="true" ctrlrange="-1 1" gear="200" /><motor name="leg_3_1_ankle_joint_motor" joint="leg_3_1_ankle_joint" ctrllimited="true" ctrlrange="-1 1" gear="200" /><motor name="leg_4_1_hip_motor" joint="leg_4_1_hip_joint" ctrllimited="true" ctrlrange="-1 1" gear="200" /><motor name="leg_4_1_ankle_joint_motor" joint="leg_4_1_ankle_joint" ctrllimited="true" ctrlrange="-1 1" gear="200" /><motor name="leg_4_2_hip_motor" joint="leg_4_2_hip_joint" ctrllimited="true" ctrlrange="-1 1" gear="200" /><motor name="leg_4_2_ankle_joint_motor" joint="leg_4_2_ankle_joint" ctrllimited="true" ctrlrange="-1 1" gear="200" /><motor name="leg_5_1_hip_motor" joint="leg_5_1_hip_joint" ctrllimited="true" ctrlrange="-1 1" gear="200" /><motor name="leg_5_1_ankle_joint_motor" joint="leg_5_1_ankle_joint" ctrllimited="true" ctrlrange="-1 1" gear="200" /><motor name="leg_5_2_hip_motor" joint="leg_5_2_hip_joint" ctrllimited="true" ctrlrange="-1 1" gear="200" /><motor name="leg_5_2_ankle_joint_motor" joint="leg_5_2_ankle_joint" ctrllimited="true" ctrlrange="-1 1" gear="200" /><motor name="leg_5_3_hip_motor" joint="leg_5_3_hip_joint" ctrllimited="true" ctrlrange="-1 1" gear="200" /><motor name="leg_5_3_ankle_joint_motor" joint="leg_5_3_ankle_joint" ctrllimited="true" ctrlrange="-1 1" gear="200" /><motor name="leg_6_1_hip_motor" joint="leg_6_1_hip_joint" ctrllimited="true" ctrlrange="-1 1" gear="200" /><motor name="leg_6_1_ankle_joint_motor" joint="leg_6_1_ankle_joint" ctrllimited="true" ctrlrange="-1 1" gear="200" /><motor name="leg_7_1_hip_motor" joint="leg_7_1_hip_joint" ctrllimited="true" ctrlrange="-1 1" gear="200" /><motor name="leg_7_1_ankle_joint_motor" joint="leg_7_1_ankle_joint" ctrllimited="true" ctrlrange="-1 1" gear="200" /><motor name="leg_7_2_hip_motor" joint="leg_7_2_hip_joint" ctrllimited="true" ctrlrange="-1 1" gear="200" /><motor name="leg_7_2_ankle_joint_motor" joint="leg_7_2_ankle_joint" ctrllimited="true" ctrlrange="-1 1" gear="200" /><motor name="leg_7_3_hip_motor" joint="leg_7_3_hip_joint" ctrllimited="true" ctrlrange="-1 1" gear="200" /><motor name="leg_7_3_ankle_joint_motor" joint="leg_7_3_ankle_joint" ctrllimited="true" ctrlrange="-1 1" gear="200" /><motor name="leg_7_4_hip_motor" joint="leg_7_4_hip_joint" ctrllimited="true" ctrlrange="-1 1" gear="200" /><motor name="leg_7_4_ankle_joint_motor" joint="leg_7_4_ankle_joint" ctrllimited="true" ctrlrange="-1 1" gear="200" /><motor name="leg_8_1_hip_motor" joint="leg_8_1_hip_joint" ctrllimited="true" ctrlrange="-1 1" gear="200" /><motor name="leg_8_1_ankle_joint_motor" joint="leg_8_1_ankle_joint" ctrllimited="true" ctrlrange="-1 1" gear="200" /><motor name="leg_8_2_hip_motor" joint="leg_8_2_hip_joint" ctrllimited="true" ctrlrange="-1 1" gear="200" /><motor name="leg_8_2_ankle_joint_motor" joint="leg_8_2_ankle_joint" ctrllimited="true" ctrlrange="-1 1" gear="200" /></actuator><sensor><accelerometer name="torso_0_accel" site="torso_0_site" /><gyro name="torso_0_gyro" site="torso_0_site" /><accelerometer name="torso_1_accel" site="torso_1_site" /><gyro name="torso_1_gyro" site="torso_1_site" /><accelerometer name="torso_2_accel" site="torso_2_site" /><gyro name="torso_2_gyro" site="torso_2_site" /><accelerometer name="torso_3_accel" site="torso_3_site" /><gyro name="torso_3_gyro" site="torso_3_site" /><accelerometer name="torso_4_accel" site="torso_4_site" /><gyro name="torso_4_gyro" site="torso_4_site" /><accelerometer name="torso_5_accel" site="torso_5_site" /><gyro name="torso_5_gyro" site="torso_5_site" /><accelerometer name="torso_6_accel" site="torso_6_site" /><gyro name="torso_6_gyro" site="torso_6_site" /><accelerometer name="torso_7_accel" site="torso_7_site" /><gyro name="torso_7_gyro" site="torso_7_site" /><accelerometer name="torso_8_accel" site="torso_8_site" /><gyro name="torso_8_gyro" site="torso_8_site" /></sensor></mujoco>